Workbook
Name LucroLiquido: ALLCOOK!#REF!
Name LucroLiquido: ESPECIARYA!#REF!
Name LucroLiquido: PALATO!#REF!
Name LucroLiquido: #REF!

Sheet MANUAL
C4: Manual
D5: 1 | E5: Relatório de Movimento | G5: Cadastro de Usuário
D6: 2 | E6: Verificara se o final do Mês é o inicial do seguinte
D7: 3

Sheet PALATO
B2: =G42+M42+T42+AA42 -> 14869988 | C2: JANEIRO | I2: FEVEREIRO | P2: MARÇO | W2: ABRIL | AD2: MAIO | AK2: JUNHO | AR2: JULHO | AY2: AGOSTO | BF2: SETEMBRO | BM2: OUTUBRO | BT2: NOVEMBRO | CA2: DEZEMBRO | CH2: 2026
B3: DEMONSTRAÇÃO FINANCEIRA | C3: ESPECIARYA | E3: ALL COOK | G3: PALATO | I3: ESPECIARYA | K3: ALL COOK | M3: PALATO | O3: Δ | P3: ESPECIARYA | R3: ALL COOK | T3: PALATO | V3: Δ | W3: ESPECIARYA | Y3: ALL COOK | AA3: PALATO | AC3: Δ | AD3: ESPECIARYA | AF3: ALL COOK | AH3: PALATO | AJ3: Δ | AK3: ESPECIARYA | AM3: ALL COOK | AO3: PALATO | AQ3: Δ | AR3: ESPECIARYA | AT3: ALL COOK | AV3: PALATO | AX3: Δ | AY3: ESPECIARYA | BA3: ALL COOK | BC3: PALATO | BE3: Δ | BF3: ESPECIARYA | BH3: ALL COOK | BJ3: PALATO | BL3: Δ | BM3: ESPECIARYA | BO3: ALL COOK | BQ3: PALATO | BS3: Δ | BT3: ESPECIARYA | BV3: ALL COOK | BX3: PALATO | BZ3: Δ | CA3: ESPECIARYA | CC3: ALL COOK | CE3: PALATO | CG3: Δ | CH3: ESPECIARYA | CJ3: ALL COOK | CL3: PALATO
B4: Vendas Dinheiro | C4: =SUMIF('MVTO E'!$C$3:$C$240,"Vda_Din",'MVTO E'!$G$3:$G$240)-SUMIF('MVTO E'!$C$3:$C$240,"Vda_S_Din",'MVTO E'!$G$3:$G$240) -> 1612193.8 | D4: =C4/$C$10 -> 0.04900135 | E4: =SUMIF('MVTO A'!$C$3:$C$184,"Vda_Din",'MVTO A'!$G$3:$G$184)-SUMIF('MVTO A'!$C$3:$C$184,"Vda_S_Din",'MVTO A'!$G$3:$G$184) -> 0 | F4: =E4/$E$10 -> 0 | G4: =C4+E4 -> 1612193.8 | H4: =G4/$G$10 -> 0.043746924 | I4: =SUMIF('MVTO E'!$C$3:$C$240,"Vda_Din",'MVTO E'!$H$3:$H$240)-SUMIF('MVTO E'!$C$3:$C$240,"Vda_S_Din",'MVTO E'!$H$3:$H$240) -> 1483685.4 | J4: =I4/$I$10 -> 0.069886187 | K4: =SUMIF('MVTO A'!$C$3:$C$184,"Vda_Din",'MVTO A'!$H$3:$H$184)-SUMIF('MVTO A'!$C$3:$C$184,"Vda_S_Din",'MVTO A'!$H$3:$H$184) -> 0 | L4: =K4/$K$10 -> 0 | M4: =I4+K4 -> 1483685.4 | N4: =M4/$M$10 -> 0.060191888 | O4: =M4-G4 -> -128508.45 | P4: =SUMIF('MVTO E'!$C$3:$C$240,"Vda_Din",'MVTO E'!$I$3:$I$240)-SUMIF('MVTO E'!$C$3:$C$240,"Vda_S_Din",'MVTO E'!$I$3:$I$240) -> 1481071.3 | Q4: =P4/$I$10 -> 0.069763058 | R4: =SUMIF('MVTO A'!$C$3:$C$184,"Vda_Din",'MVTO A'!$I$3:$I$184)-SUMIF('MVTO A'!$C$3:$C$184,"Vda_S_Din",'MVTO A'!$I$3:$I$184) -> 0 | S4: =R4/$K$10 -> 0 | T4: =P4+R4 -> 1481071.3 | U4: =T4/$T$10 -> 0.053939707 | V4: =T4-M4 -> -2614.04 | W4: =SUMIF('MVTO E'!$C$3:$C$240,"Vda_Din",'MVTO E'!$J$3:$J$240)-SUMIF('MVTO E'!$C$3:$C$240,"Vda_S_Din",'MVTO E'!$J$3:$J$240) -> 1430187.4 | X4: =W4/$I$10 -> 0.067366265 | Y4: =SUMIF('MVTO A'!$C$3:$C$184,"Vda_Din",'MVTO A'!$J$3:$J$184)-SUMIF('MVTO A'!$C$3:$C$184,"Vda_S_Din",'MVTO A'!$J$3:$J$184) -> 0 | Z4: =Y4/$K$10 -> 0 | AA4: =W4+Y4 -> 1430187.4 | AB4: =AA4/$AA$10 -> 0.056404765 | AC4: =AA4-T4 -> -50883.96 | AD4: =SUMIF('MVTO E'!$C$3:$C$240,"Vda_Din",'MVTO E'!$K$3:$K$240)-SUMIF('MVTO E'!$C$3:$C$240,"Vda_S_Din",'MVTO E'!$K$3:$K$240) -> 0 | AE4: =AD4/$I$10 -> 0 | AF4: =SUMIF('MVTO A'!$C$3:$C$184,"Vda_Din",'MVTO A'!$K$3:$K$184)-SUMIF('MVTO A'!$C$3:$C$184,"Vda_S_Din",'MVTO A'!$K$3:$K$184) -> 0 | AG4: =AF4/$K$10 -> 0 | AH4: =AD4+AF4 -> 0 | AI4: =AH4/$AA$10 -> 0 | AJ4: =AH4-AA4 -> -1430187.4 | AK4: =SUMIF('MVTO E'!$C$3:$C$240,"Vda_Din",'MVTO E'!$L$3:$L$240)-SUMIF('MVTO E'!$C$3:$C$240,"Vda_S_Din",'MVTO E'!$L$3:$L$240) -> 0 | AL4: =AK4/$I$10 -> 0 | AM4: =SUMIF('MVTO A'!$C$3:$C$184,"Vda_Din",'MVTO A'!$L$3:$L$184)-SUMIF('MVTO A'!$C$3:$C$184,"Vda_S_Din",'MVTO A'!$L$3:$L$184) -> 0 | AN4: =AM4/$K$10 -> 0 | AO4: =AK4+AM4 -> 0 | AP4: =AO4/$AA$10 -> 0 | AQ4: =AO4-AH4 -> 0 | AR4: =SUMIF('MVTO E'!$C$3:$C$240,"Vda_Din",'MVTO E'!$M$3:$M$240)-SUMIF('MVTO E'!$C$3:$C$240,"Vda_S_Din",'MVTO E'!$M$3:$M$240) -> 0 | AS4: =AR4/$I$10 -> 0 | AT4: =SUMIF('MVTO A'!$C$3:$C$184,"Vda_Din",'MVTO A'!$M$3:$M$184)-SUMIF('MVTO A'!$C$3:$C$184,"Vda_S_Din",'MVTO A'!$M$3:$M$184) -> 0 | AU4: =AT4/$K$10 -> 0 | AV4: =AR4+AT4 -> 0 | AW4: =AV4/$AA$10 -> 0 | AX4: =AV4-AO4 -> 0 | AY4: =SUMIF('MVTO E'!$C$3:$C$240,"Vda_Din",'MVTO E'!$N$3:$N$240)-SUMIF('MVTO E'!$C$3:$C$240,"Vda_S_Din",'MVTO E'!$N$3:$N$240) -> 0 | AZ4: =AY4/$I$10 -> 0 | BA4: =SUMIF('MVTO A'!$C$3:$C$184,"Vda_Din",'MVTO A'!$N$3:$N$184)-SUMIF('MVTO A'!$C$3:$C$184,"Vda_S_Din",'MVTO A'!$N$3:$N$184) -> 0 | BB4: =BA4/$K$10 -> 0 | BC4: =AY4+BA4 -> 0 | BD4: =BC4/$AA$10 -> 0 | BE4: =BC4-AV4 -> 0 | BF4: =SUMIF('MVTO E'!$C$3:$C$240,"Vda_Din",'MVTO E'!$O$3:$O$240)-SUMIF('MVTO E'!$C$3:$C$240,"Vda_S_Din",'MVTO E'!$O$3:$O$240) -> 0 | BG4: =BF4/$I$10 -> 0 | BH4: =SUMIF('MVTO A'!$C$3:$C$184,"Vda_Din",'MVTO A'!$O$3:$O$184)-SUMIF('MVTO A'!$C$3:$C$184,"Vda_S_Din",'MVTO A'!$O$3:$O$184) -> 0 | BI4: =BH4/$K$10 -> 0 | BJ4: =BF4+BH4 -> 0 | BK4: =BJ4/$AA$10 -> 0 | BL4: =BJ4-BC4 -> 0 | BM4: =SUMIF('MVTO E'!$C$3:$C$240,"Vda_Din",'MVTO E'!$P$3:$P$240)-SUMIF('MVTO E'!$C$3:$C$240,"Vda_S_Din",'MVTO E'!$P$3:$P$240) -> 0 | BN4: =BM4/$I$10 -> 0 | BO4: =SUMIF('MVTO A'!$C$3:$C$184,"Vda_Din",'MVTO A'!$P$3:$P$184)-SUMIF('MVTO A'!$C$3:$C$184,"Vda_S_Din",'MVTO A'!$P$3:$P$184) -> 0 | BP4: =BO4/$K$10 -> 0 | BQ4: =BM4+BO4 -> 0 | BR4: =BQ4/$AA$10 -> 0 | BS4: =BQ4-BJ4 -> 0 | BT4: =SUMIF('MVTO E'!$C$3:$C$240,"Vda_Din",'MVTO E'!$Q$3:$Q$240)-SUMIF('MVTO E'!$C$3:$C$240,"Vda_S_Din",'MVTO E'!$Q$3:$Q$240) -> 0 | BU4: =BT4/$I$10 -> 0 | BV4: =SUMIF('MVTO A'!$C$3:$C$184,"Vda_Din",'MVTO A'!$Q$3:$Q$184)-SUMIF('MVTO A'!$C$3:$C$184,"Vda_S_Din",'MVTO A'!$Q$3:$Q$184) -> 0 | BW4: =BV4/$K$10 -> 0 | BX4: =BT4+BV4 -> 0 | BY4: =BX4/$AA$10 -> 0 | BZ4: =BX4-BQ4 -> 0 | CA4: =SUMIF('MVTO E'!$C$3:$C$240,"Vda_Din",'MVTO E'!$R$3:$R$240)-SUMIF('MVTO E'!$C$3:$C$240,"Vda_S_Din",'MVTO E'!$R$3:$R$240) -> 0 | CB4: =CA4/$I$10 -> 0 | CC4: =SUMIF('MVTO A'!$C$3:$C$184,"Vda_Din",'MVTO A'!$R$3:$R$184)-SUMIF('MVTO A'!$C$3:$C$184,"Vda_S_Din",'MVTO A'!$R$3:$R$184) -> 0 | CD4: =CC4/$K$10 -> 0 | CE4: =CA4+CC4 -> 0 | CF4: =CE4/$AA$10 -> 0 | CG4: =CE4-BX4 -> 0 | CH4: =SUM(C4,I4,P4,W4,AD4,AK4,AR4,AY4,BF4,BM4,BT4,CA4) -> 6007137.8 | CI4: =CH4/$CH$10 -> 0.059988986 | CJ4: =SUM(E4,K4,R4,Y4,AF4,AM4,AT4,BA4,BH4,BO4,BV4,CC4) -> 0 | CK4: =CJ4/$CJ$10 -> 0 | CL4: =SUM(G4,M4,T4,AA4,AH4,AO4,AV4,BC4,BJ4,BQ4,BX4,CE4) -> 6007137.8 | CM4: =CL4/$CL$10 -> 0.052548675
B5: Vendas - PIX | C5: =SUMIF('MVTO E'!$C$3:$C$240,"Vda_PIX",'MVTO E'!$G$3:$G$240)-SUMIF('MVTO E'!$C$3:$C$240,"Vda_S_PIX",'MVTO E'!$G$3:$G$240) -> 27676.12 | D5: =C5/$C$10 -> 0.00084119369 | E5: =SUMIF('MVTO A'!$C$3:$C$184,"Vda_PIX",'MVTO A'!$G$3:$G$184)-SUMIF('MVTO A'!$C$3:$C$184,"Vda_S_PIX",'MVTO A'!$G$3:$G$184) -> 230404.64 | F5: =E5/$E$10 -> 0.058304786 | G5: =C5+E5 -> 258080.76 | H5: =G5/$G$10 -> 0.0070030286 | I5: =SUMIF('MVTO E'!$C$3:$C$240,"Vda_PIX",'MVTO E'!$H$3:$H$240)-SUMIF('MVTO E'!$C$3:$C$240,"Vda_S_PIX",'MVTO E'!$H$3:$H$240) -> 19035.57 | J5: =I5/$I$10 -> 0.00089663445 | K5: =SUMIF('MVTO A'!$C$3:$C$184,"Vda_PIX",'MVTO A'!$H$3:$H$184)-SUMIF('MVTO A'!$C$3:$C$184,"Vda_S_PIX",'MVTO A'!$H$3:$H$184) -> 185954.55 | L5: =K5/$K$10 -> 0.054384848 | M5: =I5+K5 -> 204990.12 | N5: =M5/$M$10 -> 0.0083162797 | O5: =M5-G5 -> -53090.64 | P5: =SUMIF('MVTO E'!$C$3:$C$240,"Vda_PIX",'MVTO E'!$I$3:$I$240)-SUMIF('MVTO E'!$C$3:$C$240,"Vda_S_PIX",'MVTO E'!$I$3:$I$240) -> 19965.39 | Q5: =P5/$I$10 -> 0.00094043186 | R5: =SUMIF('MVTO A'!$C$3:$C$184,"Vda_PIX",'MVTO A'!$I$3:$I$184)-SUMIF('MVTO A'!$C$3:$C$184,"Vda_S_PIX",'MVTO A'!$I$3:$I$184) -> 208795.25 | S5: =R5/$K$10 -> 0.061064911 | T5: =P5+R5 -> 228760.64 | U5: =T5/$T$10 -> 0.0083313219 | V5: =T5-M5 -> 23770.52 | W5: =SUMIF('MVTO E'!$C$3:$C$240,"Vda_PIX",'MVTO E'!$J$3:$J$240)-SUMIF('MVTO E'!$C$3:$C$240,"Vda_S_PIX",'MVTO E'!$J$3:$J$240) -> 34126.54 | X5: =W5/$I$10 -> 0.001607466 | Y5: =SUMIF('MVTO A'!$C$3:$C$184,"Vda_PIX",'MVTO A'!$J$3:$J$184)-SUMIF('MVTO A'!$C$3:$C$184,"Vda_S_PIX",'MVTO A'!$J$3:$J$184) -> 164338.74 | Z5: =Y5/$K$10 -> 0.048063021 | AA5: =W5+Y5 -> 198465.28 | AB5: =AA5/$AA$10 -> 0.0078272176 | AC5: =AA5-T5 -> -30295.36 | AD5: =SUMIF('MVTO E'!$C$3:$C$240,"Vda_PIX",'MVTO E'!$K$3:$K$240)-SUMIF('MVTO E'!$C$3:$C$240,"Vda_S_PIX",'MVTO E'!$K$3:$K$240) -> 0 | AE5: =AD5/$I$10 -> 0 | AF5: =SUMIF('MVTO A'!$C$3:$C$184,"Vda_PIX",'MVTO A'!$K$3:$K$184)-SUMIF('MVTO A'!$C$3:$C$184,"Vda_S_PIX",'MVTO A'!$K$3:$K$184) -> 0 | AG5: =AF5/$K$10 -> 0 | AH5: =AD5+AF5 -> 0 | AI5: =AH5/$AA$10 -> 0 | AJ5: =AH5-AA5 -> -198465.28 | AK5: =SUMIF('MVTO E'!$C$3:$C$240,"Vda_PIX",'MVTO E'!$L$3:$L$240)-SUMIF('MVTO E'!$C$3:$C$240,"Vda_S_PIX",'MVTO E'!$L$3:$L$240) -> 0 | AL5: =AK5/$I$10 -> 0 | AM5: =SUMIF('MVTO A'!$C$3:$C$184,"Vda_PIX",'MVTO A'!$L$3:$L$184)-SUMIF('MVTO A'!$C$3:$C$184,"Vda_S_PIX",'MVTO A'!$L$3:$L$184) -> 0 | AN5: =AM5/$K$10 -> 0 | AO5: =AK5+AM5 -> 0 | AP5: =AO5/$AA$10 -> 0 | AQ5: =AO5-AH5 -> 0 | AR5: =SUMIF('MVTO E'!$C$3:$C$240,"Vda_PIX",'MVTO E'!$M$3:$M$240)-SUMIF('MVTO E'!$C$3:$C$240,"Vda_S_PIX",'MVTO E'!$M$3:$M$240) -> 0 | AS5: =AR5/$I$10 -> 0 | AT5: =SUMIF('MVTO A'!$C$3:$C$184,"Vda_PIX",'MVTO A'!$M$3:$M$184)-SUMIF('MVTO A'!$C$3:$C$184,"Vda_S_PIX",'MVTO A'!$M$3:$M$184) -> 0 | AU5: =AT5/$K$10 -> 0 | AV5: =AR5+AT5 -> 0 | AW5: =AV5/$AA$10 -> 0 | AX5: =AV5-AO5 -> 0 | AY5: =SUMIF('MVTO E'!$C$3:$C$240,"Vda_PIX",'MVTO E'!$N$3:$N$240)-SUMIF('MVTO E'!$C$3:$C$240,"Vda_S_PIX",'MVTO E'!$N$3:$N$240) -> 0 | AZ5: =AY5/$I$10 -> 0 | BA5: =SUMIF('MVTO A'!$C$3:$C$184,"Vda_PIX",'MVTO A'!$N$3:$N$184)-SUMIF('MVTO A'!$C$3:$C$184,"Vda_S_PIX",'MVTO A'!$N$3:$N$184) -> 0 | BB5: =BA5/$K$10 -> 0 | BC5: =AY5+BA5 -> 0 | BD5: =BC5/$AA$10 -> 0 | BE5: =BC5-AV5 -> 0 | BF5: =SUMIF('MVTO E'!$C$3:$C$240,"Vda_PIX",'MVTO E'!$O$3:$O$240)-SUMIF('MVTO E'!$C$3:$C$240,"Vda_S_PIX",'MVTO E'!$O$3:$O$240) -> 0 | BG5: =BF5/$I$10 -> 0 | BH5: =SUMIF('MVTO A'!$C$3:$C$184,"Vda_PIX",'MVTO A'!$O$3:$O$184)-SUMIF('MVTO A'!$C$3:$C$184,"Vda_S_PIX",'MVTO A'!$O$3:$O$184) -> 0 | BI5: =BH5/$K$10 -> 0 | BJ5: =BF5+BH5 -> 0 | BK5: =BJ5/$AA$10 -> 0 | BL5: =BJ5-BC5 -> 0 | BM5: =SUMIF('MVTO E'!$C$3:$C$240,"Vda_PIX",'MVTO E'!$P$3:$P$240)-SUMIF('MVTO E'!$C$3:$C$240,"Vda_S_PIX",'MVTO E'!$P$3:$P$240) -> 0 | BN5: =BM5/$I$10 -> 0 | BO5: =SUMIF('MVTO A'!$C$3:$C$184,"Vda_PIX",'MVTO A'!$P$3:$P$184)-SUMIF('MVTO A'!$C$3:$C$184,"Vda_S_PIX",'MVTO A'!$P$3:$P$184) -> 0 | BP5: =BO5/$K$10 -> 0 | BQ5: =BM5+BO5 -> 0 | BR5: =BQ5/$AA$10 -> 0 | BS5: =BQ5-BJ5 -> 0 | BT5: =SUMIF('MVTO E'!$C$3:$C$240,"Vda_PIX",'MVTO E'!$Q$3:$Q$240)-SUMIF('MVTO E'!$C$3:$C$240,"Vda_S_PIX",'MVTO E'!$Q$3:$Q$240) -> 0 | BU5: =BT5/$I$10 -> 0 | BV5: =SUMIF('MVTO A'!$C$3:$C$184,"Vda_PIX",'MVTO A'!$Q$3:$Q$184)-SUMIF('MVTO A'!$C$3:$C$184,"Vda_S_PIX",'MVTO A'!$Q$3:$Q$184) -> 0 | BW5: =BV5/$K$10 -> 0 | BX5: =BT5+BV5 -> 0 | BY5: =BX5/$AA$10 -> 0 | BZ5: =BX5-BQ5 -> 0 | CA5: =SUMIF('MVTO E'!$C$3:$C$240,"Vda_PIX",'MVTO E'!$R$3:$R$240)-SUMIF('MVTO E'!$C$3:$C$240,"Vda_S_PIX",'MVTO E'!$R$3:$R$240) -> 0 | CB5: =CA5/$I$10 -> 0 | CC5: =SUMIF('MVTO A'!$C$3:$C$184,"Vda_PIX",'MVTO A'!$R$3:$R$184)-SUMIF('MVTO A'!$C$3:$C$184,"Vda_S_PIX",'MVTO A'!$R$3:$R$184) -> 0 | CD5: =CC5/$K$10 -> 0 | CE5: =CA5+CC5 -> 0 | CF5: =CE5/$AA$10 -> 0 | CG5: =CE5-BX5 -> 0 | CH5: =SUM(C5,I5,P5,W5,AD5,AK5,AR5,AY5,BF5,BM5,BT5,CA5) -> 100803.62 | CI5: =CH5/$CH$10 -> 0.0010066536 | CJ5: =SUM(E5,K5,R5,Y5,AF5,AM5,AT5,BA5,BH5,BO5,BV5,CC5) -> 789493.18 | CK5: =CJ5/$CJ$10 -> 0.055683045 | CL5: =SUM(G5,M5,T5,AA5,AH5,AO5,AV5,BC5,BJ5,BQ5,BX5,CE5) -> 890296.8 | CM5: =CL5/$CL$10 -> 0.0077880545
B6: Vendas - Débito | C6: =SUMIF('MVTO E'!$C$3:$C$240,"Vda_Debito",'MVTO E'!$G$3:$G$240)-SUMIF('MVTO E'!$C$3:$C$240,"Vda_S_Deb",'MVTO E'!$G$3:$G$240) -> 5599965.6 | D6: =C6/$C$10 -> 0.17020651 | E6: =SUMIF('MVTO A'!$C$3:$C$184,"Vda_Debito",'MVTO A'!$G$3:$G$184)-SUMIF('MVTO A'!$C$3:$C$184,"Vda_S_Deb",'MVTO A'!$G$3:$G$184) -> 991436.74 | F6: =E6/$E$10 -> 0.2508869 | G6: =C6+E6 -> 6591402.3 | H6: =G6/$G$10 -> 0.17885788 | I6: =SUMIF('MVTO E'!$C$3:$C$240,"Vda_Debito",'MVTO E'!$H$3:$H$240)-SUMIF('MVTO E'!$C$3:$C$240,"Vda_S_Deb",'MVTO E'!$H$3:$H$240) -> 4567047.7 | J6: =I6/$I$10 -> 0.21512213 | K6: =SUMIF('MVTO A'!$C$3:$C$184,"Vda_Debito",'MVTO A'!$H$3:$H$184)-SUMIF('MVTO A'!$C$3:$C$184,"Vda_S_Deb",'MVTO A'!$H$3:$H$184) -> 776917.09 | L6: =K6/$K$10 -> 0.2272196 | M6: =I6+K6 -> 5343964.8 | N6: =M6/$M$10 -> 0.21680024 | O6: =M6-G6 -> -1247437.5 | P6: =SUMIF('MVTO E'!$C$3:$C$240,"Vda_Debito",'MVTO E'!$I$3:$I$240)-SUMIF('MVTO E'!$C$3:$C$240,"Vda_S_Deb",'MVTO E'!$I$3:$I$240) -> 5183789.5 | Q6: =P6/$I$10 -> 0.24417258 | R6: =SUMIF('MVTO A'!$C$3:$C$184,"Vda_Debito",'MVTO A'!$I$3:$I$184)-SUMIF('MVTO A'!$C$3:$C$184,"Vda_S_Deb",'MVTO A'!$I$3:$I$184) -> 903793.71 | S6: =R6/$K$10 -> 0.26432633 | T6: =P6+R6 -> 6087583.2 | U6: =T6/$T$10 -> 0.22170604 | V6: =T6-M6 -> 743618.37 | W6: =SUMIF('MVTO E'!$C$3:$C$240,"Vda_Debito",'MVTO E'!$J$3:$J$240)-SUMIF('MVTO E'!$C$3:$C$240,"Vda_S_Deb",'MVTO E'!$J$3:$J$240) -> 4670126.4 | X6: =W6/$I$10 -> 0.21997746 | Y6: =SUMIF('MVTO A'!$C$3:$C$184,"Vda_Debito",'MVTO A'!$J$3:$J$184)-SUMIF('MVTO A'!$C$3:$C$184,"Vda_S_Deb",'MVTO A'!$J$3:$J$184) -> 770320.33 | Z6: =Y6/$K$10 -> 0.22529029 | AA6: =W6+Y6 -> 5440446.7 | AB6: =AA6/$AA$10 -> 0.21456428 | AC6: =AA6-T6 -> -647136.45 | AD6: =SUMIF('MVTO E'!$C$3:$C$240,"Vda_Debito",'MVTO E'!$K$3:$K$240)-SUMIF('MVTO E'!$C$3:$C$240,"Vda_S_Deb",'MVTO E'!$K$3:$K$240) -> 0 | AE6: =AD6/$I$10 -> 0 | AF6: =SUMIF('MVTO A'!$C$3:$C$184,"Vda_Debito",'MVTO A'!$K$3:$K$184)-SUMIF('MVTO A'!$C$3:$C$184,"Vda_S_Deb",'MVTO A'!$K$3:$K$184) -> 0 | AG6: =AF6/$K$10 -> 0 | AH6: =AD6+AF6 -> 0 | AI6: =AH6/$AA$10 -> 0 | AJ6: =AH6-AA6 -> -5440446.7 | AK6: =SUMIF('MVTO E'!$C$3:$C$240,"Vda_Debito",'MVTO E'!$L$3:$L$240)-SUMIF('MVTO E'!$C$3:$C$240,"Vda_S_Deb",'MVTO E'!$L$3:$L$240) -> 0 | AL6: =AK6/$I$10 -> 0 | AM6: =SUMIF('MVTO A'!$C$3:$C$184,"Vda_Debito",'MVTO A'!$L$3:$L$184)-SUMIF('MVTO A'!$C$3:$C$184,"Vda_S_Deb",'MVTO A'!$L$3:$L$184) -> 0 | AN6: =AM6/$K$10 -> 0 | AO6: =AK6+AM6 -> 0 | AP6: =AO6/$AA$10 -> 0 | AQ6: =AO6-AH6 -> 0 | AR6: =SUMIF('MVTO E'!$C$3:$C$240,"Vda_Debito",'MVTO E'!$M$3:$M$240)-SUMIF('MVTO E'!$C$3:$C$240,"Vda_S_Deb",'MVTO E'!$M$3:$M$240) -> 0 | AS6: =AR6/$I$10 -> 0 | AT6: =SUMIF('MVTO A'!$C$3:$C$184,"Vda_Debito",'MVTO A'!$M$3:$M$184)-SUMIF('MVTO A'!$C$3:$C$184,"Vda_S_Deb",'MVTO A'!$M$3:$M$184) -> 0 | AU6: =AT6/$K$10 -> 0 | AV6: =AR6+AT6 -> 0 | AW6: =AV6/$AA$10 -> 0 | AX6: =AV6-AO6 -> 0 | AY6: =SUMIF('MVTO E'!$C$3:$C$240,"Vda_Debito",'MVTO E'!$N$3:$N$240)-SUMIF('MVTO E'!$C$3:$C$240,"Vda_S_Deb",'MVTO E'!$N$3:$N$240) -> 0 | AZ6: =AY6/$I$10 -> 0 | BA6: =SUMIF('MVTO A'!$C$3:$C$184,"Vda_Debito",'MVTO A'!$N$3:$N$184)-SUMIF('MVTO A'!$C$3:$C$184,"Vda_S_Deb",'MVTO A'!$N$3:$N$184) -> 0 | BB6: =BA6/$K$10 -> 0 | BC6: =AY6+BA6 -> 0 | BD6: =BC6/$AA$10 -> 0 | BE6: =BC6-AV6 -> 0 | BF6: =SUMIF('MVTO E'!$C$3:$C$240,"Vda_Debito",'MVTO E'!$O$3:$O$240)-SUMIF('MVTO E'!$C$3:$C$240,"Vda_S_Deb",'MVTO E'!$O$3:$O$240) -> 0 | BG6: =BF6/$I$10 -> 0 | BH6: =SUMIF('MVTO A'!$C$3:$C$184,"Vda_Debito",'MVTO A'!$O$3:$O$184)-SUMIF('MVTO A'!$C$3:$C$184,"Vda_S_Deb",'MVTO A'!$O$3:$O$184) -> 0 | BI6: =BH6/$K$10 -> 0 | BJ6: =BF6+BH6 -> 0 | BK6: =BJ6/$AA$10 -> 0 | BL6: =BJ6-BC6 -> 0 | BM6: =SUMIF('MVTO E'!$C$3:$C$240,"Vda_Debito",'MVTO E'!$P$3:$P$240)-SUMIF('MVTO E'!$C$3:$C$240,"Vda_S_Deb",'MVTO E'!$P$3:$P$240) -> 0 | BN6: =BM6/$I$10 -> 0 | BO6: =SUMIF('MVTO A'!$C$3:$C$184,"Vda_Debito",'MVTO A'!$P$3:$P$184)-SUMIF('MVTO A'!$C$3:$C$184,"Vda_S_Deb",'MVTO A'!$P$3:$P$184) -> 0 | BP6: =BO6/$K$10 -> 0 | BQ6: =BM6+BO6 -> 0 | BR6: =BQ6/$AA$10 -> 0 | BS6: =BQ6-BJ6 -> 0 | BT6: =SUMIF('MVTO E'!$C$3:$C$240,"Vda_Debito",'MVTO E'!$Q$3:$Q$240)-SUMIF('MVTO E'!$C$3:$C$240,"Vda_S_Deb",'MVTO E'!$Q$3:$Q$240) -> 0 | BU6: =BT6/$I$10 -> 0 | BV6: =SUMIF('MVTO A'!$C$3:$C$184,"Vda_Debito",'MVTO A'!$Q$3:$Q$184)-SUMIF('MVTO A'!$C$3:$C$184,"Vda_S_Deb",'MVTO A'!$Q$3:$Q$184) -> 0 | BW6: =BV6/$K$10 -> 0 | BX6: =BT6+BV6 -> 0 | BY6: =BX6/$AA$10 -> 0 | BZ6: =BX6-BQ6 -> 0 | CA6: =SUMIF('MVTO E'!$C$3:$C$240,"Vda_Debito",'MVTO E'!$R$3:$R$240)-SUMIF('MVTO E'!$C$3:$C$240,"Vda_S_Deb",'MVTO E'!$R$3:$R$240) -> 0 | CB6: =CA6/$I$10 -> 0 | CC6: =SUMIF('MVTO A'!$C$3:$C$184,"Vda_Debito",'MVTO A'!$R$3:$R$184)-SUMIF('MVTO A'!$C$3:$C$184,"Vda_S_Deb",'MVTO A'!$R$3:$R$184) -> 0 | CD6: =CC6/$K$10 -> 0 | CE6: =CA6+CC6 -> 0 | CF6: =CE6/$AA$10 -> 0 | CG6: =CE6-BX6 -> 0 | CH6: =SUM(C6,I6,P6,W6,AD6,AK6,AR6,AY6,BF6,BM6,BT6,CA6) -> 20020929 | CI6: =CH6/$CH$10 -> 0.19993469 | CJ6: =SUM(E6,K6,R6,Y6,AF6,AM6,AT6,BA6,BH6,BO6,BV6,CC6) -> 3442467.9 | CK6: =CJ6/$CJ$10 -> 0.24279766 | CL6: =SUM(G6,M6,T6,AA6,AH6,AO6,AV6,BC6,BJ6,BQ6,BX6,CE6) -> 23463397 | CM6: =CL6/$CL$10 -> 0.2052509
B7: Vendas - Crédito | C7: =SUMIF('MVTO E'!$C$3:$C$240,"Vda_Credito",'MVTO E'!$G$3:$G$240)-SUMIF('MVTO E'!$C$3:$C$240,"Vda_S_Cre",'MVTO E'!$G$3:$G$240) -> 20084101 | D7: =C7/$C$10 -> 0.61044029 | E7: =SUMIF('MVTO A'!$C$3:$C$184,"Vda_Credito",'MVTO A'!$G$3:$G$184)-SUMIF('MVTO A'!$C$3:$C$184,"Vda_S_Cre",'MVTO A'!$G$3:$G$184) -> 2297155.8 | F7: =E7/$E$10 -> 0.58130416 | G7: =C7+E7 -> 22381256 | H7: =G7/$G$10 -> 0.60731601 | I7: =SUMIF('MVTO E'!$C$3:$C$240,"Vda_Credito",'MVTO E'!$H$3:$H$240)-SUMIF('MVTO E'!$C$3:$C$240,"Vda_S_Cre",'MVTO E'!$H$3:$H$240) -> 10918480 | J7: =I7/$I$10 -> 0.51429433 | K7: =SUMIF('MVTO A'!$C$3:$C$184,"Vda_Credito",'MVTO A'!$H$3:$H$184)-SUMIF('MVTO A'!$C$3:$C$184,"Vda_S_Cre",'MVTO A'!$H$3:$H$184) -> 2042355.7 | L7: =K7/$K$10 -> 0.59731373 | M7: =I7+K7 -> 12960836 | N7: =M7/$M$10 -> 0.52581041 | O7: =M7-G7 -> -9420420.3 | P7: =SUMIF('MVTO E'!$C$3:$C$240,"Vda_Credito",'MVTO E'!$I$3:$I$240)-SUMIF('MVTO E'!$C$3:$C$240,"Vda_S_Cre",'MVTO E'!$I$3:$I$240) -> 12259326 | Q7: =P7/$I$10 -> 0.57745234 | R7: =SUMIF('MVTO A'!$C$3:$C$184,"Vda_Credito",'MVTO A'!$I$3:$I$184)-SUMIF('MVTO A'!$C$3:$C$184,"Vda_S_Cre",'MVTO A'!$I$3:$I$184) -> 2074024.7 | S7: =R7/$K$10 -> 0.60657573 | T7: =P7+R7 -> 14333351 | U7: =T7/$T$10 -> 0.52201184 | V7: =T7-M7 -> 1372515 | W7: =SUMIF('MVTO E'!$C$3:$C$240,"Vda_Credito",'MVTO E'!$J$3:$J$240)-SUMIF('MVTO E'!$C$3:$C$240,"Vda_S_Cre",'MVTO E'!$J$3:$J$240) -> 10963833 | X7: =W7/$I$10 -> 0.51643056 | Y7: =SUMIF('MVTO A'!$C$3:$C$184,"Vda_Credito",'MVTO A'!$J$3:$J$184)-SUMIF('MVTO A'!$C$3:$C$184,"Vda_S_Cre",'MVTO A'!$J$3:$J$184) -> 1957630.4 | Z7: =Y7/$K$10 -> 0.57253469 | AA7: =W7+Y7 -> 12921463 | AB7: =AA7/$AA$10 -> 0.50960603 | AC7: =AA7-T7 -> -1411888 | AD7: =SUMIF('MVTO E'!$C$3:$C$240,"Vda_Credito",'MVTO E'!$K$3:$K$240)-SUMIF('MVTO E'!$C$3:$C$240,"Vda_S_Cre",'MVTO E'!$K$3:$K$240) -> 0 | AE7: =AD7/$I$10 -> 0 | AF7: =SUMIF('MVTO A'!$C$3:$C$184,"Vda_Credito",'MVTO A'!$K$3:$K$184)-SUMIF('MVTO A'!$C$3:$C$184,"Vda_S_Cre",'MVTO A'!$K$3:$K$184) -> 0 | AG7: =AF7/$K$10 -> 0 | AH7: =AD7+AF7 -> 0 | AI7: =AH7/$AA$10 -> 0 | AJ7: =AH7-AA7 -> -12921463 | AK7: =SUMIF('MVTO E'!$C$3:$C$240,"Vda_Credito",'MVTO E'!$L$3:$L$240)-SUMIF('MVTO E'!$C$3:$C$240,"Vda_S_Cre",'MVTO E'!$L$3:$L$240) -> 0 | AL7: =AK7/$I$10 -> 0 | AM7: =SUMIF('MVTO A'!$C$3:$C$184,"Vda_Credito",'MVTO A'!$L$3:$L$184)-SUMIF('MVTO A'!$C$3:$C$184,"Vda_S_Cre",'MVTO A'!$L$3:$L$184) -> 0 | AN7: =AM7/$K$10 -> 0 | AO7: =AK7+AM7 -> 0 | AP7: =AO7/$AA$10 -> 0 | AQ7: =AO7-AH7 -> 0 | AR7: =SUMIF('MVTO E'!$C$3:$C$240,"Vda_Credito",'MVTO E'!$M$3:$M$240)-SUMIF('MVTO E'!$C$3:$C$240,"Vda_S_Cre",'MVTO E'!$M$3:$M$240) -> 0 | AS7: =AR7/$I$10 -> 0 | AT7: =SUMIF('MVTO A'!$C$3:$C$184,"Vda_Credito",'MVTO A'!$M$3:$M$184)-SUMIF('MVTO A'!$C$3:$C$184,"Vda_S_Cre",'MVTO A'!$M$3:$M$184) -> 0 | AU7: =AT7/$K$10 -> 0 | AV7: =AR7+AT7 -> 0 | AW7: =AV7/$AA$10 -> 0 | AX7: =AV7-AO7 -> 0 | AY7: =SUMIF('MVTO E'!$C$3:$C$240,"Vda_Credito",'MVTO E'!$N$3:$N$240)-SUMIF('MVTO E'!$C$3:$C$240,"Vda_S_Cre",'MVTO E'!$N$3:$N$240) -> 0 | AZ7: =AY7/$I$10 -> 0 | BA7: =SUMIF('MVTO A'!$C$3:$C$184,"Vda_Credito",'MVTO A'!$N$3:$N$184)-SUMIF('MVTO A'!$C$3:$C$184,"Vda_S_Cre",'MVTO A'!$N$3:$N$184) -> 0 | BB7: =BA7/$K$10 -> 0 | BC7: =AY7+BA7 -> 0 | BD7: =BC7/$AA$10 -> 0 | BE7: =BC7-AV7 -> 0 | BF7: =SUMIF('MVTO E'!$C$3:$C$240,"Vda_Credito",'MVTO E'!$O$3:$O$240)-SUMIF('MVTO E'!$C$3:$C$240,"Vda_S_Cre",'MVTO E'!$O$3:$O$240) -> 0 | BG7: =BF7/$I$10 -> 0 | BH7: =SUMIF('MVTO A'!$C$3:$C$184,"Vda_Credito",'MVTO A'!$O$3:$O$184)-SUMIF('MVTO A'!$C$3:$C$184,"Vda_S_Cre",'MVTO A'!$O$3:$O$184) -> 0 | BI7: =BH7/$K$10 -> 0 | BJ7: =BF7+BH7 -> 0 | BK7: =BJ7/$AA$10 -> 0 | BL7: =BJ7-BC7 -> 0 | BM7: =SUMIF('MVTO E'!$C$3:$C$240,"Vda_Credito",'MVTO E'!$P$3:$P$240)-SUMIF('MVTO E'!$C$3:$C$240,"Vda_S_Cre",'MVTO E'!$P$3:$P$240) -> 0 | BN7: =BM7/$I$10 -> 0 | BO7: =SUMIF('MVTO A'!$C$3:$C$184,"Vda_Credito",'MVTO A'!$P$3:$P$184)-SUMIF('MVTO A'!$C$3:$C$184,"Vda_S_Cre",'MVTO A'!$P$3:$P$184) -> 0 | BP7: =BO7/$K$10 -> 0 | BQ7: =BM7+BO7 -> 0 | BR7: =BQ7/$AA$10 -> 0 | BS7: =BQ7-BJ7 -> 0 | BT7: =SUMIF('MVTO E'!$C$3:$C$240,"Vda_Credito",'MVTO E'!$Q$3:$Q$240)-SUMIF('MVTO E'!$C$3:$C$240,"Vda_S_Cre",'MVTO E'!$Q$3:$Q$240) -> 0 | BU7: =BT7/$I$10 -> 0 | BV7: =SUMIF('MVTO A'!$C$3:$C$184,"Vda_Credito",'MVTO A'!$Q$3:$Q$184)-SUMIF('MVTO A'!$C$3:$C$184,"Vda_S_Cre",'MVTO A'!$Q$3:$Q$184) -> 0 | BW7: =BV7/$K$10 -> 0 | BX7: =BT7+BV7 -> 0 | BY7: =BX7/$AA$10 -> 0 | BZ7: =BX7-BQ7 -> 0 | CA7: =SUMIF('MVTO E'!$C$3:$C$240,"Vda_Credito",'MVTO E'!$R$3:$R$240)-SUMIF('MVTO E'!$C$3:$C$240,"Vda_S_Cre",'MVTO E'!$R$3:$R$240) -> 0 | CB7: =CA7/$I$10 -> 0 | CC7: =SUMIF('MVTO A'!$C$3:$C$184,"Vda_Credito",'MVTO A'!$R$3:$R$184)-SUMIF('MVTO A'!$C$3:$C$184,"Vda_S_Cre",'MVTO A'!$R$3:$R$184) -> 0 | CD7: =CC7/$K$10 -> 0 | CE7: =CA7+CC7 -> 0 | CF7: =CE7/$AA$10 -> 0 | CG7: =CE7-BX7 -> 0 | CH7: =SUM(C7,I7,P7,W7,AD7,AK7,AR7,AY7,BF7,BM7,BT7,CA7) -> 54225740 | CI7: =CH7/$CH$10 -> 0.54151366 | CJ7: =SUM(E7,K7,R7,Y7,AF7,AM7,AT7,BA7,BH7,BO7,BV7,CC7) -> 8371166.5 | CK7: =CJ7/$CJ$10 -> 0.59041934 | CL7: =SUM(G7,M7,T7,AA7,AH7,AO7,AV7,BC7,BJ7,BQ7,BX7,CE7) -> 62596907 | CM7: =CL7/$CL$10 -> 0.54757933
B8: Vendas - Ticket | C8: =SUMIF('MVTO E'!$C$3:$C$240,"Vda_Ticket",'MVTO E'!$G$3:$G$240)-SUMIF('MVTO E'!$C$3:$C$240,"Vda_S_Ticket",'MVTO E'!$G$3:$G$240) -> 4601459 | D8: =C8/$C$10 -> 0.13985769 | E8: =SUMIF('MVTO A'!$C$3:$C$184,"Vda_Ticket",'MVTO A'!$G$3:$G$184)-SUMIF('MVTO A'!$C$3:$C$184,"Vda_S_Ticket",'MVTO A'!$G$3:$G$184) -> 11369.36 | F8: =E8/$E$10 -> 0.0028770606 | G8: =C8+E8 -> 4612828.4 | H8: =G8/$G$10 -> 0.12516923 | I8: =SUMIF('MVTO E'!$C$3:$C$240,"Vda_Ticket",'MVTO E'!$H$3:$H$240)-SUMIF('MVTO E'!$C$3:$C$240,"Vda_S_Ticket",'MVTO E'!$H$3:$H$240) -> 3733267.5 | J8: =I8/$I$10 -> 0.17584849 | K8: =SUMIF('MVTO A'!$C$3:$C$184,"Vda_Ticket",'MVTO A'!$H$3:$H$184)-SUMIF('MVTO A'!$C$3:$C$184,"Vda_S_Ticket",'MVTO A'!$H$3:$H$184) -> 7082.82 | L8: =K8/$K$10 -> 0.0020714637 | M8: =I8+K8 -> 3740350.4 | N8: =M8/$M$10 -> 0.15174292 | O8: =M8-G8 -> -872478.04 | P8: =SUMIF('MVTO E'!$C$3:$C$240,"Vda_Ticket",'MVTO E'!$I$3:$I$240)-SUMIF('MVTO E'!$C$3:$C$240,"Vda_S_Ticket",'MVTO E'!$I$3:$I$240) -> 4398041.3 | Q8: =P8/$I$10 -> 0.2071614 | R8: =SUMIF('MVTO A'!$C$3:$C$184,"Vda_Ticket",'MVTO A'!$I$3:$I$184)-SUMIF('MVTO A'!$C$3:$C$184,"Vda_S_Ticket",'MVTO A'!$I$3:$I$184) -> 15070.53 | S8: =R8/$K$10 -> 0.0044075743 | T8: =P8+R8 -> 4413111.8 | U8: =T8/$T$10 -> 0.16072282 | V8: =T8-M8 -> 672761.45 | W8: =SUMIF('MVTO E'!$C$3:$C$240,"Vda_Ticket",'MVTO E'!$J$3:$J$240)-SUMIF('MVTO E'!$C$3:$C$240,"Vda_S_Ticket",'MVTO E'!$J$3:$J$240) -> 3932518.1 | X8: =W8/$I$10 -> 0.18523381 | Y8: =SUMIF('MVTO A'!$C$3:$C$184,"Vda_Ticket",'MVTO A'!$J$3:$J$184)-SUMIF('MVTO A'!$C$3:$C$184,"Vda_S_Ticket",'MVTO A'!$J$3:$J$184) -> 10029.76 | Z8: =Y8/$K$10 -> 0.0029333349 | AA8: =W8+Y8 -> 3942547.8 | AB8: =AA8/$AA$10 -> 0.15548906 | AC8: =AA8-T8 -> -470563.99 | AD8: =SUMIF('MVTO E'!$C$3:$C$240,"Vda_Ticket",'MVTO E'!$K$3:$K$240)-SUMIF('MVTO E'!$C$3:$C$240,"Vda_S_Ticket",'MVTO E'!$K$3:$K$240) -> 0 | AE8: =AD8/$I$10 -> 0 | AF8: =SUMIF('MVTO A'!$C$3:$C$184,"Vda_Ticket",'MVTO A'!$K$3:$K$184)-SUMIF('MVTO A'!$C$3:$C$184,"Vda_S_Ticket",'MVTO A'!$K$3:$K$184) -> 0 | AG8: =AF8/$K$10 -> 0 | AH8: =AD8+AF8 -> 0 | AI8: =AH8/$AA$10 -> 0 | AJ8: =AH8-AA8 -> -3942547.8 | AK8: =SUMIF('MVTO E'!$C$3:$C$240,"Vda_Ticket",'MVTO E'!$L$3:$L$240)-SUMIF('MVTO E'!$C$3:$C$240,"Vda_S_Ticket",'MVTO E'!$L$3:$L$240) -> 0 | AL8: =AK8/$I$10 -> 0 | AM8: =SUMIF('MVTO A'!$C$3:$C$184,"Vda_Ticket",'MVTO A'!$L$3:$L$184)-SUMIF('MVTO A'!$C$3:$C$184,"Vda_S_Ticket",'MVTO A'!$L$3:$L$184) -> 0 | AN8: =AM8/$K$10 -> 0 | AO8: =AK8+AM8 -> 0 | AP8: =AO8/$AA$10 -> 0 | AQ8: =AO8-AH8 -> 0 | AR8: =SUMIF('MVTO E'!$C$3:$C$240,"Vda_Ticket",'MVTO E'!$M$3:$M$240)-SUMIF('MVTO E'!$C$3:$C$240,"Vda_S_Ticket",'MVTO E'!$M$3:$M$240) -> 0 | AS8: =AR8/$I$10 -> 0 | AT8: =SUMIF('MVTO A'!$C$3:$C$184,"Vda_Ticket",'MVTO A'!$M$3:$M$184)-SUMIF('MVTO A'!$C$3:$C$184,"Vda_S_Ticket",'MVTO A'!$M$3:$M$184) -> 0 | AU8: =AT8/$K$10 -> 0 | AV8: =AR8+AT8 -> 0 | AW8: =AV8/$AA$10 -> 0 | AX8: =AV8-AO8 -> 0 | AY8: =SUMIF('MVTO E'!$C$3:$C$240,"Vda_Ticket",'MVTO E'!$N$3:$N$240)-SUMIF('MVTO E'!$C$3:$C$240,"Vda_S_Ticket",'MVTO E'!$N$3:$N$240) -> 0 | AZ8: =AY8/$I$10 -> 0 | BA8: =SUMIF('MVTO A'!$C$3:$C$184,"Vda_Ticket",'MVTO A'!$N$3:$N$184)-SUMIF('MVTO A'!$C$3:$C$184,"Vda_S_Ticket",'MVTO A'!$N$3:$N$184) -> 0 | BB8: =BA8/$K$10 -> 0 | BC8: =AY8+BA8 -> 0 | BD8: =BC8/$AA$10 -> 0 | BE8: =BC8-AV8 -> 0 | BF8: =SUMIF('MVTO E'!$C$3:$C$240,"Vda_Ticket",'MVTO E'!$O$3:$O$240)-SUMIF('MVTO E'!$C$3:$C$240,"Vda_S_Ticket",'MVTO E'!$O$3:$O$240) -> 0 | BG8: =BF8/$I$10 -> 0 | BH8: =SUMIF('MVTO A'!$C$3:$C$184,"Vda_Ticket",'MVTO A'!$O$3:$O$184)-SUMIF('MVTO A'!$C$3:$C$184,"Vda_S_Ticket",'MVTO A'!$O$3:$O$184) -> 0 | BI8: =BH8/$K$10 -> 0 | BJ8: =BF8+BH8 -> 0 | BK8: =BJ8/$AA$10 -> 0 | BL8: =BJ8-BC8 -> 0 | BM8: =SUMIF('MVTO E'!$C$3:$C$240,"Vda_Ticket",'MVTO E'!$P$3:$P$240)-SUMIF('MVTO E'!$C$3:$C$240,"Vda_S_Ticket",'MVTO E'!$P$3:$P$240) -> 0 | BN8: =BM8/$I$10 -> 0 | BO8: =SUMIF('MVTO A'!$C$3:$C$184,"Vda_Ticket",'MVTO A'!$P$3:$P$184)-SUMIF('MVTO A'!$C$3:$C$184,"Vda_S_Ticket",'MVTO A'!$P$3:$P$184) -> 0 | BP8: =BO8/$K$10 -> 0 | BQ8: =BM8+BO8 -> 0 | BR8: =BQ8/$AA$10 -> 0 | BS8: =BQ8-BJ8 -> 0 | BT8: =SUMIF('MVTO E'!$C$3:$C$240,"Vda_Ticket",'MVTO E'!$Q$3:$Q$240)-SUMIF('MVTO E'!$C$3:$C$240,"Vda_S_Ticket",'MVTO E'!$Q$3:$Q$240) -> 0 | BU8: =BT8/$I$10 -> 0 | BV8: =SUMIF('MVTO A'!$C$3:$C$184,"Vda_Ticket",'MVTO A'!$Q$3:$Q$184)-SUMIF('MVTO A'!$C$3:$C$184,"Vda_S_Ticket",'MVTO A'!$Q$3:$Q$184) -> 0 | BW8: =BV8/$K$10 -> 0 | BX8: =BT8+BV8 -> 0 | BY8: =BX8/$AA$10 -> 0 | BZ8: =BX8-BQ8 -> 0 | CA8: =SUMIF('MVTO E'!$C$3:$C$240,"Vda_Ticket",'MVTO E'!$R$3:$R$240)-SUMIF('MVTO E'!$C$3:$C$240,"Vda_S_Ticket",'MVTO E'!$R$3:$R$240) -> 0 | CB8: =CA8/$I$10 -> 0 | CC8: =SUMIF('MVTO A'!$C$3:$C$184,"Vda_Ticket",'MVTO A'!$R$3:$R$184)-SUMIF('MVTO A'!$C$3:$C$184,"Vda_S_Ticket",'MVTO A'!$R$3:$R$184) -> 0 | CD8: =CC8/$K$10 -> 0 | CE8: =CA8+CC8 -> 0 | CF8: =CE8/$AA$10 -> 0 | CG8: =CE8-BX8 -> 0 | CH8: =SUM(C8,I8,P8,W8,AD8,AK8,AR8,AY8,BF8,BM8,BT8,CA8) -> 16665286 | CI8: =CH8/$CH$10 -> 0.16642428 | CJ8: =SUM(E8,K8,R8,Y8,AF8,AM8,AT8,BA8,BH8,BO8,BV8,CC8) -> 43552.47 | CK8: =CJ8/$CJ$10 -> 0.0030717607 | CL8: =SUM(G8,M8,T8,AA8,AH8,AO8,AV8,BC8,BJ8,BQ8,BX8,CE8) -> 16708838 | CM8: =CL8/$CL$10 -> 0.146164
B9: Vendas - Clientes | C9: =SUMIF('MVTO E'!$C$3:$C$240,"Vda_Prazo",'MVTO E'!$G$3:$G$240)-SUMIF('MVTO E'!$C$3:$C$240,"Vda_S_Pz",'MVTO E'!$G$3:$G$240) -> 975612.51 | D9: =C9/$C$10 -> 0.029652967 | E9: =SUMIF('MVTO A'!$C$3:$C$184,"Vda_Prazo",'MVTO A'!$G$3:$G$184)-SUMIF('MVTO A'!$C$3:$C$184,"Vda_S_Pz",'MVTO A'!$G$3:$G$184) -> 421361.23 | F9: =E9/$E$10 -> 0.10662709 | G9: =C9+E9 -> 1396973.7 | H9: =G9/$G$10 -> 0.037906921 | I9: =SUMIF('MVTO E'!$C$3:$C$240,"Vda_Prazo",'MVTO E'!$H$3:$H$240)-SUMIF('MVTO E'!$C$3:$C$240,"Vda_S_Pz",'MVTO E'!$H$3:$H$240) -> 508506.3 | J9: =I9/$I$10 -> 0.023952226 | K9: =SUMIF('MVTO A'!$C$3:$C$184,"Vda_Prazo",'MVTO A'!$H$3:$H$184)-SUMIF('MVTO A'!$C$3:$C$184,"Vda_S_Pz",'MVTO A'!$H$3:$H$184) -> 406924.34 | L9: =K9/$K$10 -> 0.11901036 | M9: =I9+K9 -> 915430.64 | N9: =M9/$M$10 -> 0.037138264 | O9: =M9-G9 -> -481543.1 | P9: =SUMIF('MVTO E'!$C$3:$C$240,"Vda_Prazo",'MVTO E'!$I$3:$I$240)-SUMIF('MVTO E'!$C$3:$C$240,"Vda_S_Pz",'MVTO E'!$I$3:$I$240) -> 465125.84 | Q9: =P9/$I$10 -> 0.021908871 | R9: =SUMIF('MVTO A'!$C$3:$C$184,"Vda_Prazo",'MVTO A'!$I$3:$I$184)-SUMIF('MVTO A'!$C$3:$C$184,"Vda_S_Pz",'MVTO A'!$I$3:$I$184) -> 448900.38 | S9: =R9/$K$10 -> 0.13128681 | T9: =P9+R9 -> 914026.22 | U9: =T9/$T$10 -> 0.033288273 | V9: =T9-M9 -> -1404.42 | W9: =SUMIF('MVTO E'!$C$3:$C$240,"Vda_Prazo",'MVTO E'!$J$3:$J$240)-SUMIF('MVTO E'!$C$3:$C$240,"Vda_S_Pz",'MVTO E'!$J$3:$J$240) -> 1168204.4 | X9: =W9/$I$10 -> 0.055026056 | Y9: =SUMIF('MVTO A'!$C$3:$C$184,"Vda_Prazo",'MVTO A'!$J$3:$J$184)-SUMIF('MVTO A'!$C$3:$C$184,"Vda_S_Pz",'MVTO A'!$J$3:$J$184) -> 254474.69 | Z9: =Y9/$K$10 -> 0.074424463 | AA9: =W9+Y9 -> 1422679.1 | AB9: =AA9/$AA$10 -> 0.05610865 | AC9: =AA9-T9 -> 508652.9 | AD9: =SUMIF('MVTO E'!$C$3:$C$240,"Vda_Prazo",'MVTO E'!$K$3:$K$240)-SUMIF('MVTO E'!$C$3:$C$240,"Vda_S_Pz",'MVTO E'!$K$3:$K$240) -> 0 | AE9: =AD9/$I$10 -> 0 | AF9: =SUMIF('MVTO A'!$C$3:$C$184,"Vda_Prazo",'MVTO A'!$K$3:$K$184)-SUMIF('MVTO A'!$C$3:$C$184,"Vda_S_Pz",'MVTO A'!$K$3:$K$184) -> 0 | AG9: =AF9/$K$10 -> 0 | AH9: =AD9+AF9 -> 0 | AI9: =AH9/$AA$10 -> 0 | AJ9: =AH9-AA9 -> -1422679.1 | AK9: =SUMIF('MVTO E'!$C$3:$C$240,"Vda_Prazo",'MVTO E'!$L$3:$L$240)-SUMIF('MVTO E'!$C$3:$C$240,"Vda_S_Pz",'MVTO E'!$L$3:$L$240) -> 0 | AL9: =AK9/$I$10 -> 0 | AM9: =SUMIF('MVTO A'!$C$3:$C$184,"Vda_Prazo",'MVTO A'!$L$3:$L$184)-SUMIF('MVTO A'!$C$3:$C$184,"Vda_S_Pz",'MVTO A'!$L$3:$L$184) -> 0 | AN9: =AM9/$K$10 -> 0 | AO9: =AK9+AM9 -> 0 | AP9: =AO9/$AA$10 -> 0 | AQ9: =AO9-AH9 -> 0 | AR9: =SUMIF('MVTO E'!$C$3:$C$240,"Vda_Prazo",'MVTO E'!$M$3:$M$240)-SUMIF('MVTO E'!$C$3:$C$240,"Vda_S_Pz",'MVTO E'!$M$3:$M$240) -> 0 | AS9: =AR9/$I$10 -> 0 | AT9: =SUMIF('MVTO A'!$C$3:$C$184,"Vda_Prazo",'MVTO A'!$M$3:$M$184)-SUMIF('MVTO A'!$C$3:$C$184,"Vda_S_Pz",'MVTO A'!$M$3:$M$184) -> 0 | AU9: =AT9/$K$10 -> 0 | AV9: =AR9+AT9 -> 0 | AW9: =AV9/$AA$10 -> 0 | AX9: =AV9-AO9 -> 0 | AY9: =SUMIF('MVTO E'!$C$3:$C$240,"Vda_Prazo",'MVTO E'!$N$3:$N$240)-SUMIF('MVTO E'!$C$3:$C$240,"Vda_S_Pz",'MVTO E'!$N$3:$N$240) -> 0 | AZ9: =AY9/$I$10 -> 0 | BA9: =SUMIF('MVTO A'!$C$3:$C$184,"Vda_Prazo",'MVTO A'!$N$3:$N$184)-SUMIF('MVTO A'!$C$3:$C$184,"Vda_S_Pz",'MVTO A'!$N$3:$N$184) -> 0 | BB9: =BA9/$K$10 -> 0 | BC9: =AY9+BA9 -> 0 | BD9: =BC9/$AA$10 -> 0 | BE9: =BC9-AV9 -> 0 | BF9: =SUMIF('MVTO E'!$C$3:$C$240,"Vda_Prazo",'MVTO E'!$O$3:$O$240)-SUMIF('MVTO E'!$C$3:$C$240,"Vda_S_Pz",'MVTO E'!$O$3:$O$240) -> 0 | BG9: =BF9/$I$10 -> 0 | BH9: =SUMIF('MVTO A'!$C$3:$C$184,"Vda_Prazo",'MVTO A'!$O$3:$O$184)-SUMIF('MVTO A'!$C$3:$C$184,"Vda_S_Pz",'MVTO A'!$O$3:$O$184) -> 0 | BI9: =BH9/$K$10 -> 0 | BJ9: =BF9+BH9 -> 0 | BK9: =BJ9/$AA$10 -> 0 | BL9: =BJ9-BC9 -> 0 | BM9: =SUMIF('MVTO E'!$C$3:$C$240,"Vda_Prazo",'MVTO E'!$P$3:$P$240)-SUMIF('MVTO E'!$C$3:$C$240,"Vda_S_Pz",'MVTO E'!$P$3:$P$240) -> 0 | BN9: =BM9/$I$10 -> 0 | BO9: =SUMIF('MVTO A'!$C$3:$C$184,"Vda_Prazo",'MVTO A'!$P$3:$P$184)-SUMIF('MVTO A'!$C$3:$C$184,"Vda_S_Pz",'MVTO A'!$P$3:$P$184) -> 0 | BP9: =BO9/$K$10 -> 0 | BQ9: =BM9+BO9 -> 0 | BR9: =BQ9/$AA$10 -> 0 | BS9: =BQ9-BJ9 -> 0 | BT9: =SUMIF('MVTO E'!$C$3:$C$240,"Vda_Prazo",'MVTO E'!$Q$3:$Q$240)-SUMIF('MVTO E'!$C$3:$C$240,"Vda_S_Pz",'MVTO E'!$Q$3:$Q$240) -> 0 | BU9: =BT9/$I$10 -> 0 | BV9: =SUMIF('MVTO A'!$C$3:$C$184,"Vda_Prazo",'MVTO A'!$Q$3:$Q$184)-SUMIF('MVTO A'!$C$3:$C$184,"Vda_S_Pz",'MVTO A'!$Q$3:$Q$184) -> 0 | BW9: =BV9/$K$10 -> 0 | BX9: =BT9+BV9 -> 0 | BY9: =BX9/$AA$10 -> 0 | BZ9: =BX9-BQ9 -> 0 | CA9: =SUMIF('MVTO E'!$C$3:$C$240,"Vda_Prazo",'MVTO E'!$R$3:$R$240)-SUMIF('MVTO E'!$C$3:$C$240,"Vda_S_Pz",'MVTO E'!$R$3:$R$240) -> 0 | CB9: =CA9/$I$10 -> 0 | CC9: =SUMIF('MVTO A'!$C$3:$C$184,"Vda_Prazo",'MVTO A'!$R$3:$R$184)-SUMIF('MVTO A'!$C$3:$C$184,"Vda_S_Pz",'MVTO A'!$R$3:$R$184) -> 0 | CD9: =CC9/$K$10 -> 0 | CE9: =CA9+CC9 -> 0 | CF9: =CE9/$AA$10 -> 0 | CG9: =CE9-BX9 -> 0 | CH9: =SUM(C9,I9,P9,W9,AD9,AK9,AR9,AY9,BF9,BM9,BT9,CA9) -> 3117449.1 | CI9: =CH9/$CH$10 -> 0.031131733 | CJ9: =SUM(E9,K9,R9,Y9,AF9,AM9,AT9,BA9,BH9,BO9,BV9,CC9) -> 1531660.6 | CK9: =CJ9/$CJ$10 -> 0.1080282 | CL9: =SUM(G9,M9,T9,AA9,AH9,AO9,AV9,BC9,BJ9,BQ9,BX9,CE9) -> 4649109.7 | CM9: =CL9/$CL$10 -> 0.040669044
B10: Vendas - Total | C10: =SUM(C4:C9) -> 32901008 | D10: =SUM(D4:D9) -> 1 | E10: =SUM(E4:E9) -> 3951727.7 | F10: =SUM(F4:F9) -> 1 | G10: =C10+E10 -> 36852735 | H10: =SUM(H4:H9) -> 1 | I10: =SUM(I4:I9) -> 21230023 | J10: =SUM(J4:J9) -> 1 | K10: =SUM(K4:K9) -> 3419234.5 | L10: =SUM(L4:L9) -> 1 | M10: =I10+K10 -> 24649257 | N10: =SUM(N4:N9) -> 1 | O10: =M10-G10 -> -12203478 | P10: =SUM(P4:P9) -> 23807320 | Q10: =SUM(Q4:Q9) -> 1.1213987 | R10: =SUM(R4:R9) -> 3650584.5 | S10: =SUM(S4:S9) -> 1.0676614 | T10: =P10+R10 -> 27457904 | U10: =SUM(U4:U9) -> 1 | V10: =T10-M10 -> 2808646.8 | W10: =SUM(W4:W9) -> 22198995 | X10: =W10/$W$10 -> 1 | Y10: =SUM(Y4:Y9) -> 3156793.9 | Z10: =Y10/$Y$10 -> 1 | AA10: =W10+Y10 -> 25355789 | AB10: =SUM(AB4:AB9) -> 1 | AC10: =AA10-T10 -> -2102114.9 | AD10: =SUM(AD4:AD9) -> 0 | AE10: =AD10/$AD$10 -> #DIV/0! | AF10: =SUM(AF4:AF9) -> 0 | AG10: =AF10/$AF$10 -> #DIV/0! | AH10: =AD10+AF10 -> 0 | AI10: =SUM(AI4:AI9) -> 0 | AJ10: =AH10-AA10 -> -25355789 | AK10: =SUM(AK4:AK9) -> 0 | AL10: =AK10/$AK$10 -> #DIV/0! | AM10: =SUM(AM4:AM9) -> 0 | AN10: =AM10/$AM$10 -> #DIV/0! | AO10: =AK10+AM10 -> 0 | AP10: =SUM(AP4:AP9) -> 0 | AQ10: =AO10-AH10 -> 0 | AR10: =SUM(AR4:AR9) -> 0 | AS10: =AR10/$AR$10 -> #DIV/0! | AT10: =SUM(AT4:AT9) -> 0 | AU10: =AT10/$AT$10 -> #DIV/0! | AV10: =AR10+AT10 -> 0 | AW10: =SUM(AW4:AW9) -> 0 | AX10: =AV10-AO10 -> 0 | AY10: =SUM(AY4:AY9) -> 0 | AZ10: =AY10/$AY$10 -> #DIV/0! | BA10: =SUM(BA4:BA9) -> 0 | BB10: =BA10/$BA$10 -> #DIV/0! | BC10: =AY10+BA10 -> 0 | BD10: =SUM(BD4:BD9) -> 0 | BE10: =BC10-AV10 -> 0 | BF10: =SUM(BF4:BF9) -> 0 | BG10: =BF10/$BF$10 -> #DIV/0! | BH10: =SUM(BH4:BH9) -> 0 | BI10: =BH10/$BH$10 -> #DIV/0! | BJ10: =BF10+BH10 -> 0 | BK10: =SUM(BK4:BK9) -> 0 | BL10: =BJ10-BC10 -> 0 | BM10: =SUM(BM4:BM9) -> 0 | BN10: =BM10/$BF$10 -> #DIV/0! | BO10: =SUM(BO4:BO9) -> 0 | BP10: =BO10/$BH$10 -> #DIV/0! | BQ10: =BM10+BO10 -> 0 | BR10: =SUM(BR4:BR9) -> 0 | BS10: =BQ10-BJ10 -> 0 | BT10: =SUM(BT4:BT9) -> 0 | BU10: =BT10/$BF$10 -> #DIV/0! | BV10: =SUM(BV4:BV9) -> 0 | BW10: =BV10/$BH$10 -> #DIV/0! | BX10: =BT10+BV10 -> 0 | BY10: =SUM(BY4:BY9) -> 0 | BZ10: =BX10-BQ10 -> 0 | CA10: =SUM(CA4:CA9) -> 0 | CB10: =CA10/$BF$10 -> #DIV/0! | CC10: =SUM(CC4:CC9) -> 0 | CD10: =CC10/$BH$10 -> #DIV/0! | CE10: =CA10+CC10 -> 0 | CF10: =SUM(CF4:CF9) -> 0 | CG10: =CE10-BX10 -> 0 | CH10: =SUM(C10,I10,P10,W10,AD10,AK10,AR10,AY10,BF10,BM10,BT10,CA10) -> 1.0013735e+08 | CI10: =CH10/$CH$10 -> 1 | CJ10: =SUM(E10,K10,R10,Y10,AF10,AM10,AT10,BA10,BH10,BO10,BV10,CC10) -> 14178341 | CK10: =CJ10/$CJ$10 -> 1 | CL10: =SUM(G10,M10,T10,AA10,AH10,AO10,AV10,BC10,BJ10,BQ10,BX10,CE10) -> 1.1431569e+08 | CM10: =CL10/$CL$10 -> 1
B11: ( - ) Deduções | C11: =SUMIF('MVTO E'!$C$3:$C$240,"S_Deduções",'MVTO E'!$G$3:$G$240) -> 65385 | D11: =C11/$C$10 -> 0.0019873252 | E11: =SUMIF('MVTO A'!$C$3:$C$184,"S_Deduções",'MVTO A'!$G$3:$G$184) -> 185.5 | F11: =E11/$E$10 -> 4.6941493e-05 | G11: =C11+E11 -> 65570.5 | H11: =G11/$G$10 -> 0.0017792573 | I11: =SUMIF('MVTO E'!$C$3:$C$240,"S_Deduções",'MVTO E'!$H$3:$H$240) -> 43517.62 | J11: =I11/$I$10 -> 0.002049815 | K11: =SUMIF('MVTO A'!$C$3:$C$184,"S_Deduções",'MVTO A'!$H$3:$H$184) -> 0 | L11: =K11/$K$10 -> 0 | M11: =I11+K11 -> 43517.62 | N11: =M11/$M$10 -> 0.0017654739 | O11: =M11-G11 -> -22052.88 | P11: =SUMIF('MVTO E'!$C$3:$C$240,"S_Deduções",'MVTO E'!$I$3:$I$240) -> 372509.19 | Q11: =P11/$P$10 -> 0.015646834 | R11: =SUMIF('MVTO A'!$C$3:$C$184,"S_Deduções",'MVTO A'!$I$3:$I$184) -> 0 | S11: =R11/$R$10 -> 0 | T11: =P11+R11 -> 372509.19 | U11: =T11/$T$10 -> 0.013566556 | V11: =T11-M11 -> 328991.57 | W11: =SUMIF('MVTO E'!$C$3:$C$240,"S_Deduções",'MVTO E'!$J$3:$J$240) -> 64143.51 | X11: =W11/$W$10 -> 0.002889478 | Y11: =SUMIF('MVTO A'!$C$3:$C$184,"S_Deduções",'MVTO A'!$J$3:$J$184) -> 0 | Z11: =Y11/$Y$10 -> 0 | AA11: =W11+Y11 -> 64143.51 | AB11: =AA11/$AA$10 -> 0.0025297382 | AC11: =AA11-T11 -> -308365.68 | AD11: =SUMIF('MVTO E'!$C$3:$C$240,"S_Deduções",'MVTO E'!$K$3:$K$240) -> 0 | AE11: =AD11/$AD$10 -> #DIV/0! | AF11: =SUMIF('MVTO A'!$C$3:$C$184,"S_Deduções",'MVTO A'!$K$3:$K$184) -> 0 | AG11: =AF11/$AF$10 -> #DIV/0! | AH11: =AD11+AF11 -> 0 | AI11: =AH11/$AH$10 -> #DIV/0! | AJ11: =AH11-AA11 -> -64143.51 | AK11: =SUMIF('MVTO E'!$C$3:$C$240,"S_Deduções",'MVTO E'!$L$3:$L$240) -> 0 | AL11: =AK11/$AK$10 -> #DIV/0! | AM11: =SUMIF('MVTO A'!$C$3:$C$184,"S_Deduções",'MVTO A'!$L$3:$L$184) -> 0 | AN11: =AM11/$AM$10 -> #DIV/0! | AO11: =AK11+AM11 -> 0 | AP11: =AO11/$AO$10 -> #DIV/0! | AQ11: =AO11-AH11 -> 0 | AR11: =SUMIF('MVTO E'!$C$3:$C$240,"S_Deduções",'MVTO E'!$M$3:$M$240) -> 0 | AS11: =AR11/$AR$10 -> #DIV/0! | AT11: =SUMIF('MVTO A'!$C$3:$C$184,"S_Deduções",'MVTO A'!$M$3:$M$189) -> 0 | AU11: =AT11/$AT$10 -> #DIV/0! | AV11: =AR11+AT11 -> 0 | AW11: =AV11/$AV$10 -> #DIV/0! | AX11: =AV11-AO11 -> 0 | AY11: =SUMIF('MVTO E'!$C$3:$C$240,"S_Deduções",'MVTO E'!$N$3:$N$240) -> 0 | AZ11: =AY11/$AY$10 -> #DIV/0! | BA11: =SUMIF('MVTO A'!$C$3:$C$184,"S_Deduções",'MVTO A'!$N$3:$N$189) -> 0 | BB11: =BA11/$BA$10 -> #DIV/0! | BC11: =AY11+BA11 -> 0 | BD11: =BC11/$BC$10 -> #DIV/0! | BE11: =BC11-AV11 -> 0 | BF11: =SUMIF('MVTO E'!$C$3:$C$240,"S_Deduções",'MVTO E'!$O$3:$O$240) -> 0 | BG11: =BF11/$BF$10 -> #DIV/0! | BH11: =SUMIF('MVTO A'!$C$3:$C$195,"S_Deduções",'MVTO A'!$O$3:$O$195) -> 0 | BI11: =BH11/$BH$10 -> #DIV/0! | BJ11: =BF11+BH11 -> 0 | BK11: =BJ11/$BJ$10 -> #DIV/0! | BL11: =BJ11-BC11 -> 0 | BM11: =SUMIF('MVTO E'!$C$3:$C$240,"S_Deduções",'MVTO E'!$P$3:$P$240) -> 0 | BN11: =BM11/$BF$10 -> #DIV/0! | BO11: =SUMIF('MVTO A'!$C$3:$C$184,"S_Deduções",'MVTO A'!$P$3:$P$189) -> 0 | BP11: =BO11/$BH$10 -> #DIV/0! | BQ11: =BM11+BO11 -> 0 | BR11: =BQ11/$BJ$10 -> #DIV/0! | BS11: =BQ11-BJ11 -> 0 | BT11: =SUMIF('MVTO E'!$C$3:$C$240,"S_Deduções",'MVTO E'!$Q$3:$Q$240) -> 0 | BU11: =BT11/$BF$10 -> #DIV/0! | BV11: =SUMIF('MVTO A'!$C$3:$C$184,"S_Deduções",'MVTO A'!$Q$3:$Q$189) -> 0 | BW11: =BV11/$BH$10 -> #DIV/0! | BX11: =BT11+BV11 -> 0 | BY11: =BX11/$BJ$10 -> #DIV/0! | BZ11: =BX11-BQ11 -> 0 | CA11: =SUMIF('MVTO E'!$C$3:$C$240,"S_Deduções",'MVTO E'!$R$3:$R$240) -> 0 | CB11: =CA11/$BF$10 -> #DIV/0! | CC11: =SUMIF('MVTO A'!$C$3:$C$184,"S_Deduções",'MVTO A'!$R$3:$R$189) -> 0 | CD11: =CC11/$BH$10 -> #DIV/0! | CE11: =CA11+CC11 -> 0 | CF11: =CE11/$BJ$10 -> #DIV/0! | CG11: =CE11-BX11 -> 0 | CH11: =SUM(C11,I11,P11,W11,AD11,AK11,AR11,AY11,BF11,BM11,BT11,CA11) -> 545555.32 | CI11: =CH11/$CH$10 -> 0.0054480705 | CJ11: =SUM(E11,K11,R11,Y11,AF11,AM11,AT11,BA11,BH11,BO11,BV11,CC11) -> 185.5 | CK11: =CJ11/$CJ$10 -> 1.3083336e-05 | CL11: =SUM(G11,M11,T11,AA11,AH11,AO11,AV11,BC11,BJ11,BQ11,BX11,CE11) -> 545740.82 | CM11: =CL11/$CL$10 -> 0.0047739802
B12: ( - ) COMPRAS | C12: =SUMIF('MVTO E'!$C$3:$C$240,"Compras",'MVTO E'!$G$3:$G$240)+SUMIF('DESP E'!$D$3:$D$146,"Compras",'DESP E'!$G$3:$G$146) -> 22556749 | D12: =C12/$C$10 -> 0.68559447 | E12: =SUMIF('MVTO A'!$C$3:$C$184,"Compras",'MVTO A'!$G$3:$G$184)+SUMIF('DESP A'!$D$3:$D$129,"Compras",'DESP A'!$G$3:$G$129) -> 182167.49 | F12: =E12/$E$10 -> 0.046098188 | G12: =C12+E12 -> 22738916 | H12: =G12/$G$10 -> 0.61702113 | I12: =SUMIF('MVTO E'!$C$3:$C$240,"Compras",'MVTO E'!$H$3:$H$240)+SUMIF('DESP E'!$D$3:$D$146,"Compras",'DESP E'!$H$3:$H$146) -> 12804108 | J12: =I12/$I$10 -> 0.60311325 | K12: =SUMIF('MVTO A'!$C$3:$C$184,"Compras",'MVTO A'!$H$3:$H$184)+SUMIF('DESP A'!$D$3:$D$129,"Compras",'DESP A'!$H$3:$H$129) -> 121690.06 | L12: =K12/$K$10 -> 0.035589855 | M12: =I12+K12 -> 12925798 | N12: =M12/$M$10 -> 0.52438895 | O12: =M12-G12 -> -9813118.3 | P12: =SUMIF('MVTO E'!$C$3:$C$240,"Compras",'MVTO E'!$I$3:$I$240)+SUMIF('DESP E'!$D$3:$D$146,"Compras",'DESP E'!$I$3:$I$146) -> 15196261 | Q12: =P12/$P$10 -> 0.63830204 | R12: =SUMIF('MVTO A'!$C$3:$C$184,"Compras",'MVTO A'!$I$3:$I$184)+SUMIF('DESP A'!$D$3:$D$129,"Compras",'DESP A'!$I$3:$I$129) -> 141505.6 | S12: =R12/$R$10 -> 0.03876245 | T12: =P12+R12 -> 15337766 | U12: =T12/$T$10 -> 0.55859202 | V12: =T12-M12 -> 2411968.1 | W12: =SUMIF('MVTO E'!$C$3:$C$240,"Compras",'MVTO E'!$J$3:$J$240)+SUMIF('DESP E'!$D$3:$D$146,"Compras",'DESP E'!$J$3:$J$146) -> 14769758 | X12: =W12/$P$10 -> 0.62038725 | Y12: =SUMIF('MVTO A'!$C$3:$C$184,"Compras",'MVTO A'!$J$3:$J$184)+SUMIF('DESP A'!$D$3:$D$129,"Compras",'DESP A'!$J$3:$J$129) -> 112457.25 | Z12: =Y12/$Y$10 -> 0.035623881 | AA12: =W12+Y12 -> 14882215 | AB12: =AA12/$AA$10 -> 0.58693558 | AC12: =AA12-T12 -> -455551.4 | AD12: =SUMIF('MVTO E'!$C$3:$C$240,"Compras",'MVTO E'!$K$3:$K$240)+SUMIF('DESP E'!$D$3:$D$146,"Compras",'DESP E'!$K$3:$K$146) -> 0 | AE12: =AD12/$P$10 -> 0 | AF12: =SUMIF('MVTO A'!$C$3:$C$184,"Compras",'MVTO A'!$K$3:$K$184)+SUMIF('DESP A'!$D$3:$D$129,"Compras",'DESP A'!$K$3:$K$129) -> 0 | AG12: =AF12/$AF$10 -> #DIV/0! | AH12: =AD12+AF12 -> 0 | AI12: =AH12/$AH$10 -> #DIV/0! | AJ12: =AH12-AA12 -> -14882215 | AK12: =SUMIF('MVTO E'!$C$3:$C$240,"Compras",'MVTO E'!$L$3:$L$240)+SUMIF('DESP E'!$D$3:$D$146,"Compras",'DESP E'!$L$3:$L$146) -> 0 | AL12: =AK12/$P$10 -> 0 | AM12: =SUMIF('MVTO A'!$C$3:$C$184,"Compras",'MVTO A'!$L$3:$L$184)+SUMIF('DESP A'!$D$3:$D$129,"Compras",'DESP A'!$L$3:$L$129) -> 0 | AN12: =AM12/$AM$10 -> #DIV/0! | AO12: =AK12+AM12 -> 0 | AP12: =AO12/$AO$10 -> #DIV/0! | AQ12: =AO12-AH12 -> 0 | AR12: =SUMIF('MVTO E'!$C$3:$C$240,"Compras",'MVTO E'!$M$3:$M$240)+SUMIF('DESP E'!$D$3:$D$146,"Compras",'DESP E'!$M$3:$M$146) -> 0 | AS12: =AR12/$P$10 -> 0 | AT12: =SUMIF('MVTO A'!$C$3:$C$184,"Compras",'MVTO A'!$M$3:$M$189)+SUMIF('DESP A'!$D$3:$D$129,"Compras",'DESP A'!$M$3:$M$129) -> 0 | AU12: =AT12/$AT$10 -> #DIV/0! | AV12: =AR12+AT12 -> 0 | AW12: =AV12/$AV$10 -> #DIV/0! | AX12: =AV12-AO12 -> 0 | AY12: =SUMIF('MVTO E'!$C$3:$C$240,"Compras",'MVTO E'!$N$3:$N$240)+SUMIF('DESP E'!$D$3:$D$146,"Compras",'DESP E'!$N$3:$N$146) -> 0 | AZ12: =AY12/$P$10 -> 0 | BA12: =SUMIF('MVTO A'!$C$3:$C$184,"Compras",'MVTO A'!$N$3:$N$189)+SUMIF('DESP A'!$D$3:$D$129,"Compras",'DESP A'!$N$3:$N$129) -> 0 | BB12: =BA12/$BA$10 -> #DIV/0! | BC12: =AY12+BA12 -> 0 | BD12: =BC12/$BC$10 -> #DIV/0! | BE12: =BC12-AV12 -> 0 | BF12: =SUMIF('MVTO E'!$C$3:$C$240,"Compras",'MVTO E'!$O$3:$O$240)+SUMIF('DESP E'!$D$3:$D$146,"Compras",'DESP E'!$O$3:$O$146) -> 0 | BG12: =BF12/$P$10 -> 0 | BH12: =SUMIF('MVTO A'!$C$3:$C$195,"Compras",'MVTO A'!$O$3:$O$195)+SUMIF('DESP A'!$D$3:$D$144,"Compras",'DESP A'!$O$3:$O$185) -> 0 | BI12: =BH12/$BH$10 -> #DIV/0! | BJ12: =BF12+BH12 -> 0 | BK12: =BJ12/$BJ$10 -> #DIV/0! | BL12: =BJ12-BC12 -> 0 | BM12: =SUMIF('MVTO E'!$C$3:$C$240,"Compras",'MVTO E'!$P$3:$P$240)+SUMIF('DESP E'!$D$3:$D$146,"Compras",'DESP E'!$P$3:$P$146) -> 0 | BN12: =BM12/$P$10 -> 0 | BO12: =SUMIF('MVTO A'!$C$3:$C$195,"Compras",'MVTO A'!$P$3:$P$195)+SUMIF('DESP A'!$D$3:$D$129,"Compras",'DESP A'!$P$3:$P$129) -> 0 | BP12: =BO12/$BH$10 -> #DIV/0! | BQ12: =BM12+BO12 -> 0 | BR12: =BQ12/$BJ$10 -> #DIV/0! | BS12: =BQ12-BJ12 -> 0 | BT12: =SUMIF('MVTO E'!$C$3:$C$240,"Compras",'MVTO E'!$Q$3:$Q$240)+SUMIF('DESP E'!$D$3:$D$146,"Compras",'DESP E'!$Q$3:$Q$146) -> 0 | BU12: =BT12/$P$10 -> 0 | BV12: =SUMIF('MVTO A'!$C$3:$C$184,"Compras",'MVTO A'!$Q$3:$Q$189)+SUMIF('DESP A'!$D$3:$D$129,"Compras",'DESP A'!$Q$3:$Q$129) -> 0 | BW12: =BV12/$BH$10 -> #DIV/0! | BX12: =BT12+BV12 -> 0 | BY12: =BX12/$BJ$10 -> #DIV/0! | BZ12: =BX12-BQ12 -> 0 | CA12: =SUMIF('MVTO E'!$C$3:$C$240,"Compras",'MVTO E'!$R$3:$R$240)+SUMIF('DESP E'!$D$3:$D$146,"Compras",'DESP E'!$R$3:$R$146) -> 0 | CB12: =CA12/$P$10 -> 0 | CC12: =SUMIF('MVTO A'!$C$3:$C$184,"Compras",'MVTO A'!$R$3:$R$189)+SUMIF('DESP A'!$D$3:$D$174,"Compras",'DESP A'!$R$3:$R$174) -> 0 | CD12: =CC12/$BH$10 -> #DIV/0! | CE12: =CA12+CC12 -> 0 | CF12: =CE12/$BJ$10 -> #DIV/0! | CG12: =CE12-BX12 -> 0 | CH12: =SUM(C12,I12,P12,W12,AD12,AK12,AR12,AY12,BF12,BM12,BT12,CA12) -> 65326876 | CI12: =CH12/$CH$10 -> 0.65237275 | CJ12: =SUM(E12,K12,R12,Y12,AF12,AM12,AT12,BA12,BH12,BO12,BV12,CC12) -> 557820.4 | CK12: =CJ12/$CJ$10 -> 0.039343137 | CL12: =SUM(G12,M12,T12,AA12,AH12,AO12,AV12,BC12,BJ12,BQ12,BX12,CE12) -> 65884696 | CM12: =CL12/$CL$10 -> 0.57633994
B13: ( = ) Margem de Venda | C13: =C10-C11-C12 -> 10278874 | D13: =D10-D11-D12 -> 0.3124182 | E13: =E10-E11-E12 -> 3769374.8 | F13: =F10-F11-F12 -> 0.95385487 | G13: =C13+E13 -> 14048248 | H13: =H10-H11-H12 -> 0.38119961 | I13: =I10-I11-I12 -> 8382397.1 | J13: =J10-J11-J12 -> 0.39483693 | K13: =K10-K11-K12 -> 3297544.4 | L13: =L10-L11-L12 -> 0.96441015 | M13: =I13+K13 -> 11679942 | N13: =N10-N11-N12 -> 0.47384558 | O13: =M13-G13 -> -2368306.8 | P13: =P10-P11-P12 -> 8238549.8 | Q13: =Q10-Q11-Q12 -> 0.46744981 | R13: =R10-R11-R12 -> 3509078.9 | S13: =S10-S11-S12 -> 1.0288989 | T13: =P13+R13 -> 11747629 | U13: =U10-U11-U12 -> 0.42784142 | V13: =T13-M13 -> 67687.2 | W13: =W10-W11-W12 -> 7365094.3 | X13: =X10-X11-X12 -> 0.37672327 | Y13: =Y10-Y11-Y12 -> 3044336.6 | Z13: =Z10-Z11-Z12 -> 0.96437612 | AA13: =W13+Y13 -> 10409431 | AB13: =AB10-AB11-AB12 -> 0.41053468 | AC13: =AA13-T13 -> -1338197.8 | AD13: =AD10-AD11-AD12 -> 0 | AE13: =AE10-AE11-AE12 -> #DIV/0! | AF13: =AF10-AF11-AF12 -> 0 | AG13: =AG10-AG11-AG12 -> #DIV/0! | AH13: =AD13+AF13 -> 0 | AI13: =AI10-AI11-AI12 -> #DIV/0! | AJ13: =AH13-AA13 -> -10409431 | AK13: =AK10-AK11-AK12 -> 0 | AL13: =AL10-AL11-AL12 -> #DIV/0! | AM13: =AM10-AM11-AM12 -> 0 | AN13: =AN10-AN11-AN12 -> #DIV/0! | AO13: =AK13+AM13 -> 0 | AP13: =AP10-AP11-AP12 -> #DIV/0! | AQ13: =AO13-AH13 -> 0 | AR13: =AR10-AR11-AR12 -> 0 | AS13: =AS10-AS11-AS12 -> #DIV/0! | AT13: =AT10-AT11-AT12 -> 0 | AU13: =AU10-AU11-AU12 -> #DIV/0! | AV13: =AR13+AT13 -> 0 | AW13: =AW10-AW11-AW12 -> #DIV/0! | AX13: =AV13-AO13 -> 0 | AY13: =AY10-AY11-AY12 -> 0 | AZ13: =AZ10-AZ11-AZ12 -> #DIV/0! | BA13: =BA10-BA11-BA12 -> 0 | BB13: =BB10-BB11-BB12 -> #DIV/0! | BC13: =AY13+BA13 -> 0 | BD13: =BD10-BD11-BD12 -> #DIV/0! | BE13: =BC13-AV13 -> 0 | BF13: =BF10-BF11-BF12 -> 0 | BG13: =BG10-BG11-BG12 -> #DIV/0! | BH13: =BH10-BH11-BH12 -> 0 | BI13: =BI10-BI11-BI12 -> #DIV/0! | BJ13: =BF13+BH13 -> 0 | BK13: =BK10-BK11-BK12 -> #DIV/0! | BL13: =BJ13-BC13 -> 0 | BM13: =BM10-BM11-BM12 -> 0 | BN13: =BN10-BN11-BN12 -> #DIV/0! | BO13: =BO10-BO11-BO12 -> 0 | BP13: =BP10-BP11-BP12 -> #DIV/0! | BQ13: =BM13+BO13 -> 0 | BR13: =BR10-BR11-BR12 -> #DIV/0! | BS13: =BQ13-BJ13 -> 0 | BT13: =BT10-BT11-BT12 -> 0 | BU13: =BU10-BU11-BU12 -> #DIV/0! | BV13: =BV10-BV11-BV12 -> 0 | BW13: =BW10-BW11-BW12 -> #DIV/0! | BX13: =BT13+BV13 -> 0 | BY13: =BY10-BY11-BY12 -> #DIV/0! | BZ13: =BX13-BQ13 -> 0 | CA13: =CA10-CA11-CA12 -> 0 | CB13: =CB10-CB11-CB12 -> #DIV/0! | CC13: =CC10-CC11-CC12 -> 0 | CD13: =CD10-CD11-CD12 -> #DIV/0! | CE13: =CA13+CC13 -> 0 | CF13: =CF10-CF11-CF12 -> #DIV/0! | CG13: =CE13-BX13 -> 0 | CH13: =CH10-CH11-CH12 -> 34264915 | CI13: =CH13/$CH$10 -> 0.34217918 | CJ13: =CJ10-CJ11-CJ12 -> 13620335 | CK13: =CJ13/$CJ$10 -> 0.96064378 | CL13: =CL10-CL11-CL12 -> 47885250 | CM13: =CL13/$CL$10 -> 0.41888608
B14: ( - ) Impostos Sobre Vendas | C14: =SUMIF('MVTO E'!$C$3:$C$240,"Imp_Vda",'MVTO E'!$G$3:$G$240) -> 4511859.1 | D14: =C14/$C$10 -> 0.13713438 | E14: =SUMIF('MVTO A'!$C$3:$C$184,"Imp_Vda",'MVTO A'!$G$3:$G$184) -> 295759.72 | F14: =E14/$E$10 -> 0.074843142 | G14: =C14+E14 -> 4807618.8 | H14: =G14/$G$10 -> 0.13045487 | I14: =SUMIF('MVTO E'!$C$3:$C$240,"Imp_Vda",'MVTO E'!$H$3:$H$240) -> 2213354.6 | J14: =I14/$I$10 -> 0.10425588 | K14: =SUMIF('MVTO A'!$C$3:$C$184,"Imp_Vda",'MVTO A'!$H$3:$H$184) -> 282321.16 | L14: =K14/$K$10 -> 0.082568528 | M14: =I14+K14 -> 2495675.8 | N14: =M14/$M$10 -> 0.1012475 | O14: =M14-G14 -> -2311943.1 | P14: =SUMIF('MVTO E'!$C$3:$C$240,"Imp_Vda",'MVTO E'!$I$3:$I$240) -> 2370780.4 | Q14: =P14/$P$10 -> 0.099581996 | R14: =SUMIF('MVTO A'!$C$3:$C$184,"Imp_Vda",'MVTO A'!$I$3:$I$184) -> 144833.21 | S14: =R14/$R$10 -> 0.039673978 | T14: =P14+R14 -> 2515613.6 | U14: =T14/$T$10 -> 0.091617102 | V14: =T14-M14 -> 19937.83 | W14: =SUMIF('MVTO E'!$C$3:$C$240,"Imp_Vda",'MVTO E'!$J$3:$J$240) -> 2203266.9 | X14: =W14/$W$10 -> 0.099250746 | Y14: =SUMIF('MVTO A'!$C$3:$C$184,"Imp_Vda",'MVTO A'!$J$3:$J$184) -> 248869.95 | Z14: =Y14/$Y$10 -> 0.0788363 | AA14: =W14+Y14 -> 2452136.8 | AB14: =AA14/$AA$10 -> 0.096709149 | AC14: =AA14-T14 -> -63476.82 | AD14: =SUMIF('MVTO E'!$C$3:$C$240,"Imp_Vda",'MVTO E'!$K$3:$K$240) -> 0 | AE14: =AD14/$AD$10 -> #DIV/0! | AF14: =SUMIF('MVTO A'!$C$3:$C$184,"Imp_Vda",'MVTO A'!$K$3:$K$184) -> 0 | AG14: =AF14/$AF$10 -> #DIV/0! | AH14: =AD14+AF14 -> 0 | AI14: =AH14/$AH$10 -> #DIV/0! | AJ14: =AH14-AA14 -> -2452136.8 | AK14: =SUMIF('MVTO E'!$C$3:$C$240,"Imp_Vda",'MVTO E'!$L$3:$L$240) -> 0 | AL14: =AK14/$AK$10 -> #DIV/0! | AM14: =SUMIF('MVTO A'!$C$3:$C$184,"Imp_Vda",'MVTO A'!$L$3:$L$184) -> 0 | AN14: =AM14/$AM$10 -> #DIV/0! | AO14: =AK14+AM14 -> 0 | AP14: =AO14/$AO$10 -> #DIV/0! | AQ14: =AO14-AH14 -> 0 | AR14: =SUMIF('MVTO E'!$C$3:$C$240,"Imp_Vda",'MVTO E'!$M$3:$M$240) -> 0 | AS14: =AR14/$AR$10 -> #DIV/0! | AT14: =SUMIF('MVTO A'!$C$3:$C$184,"Imp_Vda",'MVTO A'!$M$3:$M$189) -> 0 | AU14: =AT14/$AT$10 -> #DIV/0! | AV14: =AR14+AT14 -> 0 | AW14: =AV14/$AV$10 -> #DIV/0! | AX14: =AV14-AO14 -> 0 | AY14: =SUMIF('MVTO E'!$C$3:$C$240,"Imp_Vda",'MVTO E'!$N$3:$N$240) -> 0 | AZ14: =AY14/$AY$10 -> #DIV/0! | BA14: =SUMIF('MVTO A'!$C$3:$C$184,"Imp_Vda",'MVTO A'!$N$3:$N$189) -> 0 | BB14: =BA14/$BA$10 -> #DIV/0! | BC14: =AY14+BA14 -> 0 | BD14: =BC14/$BC$10 -> #DIV/0! | BE14: =BC14-AV14 -> 0 | BF14: =SUMIF('MVTO E'!$C$3:$C$240,"Imp_Vda",'MVTO E'!$O$3:$O$240) -> 0 | BG14: =BF14/$BF$10 -> #DIV/0! | BH14: =SUMIF('MVTO A'!$C$3:$C$195,"Imp_Vda",'MVTO A'!$O$3:$O$195) -> 0 | BI14: =BH14/$BH$10 -> #DIV/0! | BJ14: =BF14+BH14 -> 0 | BK14: =BJ14/$BJ$10 -> #DIV/0! | BL14: =BJ14-BC14 -> 0 | BM14: =SUMIF('MVTO E'!$C$3:$C$240,"Imp_Vda",'MVTO E'!$P$3:$P$240) -> 0 | BN14: =BM14/$BF$10 -> #DIV/0! | BO14: =SUMIF('MVTO A'!$C$3:$C$184,"Imp_Vda",'MVTO A'!$P$3:$P$189) -> 0 | BP14: =BO14/$BH$10 -> #DIV/0! | BQ14: =BM14+BO14 -> 0 | BR14: =BQ14/$BJ$10 -> #DIV/0! | BS14: =BQ14-BJ14 -> 0 | BT14: =SUMIF('MVTO E'!$C$3:$C$240,"Imp_Vda",'MVTO E'!$Q$3:$Q$240) -> 0 | BU14: =BT14/$BF$10 -> #DIV/0! | BV14: =SUMIF('MVTO A'!$C$3:$C$184,"Imp_Vda",'MVTO A'!$Q$3:$Q$189) -> 0 | BW14: =BV14/$BH$10 -> #DIV/0! | BX14: =BT14+BV14 -> 0 | BY14: =BX14/$BJ$10 -> #DIV/0! | BZ14: =BX14-BQ14 -> 0 | CA14: =SUMIF('MVTO E'!$C$3:$C$240,"Imp_Vda",'MVTO E'!$R$3:$R$240) -> 0 | CB14: =CA14/$BF$10 -> #DIV/0! | CC14: =SUMIF('MVTO A'!$C$3:$C$184,"Imp_Vda",'MVTO A'!$R$3:$R$189) -> 0 | CD14: =CC14/$BH$10 -> #DIV/0! | CE14: =CA14+CC14 -> 0 | CF14: =CE14/$BJ$10 -> #DIV/0! | CG14: =CE14-BX14 -> 0 | CH14: =SUM(C14,I14,P14,W14,AD14,AK14,AR14,AY14,BF14,BM14,BT14,CA14) -> 11299261 | CI14: =CH14/$CH$10 -> 0.11283763 | CJ14: =SUM(E14,K14,R14,Y14,AF14,AM14,AT14,BA14,BH14,BO14,BV14,CC14) -> 971784.04 | CK14: =CJ14/$CJ$10 -> 0.06854004 | CL14: =SUM(G14,M14,T14,AA14,AH14,AO14,AV14,BC14,BJ14,BQ14,BX14,CE14) -> 12271045 | CM14: =CL14/$CL$10 -> 0.10734349
B15: ( + ) Adiantamentos de Clientes/Outras Receitas | C15: =SUMIF('MVTO E'!$C$3:$C$240,"Outros_Creditos",'MVTO E'!$G$3:$G$240) -> 73614.99 | D15: =C15/$C$10 -> 0.0022374692 | E15: =SUMIF('MVTO A'!$C$3:$C$184,"Outros_Creditos",'MVTO A'!$G$3:$G$184) -> 4773.84 | F15: =E15/$E$10 -> 0.0012080387 | G15: =C15+E15 -> 78388.83 | H15: =G15/$G$10 -> 0.0021270831 | I15: =SUMIF('MVTO E'!$C$3:$C$240,"Outros_Creditos",'MVTO E'!$H$3:$H$240) -> 112375.92 | J15: =I15/$I$10 -> 0.0052932548 | K15: =SUMIF('MVTO A'!$C$3:$C$184,"Outros_Creditos",'MVTO A'!$H$3:$H$184) -> 12404.57 | L15: =K15/$K$10 -> 0.0036278793 | M15: =I15+K15 -> 124780.49 | N15: =M15/$M$10 -> 0.0050622413 | O15: =M15-G15 -> 46391.66 | P15: =SUMIF('MVTO E'!$C$3:$C$240,"Outros_Creditos",'MVTO E'!$I$3:$I$240) -> 70164.12 | Q15: =P15/$P$10 -> 0.0029471659 | R15: =SUMIF('MVTO A'!$C$3:$C$184,"Outros_Creditos",'MVTO A'!$I$3:$I$184) -> 21701.73 | S15: =R15/$R$10 -> 0.0059447274 | T15: =P15+R15 -> 91865.85 | U15: =T15/$T$10 -> 0.0033456978 | V15: =T15-M15 -> -32914.64 | W15: =SUMIF('MVTO E'!$C$3:$C$240,"Outros_Creditos",'MVTO E'!$J$3:$J$240) -> 39439.29 | X15: =W15/$W$10 -> 0.001776625 | Y15: =SUMIF('MVTO A'!$C$3:$C$184,"Outros_Creditos",'MVTO A'!$J$3:$J$184) -> 16268.44 | Z15: =Y15/$Y$10 -> 0.0051534692 | AA15: =W15+Y15 -> 55707.73 | AB15: =AA15/$AA$10 -> 0.0021970418 | AC15: =AA15-T15 -> -36158.12 | AD15: =SUMIF('MVTO E'!$C$3:$C$240,"Outros_Creditos",'MVTO E'!$K$3:$K$240) -> 0 | AE15: =AD15/$AD$10 -> #DIV/0! | AF15: =SUMIF('MVTO A'!$C$3:$C$184,"Outros_Creditos",'MVTO A'!$K$3:$K$184) -> 0 | AG15: =AF15/$AF$10 -> #DIV/0! | AH15: =AD15+AF15 -> 0 | AI15: =AH15/$AH$10 -> #DIV/0! | AJ15: =AH15-AA15 -> -55707.73 | AK15: =SUMIF('MVTO E'!$C$3:$C$240,"Outros_Creditos",'MVTO E'!$L$3:$L$240) -> 0 | AL15: =AK15/$AK$10 -> #DIV/0! | AM15: =SUMIF('MVTO A'!$C$3:$C$184,"Outros_Creditos",'MVTO A'!$L$3:$L$184) -> 0 | AN15: =AM15/$AM$10 -> #DIV/0! | AO15: =AK15+AM15 -> 0 | AP15: =AO15/$AO$10 -> #DIV/0! | AQ15: =AO15-AH15 -> 0 | AR15: =SUMIF('MVTO E'!$C$3:$C$240,"Outros_Creditos",'MVTO E'!$M$3:$M$240) -> 0 | AS15: =AR15/$AR$10 -> #DIV/0! | AT15: =SUMIF('MVTO A'!$C$3:$C$184,"Outros_Creditos",'MVTO A'!$M$3:$M$189) -> 0 | AU15: =AT15/$AT$10 -> #DIV/0! | AV15: =AR15+AT15 -> 0 | AW15: =AV15/$AV$10 -> #DIV/0! | AX15: =AV15-AO15 -> 0 | AY15: =SUMIF('MVTO E'!$C$3:$C$240,"Outros_Creditos",'MVTO E'!$N$3:$N$240) -> 0 | AZ15: =AY15/$AY$10 -> #DIV/0! | BA15: =SUMIF('MVTO A'!$C$3:$C$184,"Outros_Creditos",'MVTO A'!$N$3:$N$189) -> 0 | BB15: =BA15/$BA$10 -> #DIV/0! | BC15: =AY15+BA15 -> 0 | BD15: =BC15/$BC$10 -> #DIV/0! | BE15: =BC15-AV15 -> 0 | BF15: =SUMIF('MVTO E'!$C$3:$C$240,"Outros_Creditos",'MVTO E'!$O$3:$O$240) -> 0 | BG15: =BF15/$BF$10 -> #DIV/0! | BH15: =SUMIF('MVTO A'!$C$3:$C$195,"Outros_Creditos",'MVTO A'!$O$3:$O$195) -> 0 | BI15: =BH15/$BH$10 -> #DIV/0! | BJ15: =BF15+BH15 -> 0 | BK15: =BJ15/$BJ$10 -> #DIV/0! | BL15: =BJ15-BC15 -> 0 | BM15: =SUMIF('MVTO E'!$C$3:$C$240,"Outros_Creditos",'MVTO E'!$P$3:$P$240) -> 0 | BN15: =BM15/$BF$10 -> #DIV/0! | BO15: =SUMIF('MVTO A'!$C$3:$C$184,"Outros_Creditos",'MVTO A'!$P$3:$P$189) -> 0 | BP15: =BO15/$BH$10 -> #DIV/0! | BQ15: =BM15+BO15 -> 0 | BR15: =BQ15/$BJ$10 -> #DIV/0! | BS15: =BQ15-BJ15 -> 0 | BT15: =SUMIF('MVTO E'!$C$3:$C$240,"Outros_Creditos",'MVTO E'!$Q$3:$Q$240) -> 0 | BU15: =BT15/$BF$10 -> #DIV/0! | BV15: =SUMIF('MVTO A'!$C$3:$C$184,"Outros_Creditos",'MVTO A'!$Q$3:$Q$189) -> 0 | BW15: =BV15/$BH$10 -> #DIV/0! | BX15: =BT15+BV15 -> 0 | BY15: =BX15/$BJ$10 -> #DIV/0! | BZ15: =BX15-BQ15 -> 0 | CA15: =SUMIF('MVTO E'!$C$3:$C$240,"Outros_Creditos",'MVTO E'!$R$3:$R$240) -> 0 | CB15: =CA15/$BF$10 -> #DIV/0! | CC15: =SUMIF('MVTO A'!$C$3:$C$184,"Outros_Creditos",'MVTO A'!$R$3:$R$189) -> 0 | CD15: =CC15/$BH$10 -> #DIV/0! | CE15: =CA15+CC15 -> 0 | CF15: =CE15/$BJ$10 -> #DIV/0! | CG15: =CE15-BX15 -> 0 | CH15: =SUM(C15,I15,P15,W15,AD15,AK15,AR15,AY15,BF15,BM15,BT15,CA15) -> 295594.32 | CI15: =CH15/$CH$10 -> 0.0029518889 | CJ15: =SUM(E15,K15,R15,Y15,AF15,AM15,AT15,BA15,BH15,BO15,BV15,CC15) -> 55148.58 | CK15: =CJ15/$CJ$10 -> 0.0038896357 | CL15: =SUM(G15,M15,T15,AA15,AH15,AO15,AV15,BC15,BJ15,BQ15,BX15,CE15) -> 350742.9 | CM15: =CL15/$CL$10 -> 0.0030681957
