Workbook
Name ABR: #REF!
Name ABR: #REF!
Name ABR: #REF!
Name ABR: #REF!
Name ANO: #REF!
Name CONTA: #REF!
Name CONTA: #REF!
Name CONTA: #REF!
Name CONTA: #REF!
Name DESCRIÇÃO: #REF!
Name DESCRIÇÃO: #REF!
Name DESCRIÇÃO: #REF!
Name DESCRIÇÃO: #REF!
Name FEV: #REF!
Name FEV: #REF!
Name FEV: #REF!
Name FEV: #REF!
Name JAN: #REF!
Name JAN: #REF!
Name JAN: #REF!
Name JAN: #REF!
Name LEGENDA: #REF!
Name LEGENDA: #REF!
Name LEGENDA: #REF!
Name LEGENDA: #REF!
Name LucroLiquido: '2025'!#REF!
Name LucroLiquido: '2026'!#REF!
Name LucroLiquido: CLAUDE!#REF!
Name LucroLiquido: #REF!
Name MAI: #REF!
Name MAI: #REF!
Name MAI: #REF!
Name MAI: #REF!
Name MAR: #REF!
Name MAR: #REF!
Name MAR: #REF!
Name MAR: #REF!
Name Rub: #REF!
Name Rub: #REF!
Name Rub: #REF!
Name Rub: #REF!
Name Rubrica: #REF!
Name Rubrica: #REF!
Name Rubrica: #REF!
Name Rubrica: #REF!

Sheet 2026
C2: CONTA | D2: Janeiro | I2: Fevereiro | N2: Março | S2: Abril | X2: Maio | AC2: Junho | AH2: Julho | AM2: Agosto | AR2: Setembro | AW2: Outubro | BB2: Novembro | BG2: Dezembro | BL2: GERAL
C3: Receita | D3: ✅REALIZADO | E3: 📐%REA | F3: 🎯ORÇADO | G3: 📊%ORC | H3: ↔️DIF | I3: ✅REALIZADO | J3: 📐%REA | K3: 🎯ORÇADO | L3: 📊%ORC | M3: ↔️DIF | N3: ✅REALIZADO | O3: 📐%REA | P3: 🎯ORÇADO | Q3: 📊%ORC | R3: ↔️DIF | S3: ✅REALIZADO | T3: 📐%REA | U3: 🎯ORÇADO | V3: 📊%ORC | W3: ↔️DIF | X3: ✅REALIZADO | Y3: 📐%REA | Z3: 🎯ORÇADO | AA3: 📊%ORC | AB3: ↔️DIF | AC3: ✅REALIZADO | AD3: 📐%REA | AE3: 🎯ORÇADO | AF3: 📊%ORC | AG3: ↔️DIF | AH3: ✅REALIZADO | AI3: 📐%REA | AJ3: 🎯ORÇADO | AK3: 📊%ORC | AL3: ↔️DIF | AM3: ✅REALIZADO | AN3: 📐%REA | AO3: 🎯ORÇADO | AP3: 📊%ORC | AQ3: ↔️DIF | AR3: ✅REALIZADO | AS3: 📐%REA | AT3: 🎯ORÇADO | AU3: 📊%ORC | AV3: ↔️DIF | AW3: ✅REALIZADO | AX3: 📐%REA | AY3: 🎯ORÇADO | AZ3: 📊%ORC | BA3: ↔️DIF | BB3: ✅REALIZADO | BC3: 📐%REA | BD3: 🎯ORÇADO | BE3: 📊%ORC | BF3: ↔️DIF | BG3: ✅REALIZADO | BH3: 📐%REA | BI3: 🎯ORÇADO | BJ3: 📊%ORC | BK3: ↔️DIF | BL3: ✅REALIZADO | BM3: 📐%REA | BN3: 🎯ORÇADO | BO3: 📊%ORC | BP3: ↔️DIF | BQ3: ✅BASE - 2025 | BR3: 📐%REA
A4: Vda_Din | C4: Vendas - Dinheiro | D4: =SUMIF(EXTRATO!$F$14:$F$194,"Vda_Din",EXTRATO!$I$14:$I$194) -> 4546012.6 | E4: =D4/$D$12 -> 0.1816145 | F4: =$F$12*BR4 -> 4300373.9 | G4: =IF(F4="","",F4/$F$12) -> 0.19138347 | H4: =IF(G4="","",E4-G4) -> -0.0097689711 | I4: =SUMIF(EXTRATO!$F$14:$F$194,"Vda_Din",EXTRATO!$J$14:$J$194) -> 4418376 | J4: =I4/$I$12 -> 0.1955827 | K4: =$K$12*BR4 -> 4535788.3 | L4: =IF(K4="","",K4/$K$12) -> 0.19138347 | M4: =IF(L4="","",J4-L4) -> 0.0041992292 | O4: =IFERROR(N4/$N$16,"") | P4: =$P$12*BR4 -> 4784586.8 | Q4: =IF(P4="","",P4/$P$12) -> 0.19138347 | R4: =N4-P4 -> -4784586.8 | T4: =S4/$D$16 -> 0 | U4: =$U$12*BR4 -> 4975970.3 | V4: =IF(U4="","",U4/$U$12) -> 0.19138347 | W4: =IF(V4="","",T4-V4) -> -0.19138347 | Y4: =X4/$D$16 -> 0 | Z4: =$Z$12*BR4 -> 5167353.7 | AA4: =IF(Z4="","",Z4/$Z$12) -> 0.19138347 | AB4: =IF(AA4="","",Y4-AA4) -> -0.19138347 | AD4: =AC4/$D$16 -> 0 | AE4: =$AE$12*BR4 -> 4975970.3 | AF4: =IF(AE4="","",AE4/$AE$12) -> 0.19138347 | AG4: =IF(AF4="","",AD4-AF4) -> -0.19138347 | AI4: =AH4/$D$16 -> 0 | AJ4: =$AJ$12*BR4 -> 5320460.5 | AK4: =IF(AJ4="","",AJ4/$AJ$12) -> 0.19138347 | AL4: =IF(AK4="","",AI4-AK4) -> -0.19138347 | AN4: =AM4/$D$16 -> 0 | AO4: =$AO$12*BR4 -> 4995108.6 | AP4: =IF(AO4="","",AO4/$AO$12) -> 0.19138347 | AQ4: =IF(AP4="","",AN4-AP4) -> -0.19138347 | AS4: =AR4/$D$16 -> 0 | AT4: =$AT$12*BR4 -> 4956831.9 | AU4: =IF(AT4="","",AT4/$AT$12) -> 0.19138347 | AV4: =IF(AU4="","",AS4-AU4) -> -0.19138347 | AX4: =AW4/$D$16 -> 0 | AY4: =$AY$12*BR4 -> 5263045.5 | AZ4: =IF(AY4="","",AY4/$AY$12) -> 0.19138347 | BA4: =IF(AZ4="","",AX4-AZ4) -> -0.19138347 | BC4: =BB4/$D$16 -> 0 | BD4: =$BD$12*BR4 -> 5129077.1 | BE4: =IF(BD4="","",BD4/$BD$12) -> 0.19138347 | BF4: =IF(BE4="","",BC4-BE4) -> -0.19138347 | BH4: =BG4/$D$16 -> 0 | BI4: =$BI$12*BR4 -> 5760642.5 | BJ4: =IF(BI4="","",BI4/$BI$12) -> 0.19138347 | BK4: =IF(BJ4="","",BH4-BJ4) -> -0.19138347 | BL4: =SUM(D4,I4,N4,S4,X4,AC4,AH4,AM4,AR4,AW4,BB4,BG4) -> 8964388.6 | BM4: =BL4/$BL$16 -> 0.20152969 | BN4: =F4+K4+P4+U4+Z4+AE4+AJ4+AO4+AT4+AY4+BD4+BI4 -> 60165209 | BO4: =IF(BN4="","",BN4/$BN$16) -> 0.20349736 | BP4: =IF(BO4="","",BM4-BO4) -> -0.0019676709 | BQ4: 55862595 | BR4: =BQ4/$BQ$12 -> 0.19138347
A5: Vda_Cre | C5: Vendas - Crédito | D5: =SUMIF(EXTRATO!$F$14:$F$194,"Vda_CRE",EXTRATO!$I$14:$I$194) -> 8387984.4 | E5: =D5/$D$12 -> 0.33510237 | F5: =$F$12*BR5 -> 6786491.1 | G5: =IF(F5="","",F5/$F$12) -> 0.30202542 | H5: =IF(G5="","",E5-G5) -> 0.033076953 | I5: =SUMIF(EXTRATO!$F$14:$F$194,"Vda_CRE",EXTRATO!$J$14:$J$194) -> 6111541.4 | J5: =I5/$I$12 -> 0.27053193 | K5: =$K$12*BR5 -> 7158002.4 | L5: =IF(K5="","",K5/$K$12) -> 0.30202542 | M5: =IF(L5="","",J5-L5) -> -0.031493489 | O5: =IFERROR(N5/$N$16,"") | P5: =$P$12*BR5 -> 7550635.4 | Q5: =IF(P5="","",P5/$P$12) -> 0.30202542 | R5: =N5-P5 -> -7550635.4 | T5: =S5/$D$16 -> 0 | U5: =$U$12*BR5 -> 7852660.8 | V5: =IF(U5="","",U5/$U$12) -> 0.30202542 | W5: =IF(V5="","",T5-V5) -> -0.30202542 | Y5: =X5/$D$16 -> 0 | Z5: =$Z$12*BR5 -> 8154686.2 | AA5: =IF(Z5="","",Z5/$Z$12) -> 0.30202542 | AB5: =IF(AA5="","",Y5-AA5) -> -0.30202542 | AD5: =AC5/$D$16 -> 0 | AE5: =$AE$12*BR5 -> 7852660.8 | AF5: =IF(AE5="","",AE5/$AE$12) -> 0.30202542 | AG5: =IF(AF5="","",AD5-AF5) -> -0.30202542 | AI5: =AH5/$D$16 -> 0 | AJ5: =$AJ$12*BR5 -> 8396306.6 | AK5: =IF(AJ5="","",AJ5/$AJ$12) -> 0.30202542 | AL5: =IF(AK5="","",AI5-AK5) -> -0.30202542 | AN5: =AM5/$D$16 -> 0 | AO5: =$AO$12*BR5 -> 7882863.4 | AP5: =IF(AO5="","",AO5/$AO$12) -> 0.30202542 | AQ5: =IF(AP5="","",AN5-AP5) -> -0.30202542 | AS5: =AR5/$D$16 -> 0 | AT5: =$AT$12*BR5 -> 7822458.3 | AU5: =IF(AT5="","",AT5/$AT$12) -> 0.30202542 | AV5: =IF(AU5="","",AS5-AU5) -> -0.30202542 | AX5: =AW5/$D$16 -> 0 | AY5: =$AY$12*BR5 -> 8305699 | AZ5: =IF(AY5="","",AY5/$AY$12) -> 0.30202542 | BA5: =IF(AZ5="","",AX5-AZ5) -> -0.30202542 | BC5: =BB5/$D$16 -> 0 | BD5: =$BD$12*BR5 -> 8094281.2 | BE5: =IF(BD5="","",BD5/$BD$12) -> 0.30202542 | BF5: =IF(BE5="","",BC5-BE5) -> -0.30202542 | BH5: =BG5/$D$16 -> 0 | BI5: =$BI$12*BR5 -> 9090965 | BJ5: =IF(BI5="","",BI5/$BI$12) -> 0.30202542 | BK5: =IF(BJ5="","",BH5-BJ5) -> -0.30202542 | BL5: =SUM(D5,I5,N5,S5,X5,AC5,AH5,AM5,AR5,AW5,BB5,BG5) -> 14499526 | BM5: =BL5/$BL$16 -> 0.32596589 | BN5: =F5+K5+P5+U5+Z5+AE5+AJ5+AO5+AT5+AY5+BD5+BI5 -> 94947710 | BO5: =IF(BN5="","",BN5/$BN$16) -> 0.32114254 | BP5: =IF(BO5="","",BM5-BO5) -> 0.004823348 | BQ5: 88157684 | BR5: =BQ5/$BQ$12 -> 0.30202542
A6: Vda_Deb | C6: Vendas - Débito | D6: =SUMIF(EXTRATO!$F$14:$F$194,"Vda_DEB",EXTRATO!$I$14:$I$194) -> 5430450.8 | E6: =D6/$D$12 -> 0.21694806 | F6: =$F$12*BR6 -> 5323308.9 | G6: =IF(F6="","",F6/$F$12) -> 0.23690808 | H6: =IF(G6="","",E6-G6) -> -0.01996002 | I6: =SUMIF(EXTRATO!$F$14:$F$194,"Vda_DEB",EXTRATO!$J$14:$J$194) -> 5267023.6 | J6: =I6/$I$12 -> 0.23314872 | K6: =$K$12*BR6 -> 5614721.5 | L6: =IF(K6="","",K6/$K$12) -> 0.23690808 | M6: =IF(L6="","",J6-L6) -> -0.0037593616 | O6: =IFERROR(N6/$N$16,"") | P6: =$P$12*BR6 -> 5922702 | Q6: =IF(P6="","",P6/$P$12) -> 0.23690808 | R6: =N6-P6 -> -5922702 | T6: =S6/$D$16 -> 0 | U6: =$U$12*BR6 -> 6159610.1 | V6: =IF(U6="","",U6/$U$12) -> 0.23690808 | W6: =IF(V6="","",T6-V6) -> -0.23690808 | Y6: =X6/$D$16 -> 0 | Z6: =$Z$12*BR6 -> 6396518.2 | AA6: =IF(Z6="","",Z6/$Z$12) -> 0.23690808 | AB6: =IF(AA6="","",Y6-AA6) -> -0.23690808 | AD6: =AC6/$D$16 -> 0 | AE6: =$AE$12*BR6 -> 6159610.1 | AF6: =IF(AE6="","",AE6/$AE$12) -> 0.23690808 | AG6: =IF(AF6="","",AD6-AF6) -> -0.23690808 | AI6: =AH6/$D$16 -> 0 | AJ6: =$AJ$12*BR6 -> 6586044.6 | AK6: =IF(AJ6="","",AJ6/$AJ$12) -> 0.23690808 | AL6: =IF(AK6="","",AI6-AK6) -> -0.23690808 | AN6: =AM6/$D$16 -> 0 | AO6: =$AO$12*BR6 -> 6183300.9 | AP6: =IF(AO6="","",AO6/$AO$12) -> 0.23690808 | AQ6: =IF(AP6="","",AN6-AP6) -> -0.23690808 | AS6: =AR6/$D$16 -> 0 | AT6: =$AT$12*BR6 -> 6135919.3 | AU6: =IF(AT6="","",AT6/$AT$12) -> 0.23690808 | AV6: =IF(AU6="","",AS6-AU6) -> -0.23690808 | AX6: =AW6/$D$16 -> 0 | AY6: =$AY$12*BR6 -> 6514972.2 | AZ6: =IF(AY6="","",AY6/$AY$12) -> 0.23690808 | BA6: =IF(AZ6="","",AX6-AZ6) -> -0.23690808 | BC6: =BB6/$D$16 -> 0 | BD6: =$BD$12*BR6 -> 6349136.6 | BE6: =IF(BD6="","",BD6/$BD$12) -> 0.23690808 | BF6: =IF(BE6="","",BC6-BE6) -> -0.23690808 | BH6: =BG6/$D$16 -> 0 | BI6: =$BI$12*BR6 -> 7130933.2 | BJ6: =IF(BI6="","",BI6/$BI$12) -> 0.23690808 | BK6: =IF(BJ6="","",BH6-BJ6) -> -0.23690808 | BL6: =SUM(D6,I6,N6,S6,X6,AC6,AH6,AM6,AR6,AW6,BB6,BG6) -> 10697474 | BM6: =BL6/$BL$16 -> 0.24049144 | BN6: =F6+K6+P6+U6+Z6+AE6+AJ6+AO6+AT6+AY6+BD6+BI6 -> 74476778 | BO6: =IF(BN6="","",BN6/$BN$16) -> 0.25190351 | BP6: =IF(BO6="","",BM6-BO6) -> -0.011412076 | BQ6: 69150696 | BR6: =BQ6/$BQ$12 -> 0.23690808
A7: Vda_Cli | C7: Vendas - Clientes | D7: =SUMIF(EXTRATO!$F$14:$F$194,"Vda_CLI",EXTRATO!$I$14:$I$194) -> 311912.58 | E7: =D7/$D$12 -> 0.012460997 | F7: =$F$12*BR7 -> 271263.62 | G7: =IF(F7="","",F7/$F$12) -> 0.012072293 | H7: =IF(G7="","",E7-G7) -> 0.00038870402 | I7: =SUMIF(EXTRATO!$F$14:$F$194,"Vda_CLI",EXTRATO!$J$14:$J$194) -> 276494.3 | J7: =I7/$I$12 -> 0.012239226 | K7: =$K$12*BR7 -> 286113.33 | L7: =IF(K7="","",K7/$K$12) -> 0.012072293 | M7: =IF(L7="","",J7-L7) -> 0.0001669334 | O7: =IFERROR(N7/$N$16,"") | P7: =$P$12*BR7 -> 301807.31 | Q7: =IF(P7="","",P7/$P$12) -> 0.012072293 | R7: =N7-P7 -> -301807.31 | T7: =S7/$D$16 -> 0 | U7: =$U$12*BR7 -> 313879.61 | V7: =IF(U7="","",U7/$U$12) -> 0.012072293 | W7: =IF(V7="","",T7-V7) -> -0.012072293 | Y7: =X7/$D$16 -> 0 | Z7: =$Z$12*BR7 -> 325951.9 | AA7: =IF(Z7="","",Z7/$Z$12) -> 0.012072293 | AB7: =IF(AA7="","",Y7-AA7) -> -0.012072293 | AD7: =AC7/$D$16 -> 0 | AE7: =$AE$12*BR7 -> 313879.61 | AF7: =IF(AE7="","",AE7/$AE$12) -> 0.012072293 | AG7: =IF(AF7="","",AD7-AF7) -> -0.012072293 | AI7: =AH7/$D$16 -> 0 | AJ7: =$AJ$12*BR7 -> 335609.73 | AK7: =IF(AJ7="","",AJ7/$AJ$12) -> 0.012072293 | AL7: =IF(AK7="","",AI7-AK7) -> -0.012072293 | AN7: =AM7/$D$16 -> 0 | AO7: =$AO$12*BR7 -> 315086.84 | AP7: =IF(AO7="","",AO7/$AO$12) -> 0.012072293 | AQ7: =IF(AP7="","",AN7-AP7) -> -0.012072293 | AS7: =AR7/$D$16 -> 0 | AT7: =$AT$12*BR7 -> 312672.38 | AU7: =IF(AT7="","",AT7/$AT$12) -> 0.012072293 | AV7: =IF(AU7="","",AS7-AU7) -> -0.012072293 | AX7: =AW7/$D$16 -> 0 | AY7: =$AY$12*BR7 -> 331988.05 | AZ7: =IF(AY7="","",AY7/$AY$12) -> 0.012072293 | BA7: =IF(AZ7="","",AX7-AZ7) -> -0.012072293 | BC7: =BB7/$D$16 -> 0 | BD7: =$BD$12*BR7 -> 323537.44 | BE7: =IF(BD7="","",BD7/$BD$12) -> 0.012072293 | BF7: =IF(BE7="","",BC7-BE7) -> -0.012072293 | BH7: =BG7/$D$16 -> 0 | BI7: =$BI$12*BR7 -> 363376.01 | BJ7: =IF(BI7="","",BI7/$BI$12) -> 0.012072293 | BK7: =IF(BJ7="","",BH7-BJ7) -> -0.012072293 | BL7: =SUM(D7,I7,N7,S7,X7,AC7,AH7,AM7,AR7,AW7,BB7,BG7) -> 588406.88 | BM7: =BL7/$BL$16 -> 0.013228058 | BN7: =F7+K7+P7+U7+Z7+AE7+AJ7+AO7+AT7+AY7+BD7+BI7 -> 3795165.8 | BO7: =IF(BN7="","",BN7/$BN$16) -> 0.012836425 | BP7: =IF(BO7="","",BM7-BO7) -> 0.00039163295 | BQ7: 3523760.9 | BR7: =BQ7/$BQ$12 -> 0.012072293
A8: Vda_Pri | C8: Vendas - Private | D8: =SUMIF(EXTRATO!$F$14:$F$194,"Vda_pri",EXTRATO!$I$14:$I$194) -> 1877803.6 | E8: =D8/$D$12 -> 0.07501879 | F8: =$F$12*BR8 -> 1487355.7 | G8: =IF(F8="","",F8/$F$12) -> 0.06619315 | H8: =IF(G8="","",E8-G8) -> 0.0088256403 | I8: =SUMIF(EXTRATO!$F$14:$F$194,"Vda_pri",EXTRATO!$J$14:$J$194) -> 1773360.1 | J8: =I8/$I$12 -> 0.078499103 | K8: =$K$12*BR8 -> 1568777.6 | L8: =IF(K8="","",K8/$K$12) -> 0.06619315 | M8: =IF(L8="","",J8-L8) -> 0.012305953 | O8: =IFERROR(N8/$N$16,"") | P8: =$P$12*BR8 -> 1654828.7 | Q8: =IF(P8="","",P8/$P$12) -> 0.06619315 | R8: =N8-P8 -> -1654828.7 | T8: =S8/$D$16 -> 0 | U8: =$U$12*BR8 -> 1721021.9 | V8: =IF(U8="","",U8/$U$12) -> 0.06619315 | W8: =IF(V8="","",T8-V8) -> -0.06619315 | Y8: =X8/$D$16 -> 0 | Z8: =$Z$12*BR8 -> 1787215 | AA8: =IF(Z8="","",Z8/$Z$12) -> 0.06619315 | AB8: =IF(AA8="","",Y8-AA8) -> -0.06619315 | AD8: =AC8/$D$16 -> 0 | AE8: =$AE$12*BR8 -> 1721021.9 | AF8: =IF(AE8="","",AE8/$AE$12) -> 0.06619315 | AG8: =IF(AF8="","",AD8-AF8) -> -0.06619315 | AI8: =AH8/$D$16 -> 0 | AJ8: =$AJ$12*BR8 -> 1840169.6 | AK8: =IF(AJ8="","",AJ8/$AJ$12) -> 0.06619315 | AL8: =IF(AK8="","",AI8-AK8) -> -0.06619315 | AN8: =AM8/$D$16 -> 0 | AO8: =$AO$12*BR8 -> 1727641.2 | AP8: =IF(AO8="","",AO8/$AO$12) -> 0.06619315 | AQ8: =IF(AP8="","",AN8-AP8) -> -0.06619315 | AS8: =AR8/$D$16 -> 0 | AT8: =$AT$12*BR8 -> 1714402.6 | AU8: =IF(AT8="","",AT8/$AT$12) -> 0.06619315 | AV8: =IF(AU8="","",AS8-AU8) -> -0.06619315 | AX8: =AW8/$D$16 -> 0 | AY8: =$AY$12*BR8 -> 1820311.6 | AZ8: =IF(AY8="","",AY8/$AY$12) -> 0.06619315 | BA8: =IF(AZ8="","",AX8-AZ8) -> -0.06619315 | BC8: =BB8/$D$16 -> 0 | BD8: =$BD$12*BR8 -> 1773976.4 | BE8: =IF(BD8="","",BD8/$BD$12) -> 0.06619315 | BF8: =IF(BE8="","",BC8-BE8) -> -0.06619315 | BH8: =BG8/$D$16 -> 0 | BI8: =$BI$12*BR8 -> 1992413.8 | BJ8: =IF(BI8="","",BI8/$BI$12) -> 0.06619315 | BK8: =IF(BJ8="","",BH8-BJ8) -> -0.06619315 | BL8: =SUM(D8,I8,N8,S8,X8,AC8,AH8,AM8,AR8,AW8,BB8,BG8) -> 3651163.7 | BM8: =BL8/$BL$16 -> 0.082082327 | BN8: =F8+K8+P8+U8+Z8+AE8+AJ8+AO8+AT8+AY8+BD8+BI8 -> 20809136 | BO8: =IF(BN8="","",BN8/$BN$16) -> 0.070382939 | BP8: =IF(BO8="","",BM8-BO8) -> 0.011699389 | BQ8: 19321006 | BR8: =BQ8/$BQ$12 -> 0.06619315
A9: Vda_Pix | C9: Vendas - Pix | D9: =SUMIF(EXTRATO!$F$14:$F$194,"Vda_PIX",EXTRATO!$I$14:$I$194) -> 4357122.2 | E9: =D9/$D$12 -> 0.17406827 | F9: =$F$12*BR9 -> 4160152.3 | G9: =IF(F9="","",F9/$F$12) -> 0.18514306 | H9: =IF(G9="","",E9-G9) -> -0.011074787 | I9: =SUMIF(EXTRATO!$F$14:$F$194,"Vda_PIX",EXTRATO!$J$14:$J$194) -> 4610181.1 | J9: =I9/$I$12 -> 0.2040731 | K9: =$K$12*BR9 -> 4387890.6 | L9: =IF(K9="","",K9/$K$12) -> 0.18514306 | M9: =IF(L9="","",J9-L9) -> 0.018930037 | O9: =IFERROR(N9/$N$16,"") | P9: =$P$12*BR9 -> 4628576.5 | Q9: =IF(P9="","",P9/$P$12) -> 0.18514306 | R9: =N9-P9 -> -4628576.5 | T9: =S9/$D$16 -> 0 | U9: =$U$12*BR9 -> 4813719.6 | V9: =IF(U9="","",U9/$U$12) -> 0.18514306 | W9: =IF(V9="","",T9-V9) -> -0.18514306 | Y9: =X9/$D$16 -> 0 | Z9: =$Z$12*BR9 -> 4998862.7 | AA9: =IF(Z9="","",Z9/$Z$12) -> 0.18514306 | AB9: =IF(AA9="","",Y9-AA9) -> -0.18514306 | AD9: =AC9/$D$16 -> 0 | AE9: =$AE$12*BR9 -> 4813719.6 | AF9: =IF(AE9="","",AE9/$AE$12) -> 0.18514306 | AG9: =IF(AF9="","",AD9-AF9) -> -0.18514306 | AI9: =AH9/$D$16 -> 0 | AJ9: =$AJ$12*BR9 -> 5146977.1 | AK9: =IF(AJ9="","",AJ9/$AJ$12) -> 0.18514306 | AL9: =IF(AK9="","",AI9-AK9) -> -0.18514306 | AN9: =AM9/$D$16 -> 0 | AO9: =$AO$12*BR9 -> 4832233.9 | AP9: =IF(AO9="","",AO9/$AO$12) -> 0.18514306 | AQ9: =IF(AP9="","",AN9-AP9) -> -0.18514306 | AS9: =AR9/$D$16 -> 0 | AT9: =$AT$12*BR9 -> 4795205.3 | AU9: =IF(AT9="","",AT9/$AT$12) -> 0.18514306 | AV9: =IF(AU9="","",AS9-AU9) -> -0.18514306 | AX9: =AW9/$D$16 -> 0 | AY9: =$AY$12*BR9 -> 5091434.2 | AZ9: =IF(AY9="","",AY9/$AY$12) -> 0.18514306 | BA9: =IF(AZ9="","",AX9-AZ9) -> -0.18514306 | BC9: =BB9/$D$16 -> 0 | BD9: =$BD$12*BR9 -> 4961834 | BE9: =IF(BD9="","",BD9/$BD$12) -> 0.18514306 | BF9: =IF(BE9="","",BC9-BE9) -> -0.18514306 | BH9: =BG9/$D$16 -> 0 | BI9: =$BI$12*BR9 -> 5572806.1 | BJ9: =IF(BI9="","",BI9/$BI$12) -> 0.18514306 | BK9: =IF(BJ9="","",BH9-BJ9) -> -0.18514306 | BL9: =SUM(D9,I9,N9,S9,X9,AC9,AH9,AM9,AR9,AW9,BB9,BG9) -> 8967303.3 | BM9: =BL9/$BL$16 -> 0.20159521 | BN9: =F9+K9+P9+U9+Z9+AE9+AJ9+AO9+AT9+AY9+BD9+BI9 -> 58203412 | BO9: =IF(BN9="","",BN9/$BN$16) -> 0.19686195 | BP9: =IF(BO9="","",BM9-BO9) -> 0.004733261 | BQ9: 54041092 | BR9: =BQ9/$BQ$12 -> 0.18514306
A10: Vda_Che | B10: Vda_Che_S | C10: Vendas - Cheques | D10: =SUMIF(EXTRATO!$F$14:$F$194,"Vda_Che",EXTRATO!$I$14:$I$194)-SUMIF(EXTRATO!$F$14:$F$194,"Vda_Che_S",EXTRATO!$I$14:$I$194) -> 110104.36 | E10: =D10/$D$12 -> 0.0043987006 | F10: =$F$12*BR10 -> 136244.35 | G10: =IF(F10="","",F10/$F$12) -> 0.0060634067 | H10: =IF(G10="","",E10-G10) -> -0.0016647061 | I10: =SUMIF(EXTRATO!$F$14:$F$194,"Vda_Che",EXTRATO!$J$14:$J$194)-SUMIF(EXTRATO!$F$14:$F$194,"Vda_Che_S",EXTRATO!$J$14:$J$194) -> 123887.88 | J10: =I10/$I$12 -> 0.0054839892 | K10: =$K$12*BR10 -> 143702.74 | L10: =IF(K10="","",K10/$K$12) -> 0.0060634067 | M10: =IF(L10="","",J10-L10) -> -0.00057941752 | O10: =IFERROR(N10/$N$16,"") | P10: =$P$12*BR10 -> 151585.17 | Q10: =IF(P10="","",P10/$P$12) -> 0.0060634067 | R10: =N10-P10 -> -151585.17 | T10: =S10/$D$16 -> 0 | U10: =$U$12*BR10 -> 157648.58 | V10: =IF(U10="","",U10/$U$12) -> 0.0060634067 | W10: =IF(V10="","",T10-V10) -> -0.0060634067 | Y10: =X10/$D$16 -> 0 | Z10: =$Z$12*BR10 -> 163711.98 | AA10: =IF(Z10="","",Z10/$Z$12) -> 0.0060634067 | AB10: =IF(AA10="","",Y10-AA10) -> -0.0060634067 | AD10: =AC10/$D$16 -> 0 | AE10: =$AE$12*BR10 -> 157648.58 | AF10: =IF(AE10="","",AE10/$AE$12) -> 0.0060634067 | AG10: =IF(AF10="","",AD10-AF10) -> -0.0060634067 | AI10: =AH10/$D$16 -> 0 | AJ10: =$AJ$12*BR10 -> 168562.71 | AK10: =IF(AJ10="","",AJ10/$AJ$12) -> 0.0060634067 | AL10: =IF(AK10="","",AI10-AK10) -> -0.0060634067 | AN10: =AM10/$D$16 -> 0 | AO10: =$AO$12*BR10 -> 158254.92 | AP10: =IF(AO10="","",AO10/$AO$12) -> 0.0060634067 | AQ10: =IF(AP10="","",AN10-AP10) -> -0.0060634067 | AS10: =AR10/$D$16 -> 0 | AT10: =$AT$12*BR10 -> 157042.23 | AU10: =IF(AT10="","",AT10/$AT$12) -> 0.0060634067 | AV10: =IF(AU10="","",AS10-AU10) -> -0.0060634067 | AX10: =AW10/$D$16 -> 0 | AY10: =$AY$12*BR10 -> 166743.69 | AZ10: =IF(AY10="","",AY10/$AY$12) -> 0.0060634067 | BA10: =IF(AZ10="","",AX10-AZ10) -> -0.0060634067 | BC10: =BB10/$D$16 -> 0 | BD10: =$BD$12*BR10 -> 162499.3 | BE10: =IF(BD10="","",BD10/$BD$12) -> 0.0060634067 | BF10: =IF(BE10="","",BC10-BE10) -> -0.0060634067 | BH10: =BG10/$D$16 -> 0 | BI10: =$BI$12*BR10 -> 182508.54 | BJ10: =IF(BI10="","",BI10/$BI$12) -> 0.0060634067 | BK10: =IF(BJ10="","",BH10-BJ10) -> -0.0060634067 | BL10: =SUM(D10,I10,N10,S10,X10,AC10,AH10,AM10,AR10,AW10,BB10,BG10) -> 233992.24 | BM10: =BL10/$BL$16 -> 0.0052604127 | BN10: =F10+K10+P10+U10+Z10+AE10+AJ10+AO10+AT10+AY10+BD10+BI10 -> 1906152.8 | BO10: =IF(BN10="","",BN10/$BN$16) -> 0.0064471987 | BP10: =IF(BO10="","",BM10-BO10) -> -0.001186786 | BQ10: 1769837.4 | BR10: =BQ10/$BQ$12 -> 0.0060634067
A11: Vda_Dly | C11: Vendas - Delivery | D11: =SUMIF(EXTRATO!$F$14:$F$194,"Vda_DLY",EXTRATO!$I$14:$I$194) -> 9719.78 | E11: =D11/$D$12 -> 0.00038830799 | F11: =$F$12*BR11 -> 4743.8681 | G11: =IF(F11="","",F11/$F$12) -> 0.0002111207 | H11: =IF(G11="","",E11-G11) -> 0.00017718729 | I11: =SUMIF(EXTRATO!$F$14:$F$194,"Vda_DLY",EXTRATO!$J$14:$J$194) -> 9967.89 | J11: =I11/$I$12 -> 0.00044123607 | K11: =$K$12*BR11 -> 5003.5605 | L11: =IF(K11="","",K11/$K$12) -> 0.0002111207 | M11: =IF(L11="","",J11-L11) -> 0.00023011537 | O11: =IFERROR(N11/$N$16,"") | P11: =$P$12*BR11 -> 5278.0174 | Q11: =IF(P11="","",P11/$P$12) -> 0.0002111207 | R11: =N11-P11 -> -5278.0174 | T11: =S11/$D$16 -> 0 | U11: =$U$12*BR11 -> 5489.1381 | V11: =IF(U11="","",U11/$U$12) -> 0.0002111207 | W11: =IF(V11="","",T11-V11) -> -0.0002111207 | Y11: =X11/$D$16 -> 0 | Z11: =$Z$12*BR11 -> 5700.2588 | AA11: =IF(Z11="","",Z11/$Z$12) -> 0.0002111207 | AB11: =IF(AA11="","",Y11-AA11) -> -0.0002111207 | AD11: =AC11/$D$16 -> 0 | AE11: =$AE$12*BR11 -> 5489.1381 | AF11: =IF(AE11="","",AE11/$AE$12) -> 0.0002111207 | AG11: =IF(AF11="","",AD11-AF11) -> -0.0002111207 | AI11: =AH11/$D$16 -> 0 | AJ11: =$AJ$12*BR11 -> 5869.1554 | AK11: =IF(AJ11="","",AJ11/$AJ$12) -> 0.0002111207 | AL11: =IF(AK11="","",AI11-AK11) -> -0.0002111207 | AN11: =AM11/$D$16 -> 0 | AO11: =$AO$12*BR11 -> 5510.2502 | AP11: =IF(AO11="","",AO11/$AO$12) -> 0.0002111207 | AQ11: =IF(AP11="","",AN11-AP11) -> -0.0002111207 | AS11: =AR11/$D$16 -> 0 | AT11: =$AT$12*BR11 -> 5468.026 | AU11: =IF(AT11="","",AT11/$AT$12) -> 0.0002111207 | AV11: =IF(AU11="","",AS11-AU11) -> -0.0002111207 | AX11: =AW11/$D$16 -> 0 | AY11: =$AY$12*BR11 -> 5805.8192 | AZ11: =IF(AY11="","",AY11/$AY$12) -> 0.0002111207 | BA11: =IF(AZ11="","",AX11-AZ11) -> -0.0002111207 | BC11: =BB11/$D$16 -> 0 | BD11: =$BD$12*BR11 -> 5658.0347 | BE11: =IF(BD11="","",BD11/$BD$12) -> 0.0002111207 | BF11: =IF(BE11="","",BC11-BE11) -> -0.0002111207 | BH11: =BG11/$D$16 -> 0 | BI11: =$BI$12*BR11 -> 6354.733 | BJ11: =IF(BI11="","",BI11/$BI$12) -> 0.0002111207 | BK11: =IF(BJ11="","",BH11-BJ11) -> -0.0002111207 | BL11: =SUM(D11,I11,N11,S11,X11,AC11,AH11,AM11,AR11,AW11,BB11,BG11) -> 19687.67 | BM11: =BL11/$BL$16 -> 0.0004426013 | BN11: =F11+K11+P11+U11+Z11+AE11+AJ11+AO11+AT11+AY11+BD11+BI11 -> 66369.999 | BO11: =IF(BN11="","",BN11/$BN$16) -> 0.00022448388 | BP11: =IF(BO11="","",BM11-BO11) -> 0.00021811742 | BQ11: 61623.66 | BR11: =BQ11/$BQ$12 -> 0.0002111207
C12: Vendas - Totais | D12: =SUM(D4:D11) -> 25031110 | E12: =SUM(E4:E11) -> 1 | F12: 22469934 | G12: =SUM(G4:G11) -> 1 | H12: =IF(G12="","",E12-G12) -> 2.220446e-16 | I12: =SUM(I4:I11) -> 22590832 | J12: =SUM(J4:J11) -> 1 | K12: 23700000 | L12: =SUM(L4:L11) -> 1 | M12: =IF(L12="","",J12-L12) -> -1.110223e-16 | N12: =SUM(N4:N11) -> 0 | O12: =IFERROR(SUM(O4:O11),"") -> 0 | P12: 25000000 | Q12: =SUM(Q4:Q11) -> 1 | R12: =N12-P12 -> -25000000 | S12: =SUM(S4:S11) -> 0 | T12: =SUM(T4:T11) -> 0 | U12: 26000000 | V12: =SUM(V4:V11) -> 1 | W12: =IF(V12="","",T12-V12) -> -1 | X12: =SUM(X4:X11) -> 0 | Y12: =SUM(Y4:Y11) -> 0 | Z12: 27000000 | AA12: =SUM(AA4:AA11) -> 1 | AB12: =IF(AA12="","",Y12-AA12) -> -1 | AC12: =SUM(AC4:AC11) -> 0 | AD12: =SUM(AD4:AD11) -> 0 | AE12: 26000000 | AF12: =SUM(AF4:AF11) -> 1 | AG12: =IF(AF12="","",AD12-AF12) -> -1 | AH12: =SUM(AH4:AH11) -> 0 | AI12: =SUM(AI4:AI11) -> 0 | AJ12: 27800000 | AK12: =SUM(AK4:AK11) -> 1 | AL12: =IF(AK12="","",AI12-AK12) -> -1 | AM12: =SUM(AM4:AM11) -> 0 | AN12: =SUM(AN4:AN11) -> 0 | AO12: 26100000 | AP12: =SUM(AP4:AP11) -> 1 | AQ12: =IF(AP12="","",AN12-AP12) -> -1 | AR12: =SUM(AR4:AR11) -> 0 | AS12: =SUM(AS4:AS11) -> 0 | AT12: 25900000 | AU12: =SUM(AU4:AU11) -> 1 | AV12: =IF(AU12="","",AS12-AU12) -> -1 | AW12: =SUM(AW4:AW11) -> 0 | AX12: =SUM(AX4:AX11) -> 0 | AY12: 27500000 | AZ12: =SUM(AZ4:AZ11) -> 1 | BA12: =IF(AZ12="","",AX12-AZ12) -> -1 | BB12: =SUM(BB4:BB11) -> 0 | BC12: =SUM(BC4:BC11) -> 0 | BD12: 26800000 | BE12: =SUM(BE4:BE11) -> 1 | BF12: =IF(BE12="","",BC12-BE12) -> -1 | BG12: =SUM(BG4:BG11) -> 0 | BH12: =SUM(BH4:BH11) -> 0 | BI12: 30100000 | BJ12: =SUM(BJ4:BJ11) -> 1 | BK12: =IF(BJ12="","",BH12-BJ12) -> -1 | BL12: =SUM(BL4:BL11) -> 47621942 | BM12: =SUM(BM4:BM11) -> 1.0705956 | BN12: =F12+K12+P12+U12+Z12+AE12+AJ12+AO12+AT12+AY12+BD12+BI12 -> 3.1436993e+08 | BO12: =IF(BN12="","",SUM(BO4:BO11)) -> 1.0632964 | BP12: =IF(BO12="","",BM12-BO12) -> 0.007299215 | BQ12: =SUM(BQ4:BQ11) -> 2.9188829e+08 | BR12: =SUM(BR4:BR11) -> 1
A13: Trocas | C13: ( - ) Devolução de Vendas | D13: =SUMIF(EXTRATO!$F$14:$F$194,"Trocas",EXTRATO!$I$14:$I$194) -> 8489.33 | E13: =D13/$D$12 -> 0.00033915116 | F13: =$F$12*BR13 -> 18161.648 | G13: =IF(F13="","",F13/$F$12) -> 0.00080826441 | H13: =IF(G13="","",E13-G13) -> -0.00046911325 | I13: =SUMIF(EXTRATO!$F$14:$F$194,"Trocas",EXTRATO!$J$14:$J$194) -> 6435.62 | J13: =I13/$I$12 -> 0.00028487751 | K13: =$K$12*BR13 -> 19155.867 | L13: =IF(K13="","",K13/$K$12) -> 0.00080826441 | M13: =IF(L13="","",J13-L13) -> -0.0005233869 | O13: =IFERROR(N13/$N$16,"") | P13: =$P$12*BR13 -> 20206.61 | Q13: =IF(P13="","",P13/$P$12) -> 0.00080826441 | R13: =N13-P13 -> -20206.61 | T13: =S13/$D$16 -> 0 | U13: =$U$12*BR13 -> 21014.875 | V13: =IF(U13="","",U13/$U$12) -> 0.00080826441 | W13: =IF(V13="","",T13-V13) -> -0.00080826441 | Y13: =X13/$D$16 -> 0 | Z13: =$Z$12*BR13 -> 21823.139 | AA13: =IF(Z13="","",Z13/$Z$12) -> 0.00080826441 | AB13: =IF(AA13="","",Y13-AA13) -> -0.00080826441 | AD13: =AC13/$D$16 -> 0 | AE13: =$AE$12*BR13 -> 21014.875 | AF13: =IF(AE13="","",AE13/$AE$12) -> 0.00080826441 | AG13: =IF(AF13="","",AD13-AF13) -> -0.00080826441 | AI13: =AH13/$D$16 -> 0 | AJ13: =$AJ$12*BR13 -> 22469.751 | AK13: =IF(AJ13="","",AJ13/$AJ$12) -> 0.00080826441 | AL13: =IF(AK13="","",AI13-AK13) -> -0.00080826441 | AN13: =AM13/$D$16 -> 0 | AO13: =$AO$12*BR13 -> 21095.701 | AP13: =IF(AO13="","",AO13/$AO$12) -> 0.00080826441 | AQ13: =IF(AP13="","",AN13-AP13) -> -0.00080826441 | AS13: =AR13/$D$16 -> 0 | AT13: =$AT$12*BR13 -> 20934.048 | AU13: =IF(AT13="","",AT13/$AT$12) -> 0.00080826441 | AV13: =IF(AU13="","",AS13-AU13) -> -0.00080826441 | AX13: =AW13/$D$16 -> 0 | AY13: =$AY$12*BR13 -> 22227.271 | AZ13: =IF(AY13="","",AY13/$AY$12) -> 0.00080826441 | BA13: =IF(AZ13="","",AX13-AZ13) -> -0.00080826441 | BC13: =BB13/$D$16 -> 0 | BD13: =$BD$12*BR13 -> 21661.486 | BE13: =IF(BD13="","",BD13/$BD$12) -> 0.00080826441 | BF13: =IF(BE13="","",BC13-BE13) -> -0.00080826441 | BH13: =BG13/$D$16 -> 0 | BI13: =$BI$12*BR13 -> 24328.759 | BJ13: =IF(BI13="","",BI13/$BI$12) -> 0.00080826441 | BK13: =IF(BJ13="","",BH13-BJ13) -> -0.00080826441 | BL13: =SUM(D13,I13,N13,S13,X13,AC13,AH13,AM13,AR13,AW13,BB13,BG13) -> 14924.95 | BM13: =BL13/$BL$16 -> 0.00033552991 | BN13: =F13+K13+P13+U13+Z13+AE13+AJ13+AO13+AT13+AY13+BD13+BI13 -> 254094.03 | BO13: =IF(BN13="","",BN13/$BN$16) -> 0.00085942465 | BP13: =IF(BO13="","",BM13-BO13) -> -0.00052389474 | BQ13: 235922.92 | BR13: =BQ13/$BQ$12 -> 0.00080826441
A14: Vda_S | C14: ( - ) Extra - Caixa | D14: =SUMIF(EXTRATO!$F$14:$F$194,"Vda_s",EXTRATO!$I$14:$I$194) -> 103291.45 | E14: =D14/$D$12 -> 0.0041265229 | F14: =$F$12*BR14 -> 103928.51 | G14: =IF(F14="","",F14/$F$12) -> 0.0046252257 | H14: =IF(G14="","",E14-G14) -> -0.00049870275 | I14: =SUMIF(EXTRATO!$F$14:$F$194,"Vda_s",EXTRATO!$J$14:$J$194) -> 50270.76 | J14: =I14/$I$12 -> 0.0022252726 | K14: =$K$12*BR14 -> 109617.85 | L14: =IF(K14="","",K14/$K$12) -> 0.0046252257 | M14: =IF(L14="","",J14-L14) -> -0.0023999531 | O14: =IFERROR(N14/$N$16,"") | P14: =$P$12*BR14 -> 115630.64 | Q14: =IF(P14="","",P14/$P$12) -> 0.0046252257 | R14: =N14-P14 -> -115630.64 | T14: =S14/$D$16 -> 0 | U14: =$U$12*BR14 -> 120255.87 | V14: =IF(U14="","",U14/$U$12) -> 0.0046252257 | W14: =IF(V14="","",T14-V14) -> -0.0046252257 | Y14: =X14/$D$16 -> 0 | Z14: =$Z$12*BR14 -> 124881.09 | AA14: =IF(Z14="","",Z14/$Z$12) -> 0.0046252257 | AB14: =IF(AA14="","",Y14-AA14) -> -0.0046252257 | AD14: =AC14/$D$16 -> 0 | AE14: =$AE$12*BR14 -> 120255.87 | AF14: =IF(AE14="","",AE14/$AE$12) -> 0.0046252257 | AG14: =IF(AF14="","",AD14-AF14) -> -0.0046252257 | AI14: =AH14/$D$16 -> 0 | AJ14: =$AJ$12*BR14 -> 128581.27 | AK14: =IF(AJ14="","",AJ14/$AJ$12) -> 0.0046252257 | AL14: =IF(AK14="","",AI14-AK14) -> -0.0046252257 | AN14: =AM14/$D$16 -> 0 | AO14: =$AO$12*BR14 -> 120718.39 | AP14: =IF(AO14="","",AO14/$AO$12) -> 0.0046252257 | AQ14: =IF(AP14="","",AN14-AP14) -> -0.0046252257 | AS14: =AR14/$D$16 -> 0 | AT14: =$AT$12*BR14 -> 119793.34 | AU14: =IF(AT14="","",AT14/$AT$12) -> 0.0046252257 | AV14: =IF(AU14="","",AS14-AU14) -> -0.0046252257 | AX14: =AW14/$D$16 -> 0 | AY14: =$AY$12*BR14 -> 127193.71 | AZ14: =IF(AY14="","",AY14/$AY$12) -> 0.0046252257 | BA14: =IF(AZ14="","",AX14-AZ14) -> -0.0046252257 | BC14: =BB14/$D$16 -> 0 | BD14: =$BD$12*BR14 -> 123956.05 | BE14: =IF(BD14="","",BD14/$BD$12) -> 0.0046252257 | BF14: =IF(BE14="","",BC14-BE14) -> -0.0046252257 | BH14: =BG14/$D$16 -> 0 | BI14: =$BI$12*BR14 -> 139219.29 | BJ14: =IF(BI14="","",BI14/$BI$12) -> 0.0046252257 | BK14: =IF(BJ14="","",BH14-BJ14) -> -0.0046252257 | BL14: =SUM(D14,I14,N14,S14,X14,AC14,AH14,AM14,AR14,AW14,BB14,BG14) -> 153562.21 | BM14: =BL14/$BL$16 -> 0.0034522538 | BN14: =F14+K14+P14+U14+Z14+AE14+AJ14+AO14+AT14+AY14+BD14+BI14 -> 1454031.9 | BO14: =IF(BN14="","",BN14/$BN$16) -> 0.0049179859 | BP14: =IF(BO14="","",BM14-BO14) -> -0.0014657321 | BQ14: 1350049.2 | BR14: =BQ14/$BQ$12 -> 0.0046252257
A15: Vda_Pri_S | C15: ( - ) Repasse Private | D15: =SUMIF(EXTRATO!$F$14:$F$194,"Vda_pri_S",EXTRATO!$I$14:$I$194) -> 1532944 | E15: =D15/$D$12 -> 0.06124155 | F15: =$F$12*BR15 -> 1215510.8 | G15: =IF(F15="","",F15/$F$12) -> 0.054094987 | H15: =IF(G15="","",E15-G15) -> 0.0071465628 | I15: =SUMIF(EXTRATO!$F$14:$F$194,"Vda_pri_S",EXTRATO!$J$14:$J$194) -> 1438784.4 | J15: =I15/$I$12 -> 0.063688865 | K15: =$K$12*BR15 -> 1282051.2 | L15: =IF(K15="","",K15/$K$12) -> 0.054094987 | M15: =IF(L15="","",J15-L15) -> 0.0095938774 | O15: =IFERROR(N15/$N$16,"") | P15: =$P$12*BR15 -> 1352374.7 | Q15: =IF(P15="","",P15/$P$12) -> 0.054094987 | R15: =N15-P15 -> -1352374.7 | T15: =S15/$D$16 -> 0 | U15: =$U$12*BR15 -> 1406469.7 | V15: =IF(U15="","",U15/$U$12) -> 0.054094987 | W15: =IF(V15="","",T15-V15) -> -0.054094987 | Y15: =X15/$D$16 -> 0 | Z15: =$Z$12*BR15 -> 1460564.7 | AA15: =IF(Z15="","",Z15/$Z$12) -> 0.054094987 | AB15: =IF(AA15="","",Y15-AA15) -> -0.054094987 | AD15: =AC15/$D$16 -> 0 | AE15: =$AE$12*BR15 -> 1406469.7 | AF15: =IF(AE15="","",AE15/$AE$12) -> 0.054094987 | AG15: =IF(AF15="","",AD15-AF15) -> -0.054094987 | AI15: =AH15/$D$16 -> 0 | AJ15: =$AJ$12*BR15 -> 1503840.6 | AK15: =IF(AJ15="","",AJ15/$AJ$12) -> 0.054094987 | AL15: =IF(AK15="","",AI15-AK15) -> -0.054094987 | AN15: =AM15/$D$16 -> 0 | AO15: =$AO$12*BR15 -> 1411879.2 | AP15: =IF(AO15="","",AO15/$AO$12) -> 0.054094987 | AQ15: =IF(AP15="","",AN15-AP15) -> -0.054094987 | AS15: =AR15/$D$16 -> 0 | AT15: =$AT$12*BR15 -> 1401060.2 | AU15: =IF(AT15="","",AT15/$AT$12) -> 0.054094987 | AV15: =IF(AU15="","",AS15-AU15) -> -0.054094987 | AX15: =AW15/$D$16 -> 0 | AY15: =$AY$12*BR15 -> 1487612.1 | AZ15: =IF(AY15="","",AY15/$AY$12) -> 0.054094987 | BA15: =IF(AZ15="","",AX15-AZ15) -> -0.054094987 | BC15: =BB15/$D$16 -> 0 | BD15: =$BD$12*BR15 -> 1449745.7 | BE15: =IF(BD15="","",BD15/$BD$12) -> 0.054094987 | BF15: =IF(BE15="","",BC15-BE15) -> -0.054094987 | BH15: =BG15/$D$16 -> 0 | BI15: =$BI$12*BR15 -> 1628259.1 | BJ15: =IF(BI15="","",BI15/$BI$12) -> 0.054094987 | BK15: =IF(BJ15="","",BH15-BJ15) -> -0.054094987 | BL15: =SUM(D15,I15,N15,S15,X15,AC15,AH15,AM15,AR15,AW15,BB15,BG15) -> 2971728.4 | BM15: =BL15/$BL$16 -> 0.066807848 | BN15: =F15+K15+P15+U15+Z15+AE15+AJ15+AO15+AT15+AY15+BD15+BI15 -> 17005838 | BO15: =IF(BN15="","",BN15/$BN$16) -> 0.057519006 | BP15: =IF(BO15="","",BM15-BO15) -> 0.0092888419 | BQ15: 15789694 | BR15: =BQ15/$BQ$12 -> 0.054094987
C16: ( = ) Vendas Líquidas Recebidas | D16: =D12-D13-D14-D15 -> 23386386 | E16: 1 | F16: =F12-F13-F14-F15 -> 21132333 | G16: 1 | H16: =IF(G16="","",E16-G16) -> 0 | I16: =I12-I13-I14-I15 -> 21095341 | J16: 1 | K16: =K12-K13-K14-K15 -> 22289175 | L16: =IF(K16="","",K16/$K$16) -> 1 | M16: =IF(L16="","",J16-L16) -> 0 | N16: =N12-N13-N14-N15 -> 0 | O16: =IFERROR(SUM(O4:O11)-O14-O15,"") | P16: =P12-P13-P14-P15 -> 23511788 | Q16: =IF(P16="","",P16/$P$16) -> 1 | R16: =N16-P16 -> -23511788 | S16: =S12-S13-S14-S15 -> 0 | T16: =SUM(T4:T11)-T14-T15 -> 0 | U16: =U12-U13-U14-U15 -> 24452260 | V16: =IF(U16="","",U16/$U$16) -> 1 | W16: =IF(V16="","",T16-V16) -> -1 | X16: =X12-X13-X14-X15 -> 0 | Y16: =SUM(Y4:Y11)-Y14-Y15 -> 0 | Z16: =Z12-Z13-Z14-Z15 -> 25392731 | AA16: =IF(Z16="","",Z16/$Z$16) -> 1 | AB16: =IF(AA16="","",Y16-AA16) -> -1 | AC16: =AC12-AC13-AC14-AC15 -> 0 | AD16: =SUM(AD4:AD11)-AD14-AD15 -> 0 | AE16: =AE12-AE13-AE14-AE15 -> 24452260 | AF16: =IF(AE16="","",AE16/$AE$16) -> 1 | AG16: =IF(AF16="","",AD16-AF16) -> -1 | AH16: =AH12-AH13-AH14-AH15 -> 0 | AI16: =SUM(AI4:AI11)-AI14-AI15 -> 0 | AJ16: =AJ12-AJ13-AJ14-AJ15 -> 26145108 | AK16: =IF(AJ16="","",AJ16/$AJ$16) -> 1 | AL16: =IF(AK16="","",AI16-AK16) -> -1 | AM16: =AM12-AM13-AM14-AM15 -> 0 | AN16: =SUM(AN4:AN11)-AN14-AN15 -> 0 | AO16: =AO12-AO13-AO14-AO15 -> 24546307 | AP16: =IF(AO16="","",AO16/$AO$16) -> 1 | AQ16: =IF(AP16="","",AN16-AP16) -> -1 | AR16: =AR12-AR13-AR14-AR15 -> 0 | AS16: =SUM(AS4:AS11)-AS14-AS15 -> 0 | AT16: =AT12-AT13-AT14-AT15 -> 24358212 | AU16: =IF(AT16="","",AT16/$AT$16) -> 1 | AV16: =IF(AU16="","",AS16-AU16) -> -1 | AW16: =AW12-AW13-AW14-AW15 -> 0 | AX16: =SUM(AX4:AX11)-AX14-AX15 -> 0 | AY16: =AY12-AY13-AY14-AY15 -> 25862967 | AZ16: =IF(AY16="","",AY16/$AY$16) -> 1 | BA16: =IF(AZ16="","",AX16-AZ16) -> -1 | BB16: =BB12-BB13-BB14-BB15 -> 0 | BC16: =SUM(BC4:BC11)-BC14-BC15 -> 0 | BD16: =BD12-BD13-BD14-BD15 -> 25204637 | BE16: =IF(BD16="","",BD16/$BD$16) -> 1 | BF16: =IF(BE16="","",BC16-BE16) -> -1 | BG16: =BG12-BG13-BG14-BG15 -> 0 | BH16: =SUM(BH4:BH11)-BH14-BH15 -> 0 | BI16: =BI12-BI13-BI14-BI15 -> 28308193 | BJ16: =IF(BI16="","",BI16/$BI$16) -> 1 | BK16: =IF(BJ16="","",BH16-BJ16) -> -1 | BL16: =BL12-BL13-BL14-BL15 -> 44481727 | BM16: =SUM(BM4:BM11)-BM14-BM15 -> 1.0003355 | BN16: =F16+K16+P16+U16+Z16+AE16+AJ16+AO16+AT16+AY16+BD16+BI16 -> 2.9565597e+08 | BO16: =IF(BN16="","",BN16/$BN$16) -> 1 | BP16: =IF(BO16="","",BM16-BO16) -> 0.00033552991 | BQ16: =BQ12-BQ13-BQ14-BQ15 -> 2.7451263e+08 | BR16: 1
A17: Compras | C17: ( - ) Compras | D17: =SUMIF(EXTRATO!$F$14:$F$194,"COMPRAS",EXTRATO!$I$14:$I$194)+SUMIF(DESPESA!$E$4:$E$140,"Compras",DESPESA!$I$4:$I$140) -> 18525796 | E17: =D17/$D$16 -> 0.79216158 | F17: =F16*75% -> 15849250 | G17: =IF(F17="","",F17/$F$16) -> 0.75 | H17: =IF(G17="","",E17-G17) -> 0.042161582 | I17: =SUMIF(EXTRATO!$F$14:$F$194,"COMPRAS",EXTRATO!$J$14:$J$194)+SUMIF(DESPESA!$E$4:$E$140,"Compras",DESPESA!$J$4:$J$140) -> 16679785 | J17: =I17/$I$16 -> 0.79068569 | K17: =K16*75% -> 16716881 | L17: =IF(K17="","",K17/$K$16) -> 0.75 | M17: =IF(L17="","",J17-L17) -> 0.040685695 | O17: =IFERROR(N17/$N$16,"") | P17: =P16*75% -> 17633841 | Q17: =IF(P17="","",P17/$P$16) -> 0.75 | R17: =N17-P17 -> -17633841 | T17: =S17/$D$16 -> 0 | U17: =U16*75% -> 18339195 | V17: =IF(U17="","",U17/$U$16) -> 0.75 | W17: =IF(V17="","",T17-V17) -> -0.75 | Y17: =X17/$D$16 -> 0 | Z17: =Z16*75% -> 19044548 | AA17: =IF(Z17="","",Z17/$Z$16) -> 0.75 | AB17: =IF(AA17="","",Y17-AA17) -> -0.75 | AD17: =AC17/$D$16 -> 0 | AE17: =AE16*75% -> 18339195 | AF17: =IF(AE17="","",AE17/$AE$16) -> 0.75 | AG17: =IF(AF17="","",AD17-AF17) -> -0.75 | AI17: =AH17/$D$16 -> 0 | AJ17: =AJ16*75% -> 19608831 | AK17: =IF(AJ17="","",AJ17/$AJ$16) -> 0.75 | AL17: =IF(AK17="","",AI17-AK17) -> -0.75 | AN17: =AM17/$D$16 -> 0 | AO17: =AO16*75% -> 18409730 | AP17: =IF(AO17="","",AO17/$AO$16) -> 0.75 | AQ17: =IF(AP17="","",AN17-AP17) -> -0.75 | AS17: =AR17/$D$16 -> 0 | AT17: =AT16*75% -> 18268659 | AU17: =IF(AT17="","",AT17/$AT$16) -> 0.75 | AV17: =IF(AU17="","",AS17-AU17) -> -0.75 | AX17: =AW17/$D$16 -> 0 | AY17: =AY16*75% -> 19397225 | AZ17: =IF(AY17="","",AY17/$AY$16) -> 0.75 | BA17: =IF(AZ17="","",AX17-AZ17) -> -0.75 | BC17: =BB17/$D$16 -> 0 | BD17: =BD16*75% -> 18903478 | BE17: =IF(BD17="","",BD17/$BD$16) -> 0.75 | BF17: =IF(BE17="","",BC17-BE17) -> -0.75 | BH17: =BG17/$D$16 -> 0 | BI17: =BI16*75% -> 21231145 | BJ17: =IF(BI17="","",BI17/$BI$16) -> 0.75 | BK17: =IF(BJ17="","",BH17-BJ17) -> -0.75 | BL17: =SUM(D17,I17,N17,S17,X17,AC17,AH17,AM17,AR17,AW17,BB17,BG17) -> 35205581 | BM17: =BL17/$BL$16 -> 0.79146165 | BN17: =F17+K17+P17+U17+Z17+AE17+AJ17+AO17+AT17+AY17+BD17+BI17 -> 2.2174198e+08 | BO17: =IF(BN17="","",BN17/$BN$16) -> 0.75 | BP17: =IF(BO17="","",BM17-BO17) -> 0.041461646 | BQ17: 2.1858673e+08 | BR17: =BQ17/$BQ$16 -> 0.79627205
C18: ( = ) Margem de Venda 1 | D18: =D16-D17 -> 4860589.4 | E18: =E16-E17 -> 0.20783842 | F18: =F16-F17 -> 5283083.2 | G18: =IF(F18="","",G16-G17) -> 0.25 | H18: =IF(G18="","",E18-G18) -> -0.042161582 | I18: =I16-I17 -> 4415556.7 | J18: =J16-J17 -> 0.20931431 | K18: =K16-K17 -> 5572293.8 | L18: =IF(K18="","",L16-L17) -> 0.25 | M18: =IF(L18="","",J18-L18) -> -0.040685695 | N18: =N16-N17 -> 0 | O18: =IFERROR(O16-O17,"") | P18: =P16-P17 -> 5877947 | Q18: =IF(P18="","",Q16-Q17) -> 0.25 | R18: =N18-P18 -> -5877947 | S18: =S16-S17 -> 0 | T18: =T16-T17 -> 0 | U18: =U16-U17 -> 6113064.9 | V18: =IF(U18="","",V16-V17) -> 0.25 | W18: =IF(V18="","",T18-V18) -> -0.25 | X18: =X16-X17 -> 0 | Y18: =Y16-Y17 -> 0 | Z18: =Z16-Z17 -> 6348182.8 | AA18: =IF(Z18="","",AA16-AA17) -> 0.25 | AB18: =IF(AA18="","",Y18-AA18) -> -0.25 | AC18: =AC16-AC17 -> 0 | AD18: =AD16-AD17 -> 0 | AE18: =AE16-AE17 -> 6113064.9 | AF18: =IF(AE18="","",AF16-AF17) -> 0.25 | AG18: =IF(AF18="","",AD18-AF18) -> -0.25 | AH18: =AH16-AH17 -> 0 | AI18: =AI16-AI17 -> 0 | AJ18: =AJ16-AJ17 -> 6536277.1 | AK18: =IF(AJ18="","",AK16-AK17) -> 0.25 | AL18: =IF(AK18="","",AI18-AK18) -> -0.25 | AM18: =AM16-AM17 -> 0 | AN18: =AN16-AN17 -> 0 | AO18: =AO16-AO17 -> 6136576.7 | AP18: =IF(AO18="","",AP16-AP17) -> 0.25 | AQ18: =IF(AP18="","",AN18-AP18) -> -0.25 | AR18: =AR16-AR17 -> 0 | AS18: =AS16-AS17 -> 0 | AT18: =AT16-AT17 -> 6089553.1 | AU18: =IF(AT18="","",AU16-AU17) -> 0.25 | AV18: =IF(AU18="","",AS18-AU18) -> -0.25 | AW18: =AW16-AW17 -> 0 | AX18: =AX16-AX17 -> 0 | AY18: =AY16-AY17 -> 6465741.7 | AZ18: =IF(AY18="","",AZ16-AZ17) -> 0.25 | BA18: =IF(AZ18="","",AX18-AZ18) -> -0.25 | BB18: =BB16-BB17 -> 0 | BC18: =BC16-BC17 -> 0 | BD18: =BD16-BD17 -> 6301159.2 | BE18: =IF(BD18="","",BE16-BE17) -> 0.25 | BF18: =IF(BE18="","",BC18-BE18) -> -0.25 | BG18: =BG16-BG17 -> 0 | BH18: =BH16-BH17 -> 0 | BI18: =BI16-BI17 -> 7077048.2 | BJ18: =IF(BI18="","",BJ16-BJ17) -> 0.25 | BK18: =IF(BJ18="","",BH18-BJ18) -> -0.25 | BL18: =BL16-BL17 -> 9276146.1 | BM18: =BM16-BM17 -> 0.20887388 | BN18: =F18+K18+P18+U18+Z18+AE18+AJ18+AO18+AT18+AY18+BD18+BI18 -> 73913993 | BO18: =IF(BN18="","",BO16-BO17) -> 0.25 | BP18: =IF(BO18="","",BM18-BO18) -> -0.041126116 | BQ18: =BQ16-BQ17 -> 55925894 | BR18: =BR16-BR17 -> 0.20372795
A19: Tributario | C19: ( - ) Impostos Sobre Vendas | D19: =SUMIF(EXTRATO!$F$14:$F$194,"I_Vda",EXTRATO!$I$14:$I$194) -> 1511235.3 | E19: =D19/$D$16 -> 0.064620303 | F19: =$F$16*6.5% -> 1373601.6 | G19: =IF(F19="","",F19/$F$16) -> 0.065 | H19: =IF(G19="","",E19-G19) -> -0.00037969688 | I19: =SUMIF(EXTRATO!$F$14:$F$194,"I_Vda",EXTRATO!$J$14:$J$194) -> 1215043.8 | J19: =I19/$I$16 -> 0.057597729 | K19: =$K$16*6.5% -> 1448796.4 | L19: =IF(K19="","",K19/$K$16) -> 0.065 | M19: =IF(L19="","",J19-L19) -> -0.0074022707 | O19: =IFERROR(N19/$N$16,"") | P19: =$P$16*6.5% -> 1528266.2 | Q19: =IF(P19="","",P19/$P$16) -> 0.065 | R19: =N19-P19 -> -1528266.2 | T19: =S19/$D$16 -> 0 | U19: =$U$16*6.5% -> 1589396.9 | V19: =IF(U19="","",U19/$U$16) -> 0.065 | W19: =IF(V19="","",T19-V19) -> -0.065 | Y19: =X19/$D$16 -> 0 | Z19: =$Z$16*6.5% -> 1650527.5 | AA19: =IF(Z19="","",Z19/$Z$16) -> 0.065 | AB19: =IF(AA19="","",Y19-AA19) -> -0.065 | AD19: =AC19/$D$16 -> 0 | AE19: =$AE$16*6.5% -> 1589396.9 | AF19: =IF(AE19="","",AE19/$AE$16) -> 0.065 | AG19: =IF(AF19="","",AD19-AF19) -> -0.065 | AI19: =AH19/$D$16 -> 0 | AJ19: =$AJ$16*6.5% -> 1699432 | AK19: =IF(AJ19="","",AJ19/$AJ$16) -> 0.065 | AL19: =IF(AK19="","",AI19-AK19) -> -0.065 | AN19: =AM19/$D$16 -> 0 | AO19: =$AO$16*6.5% -> 1595509.9 | AP19: =IF(AO19="","",AO19/$AO$16) -> 0.065 | AQ19: =IF(AP19="","",AN19-AP19) -> -0.065 | AS19: =AR19/$D$16 -> 0 | AT19: =$AT$16*6.5% -> 1583283.8 | AU19: =IF(AT19="","",AT19/$AT$16) -> 0.065 | AV19: =IF(AU19="","",AS19-AU19) -> -0.065 | AX19: =AW19/$D$16 -> 0 | AY19: =$AY$16*6.5% -> 1681092.8 | AZ19: =IF(AY19="","",AY19/$AY$16) -> 0.065 | BA19: =IF(AZ19="","",AX19-AZ19) -> -0.065 | BC19: =BB19/$D$16 -> 0 | BD19: =$BD$16*6.5% -> 1638301.4 | BE19: =IF(BD19="","",BD19/$BD$16) -> 0.065 | BF19: =IF(BE19="","",BC19-BE19) -> -0.065 | BH19: =BG19/$D$16 -> 0 | BI19: =$BI$16*6.5% -> 1840032.5 | BJ19: =IF(BI19="","",BI19/$BI$16) -> 0.065 | BK19: =IF(BJ19="","",BH19-BJ19) -> -0.065 | BL19: =SUM(D19,I19,N19,S19,X19,AC19,AH19,AM19,AR19,AW19,BB19,BG19) -> 2726279.1 | BM19: =BL19/$BL$16 -> 0.061289866 | BN19: =F19+K19+P19+U19+Z19+AE19+AJ19+AO19+AT19+AY19+BD19+BI19 -> 19217638 | BO19: =IF(BN19="","",BN19/$BN$16) -> 0.065 | BP19: =IF(BO19="","",BM19-BO19) -> -0.0037101339 | BQ19: 12680836 | BR19: =BQ19/$BQ$16 -> 0.046193998
C20: ( = ) Margem de Venda 2 | D20: =D18-D19 -> 3349354.1 | E20: =E18-E19 -> 0.14321812 | F20: =F18-F19 -> 3909481.6 | G20: =IF(F20="","",G18-G19) -> 0.185 | H20: =IF(G20="","",E20-G20) -> -0.041781885 | I20: =I18-I19 -> 3200513 | J20: =J18-J19 -> 0.15171658 | K20: =K18-K19 -> 4123497.4 | L20: =IF(K20="","",L18-L19) -> 0.185 | M20: =IF(L20="","",J20-L20) -> -0.033283424 | N20: =N18-N19 -> 0 | O20: =IFERROR(O18-O19,"") | P20: =P18-P19 -> 4349680.8 | Q20: =IF(P20="","",Q18-Q19) -> 0.185 | R20: =N20-P20 -> -4349680.8 | S20: =S18-S19 -> 0 | T20: =T18-T19 -> 0 | U20: =U18-U19 -> 4523668 | V20: =IF(U20="","",V18-V19) -> 0.185 | W20: =IF(V20="","",T20-V20) -> -0.185 | X20: =X18-X19 -> 0 | Y20: =Y18-Y19 -> 0 | Z20: =Z18-Z19 -> 4697655.3 | AA20: =IF(Z20="","",AA18-AA19) -> 0.185 | AB20: =IF(AA20="","",Y20-AA20) -> -0.185 | AC20: =AC18-AC19 -> 0 | AD20: =AD18-AD19 -> 0 | AE20: =AE18-AE19 -> 4523668 | AF20: =IF(AE20="","",AF18-AF19) -> 0.185 | AG20: =IF(AF20="","",AD20-AF20) -> -0.185 | AH20: =AH18-AH19 -> 0 | AI20: =AI18-AI19 -> 0 | AJ20: =AJ18-AJ19 -> 4836845 | AK20: =IF(AJ20="","",AK18-AK19) -> 0.185 | AL20: =IF(AK20="","",AI20-AK20) -> -0.185 | AM20: =AM18-AM19 -> 0 | AN20: =AN18-AN19 -> 0 | AO20: =AO18-AO19 -> 4541066.7 | AP20: =IF(AO20="","",AP18-AP19) -> 0.185 | AQ20: =IF(AP20="","",AN20-AP20) -> -0.185 | AR20: =AR18-AR19 -> 0 | AS20: =AS18-AS19 -> 0 | AT20: =AT18-AT19 -> 4506269.3 | AU20: =IF(AT20="","",AU18-AU19) -> 0.185 | AV20: =IF(AU20="","",AS20-AU20) -> -0.185 | AW20: =AW18-AW19 -> 0 | AX20: =AX18-AX19 -> 0 | AY20: =AY18-AY19 -> 4784648.9 | AZ20: =IF(AY20="","",AZ18-AZ19) -> 0.185 | BA20: =IF(AZ20="","",AX20-AZ20) -> -0.185 | BB20: =BB18-BB19 -> 0 | BC20: =BC18-BC19 -> 0 | BD20: =BD18-BD19 -> 4662857.8 | BE20: =IF(BD20="","",BE18-BE19) -> 0.185 | BF20: =IF(BE20="","",BC20-BE20) -> -0.185 | BG20: =BG18-BG19 -> 0 | BH20: =BH18-BH19 -> 0 | BI20: =BI18-BI19 -> 5237015.7 | BJ20: =IF(BI20="","",BJ18-BJ19) -> 0.185 | BK20: =IF(BJ20="","",BH20-BJ20) -> -0.185 | BL20: =BL18-BL19 -> 6549867 | BM20: =BM18-BM19 -> 0.14758402 | BN20: =F20+K20+P20+U20+Z20+AE20+AJ20+AO20+AT20+AY20+BD20+BI20 -> 54696355 | BO20: =IF(BN20="","",BO18-BO19) -> 0.185 | BP20: =IF(BO20="","",BM20-BO20) -> -0.037415982 | BQ20: =BQ18-BQ19 -> 43245058 | BR20: =BR18-BR19 -> 0.15753395
A21: ENOP | B21: ENOP_S | C21: ( + ) Crédito Operacionais | D21: =SUMIF(EXTRATO!$F$14:$F$194,"ENOP",EXTRATO!$I$14:$I$194)-SUMIF(EXTRATO!$F$14:$F$194,"ENOP_S",EXTRATO!$I$14:$I$194) -> 192682.46 | E21: =D21/$D$16 -> 0.0082390868 | F21: =$F$16*BR21 -> 23661.492 | G21: =IF(F21="","",F21/$F$16) -> 0.001119682 | H21: =IF(G21="","",E21-G21) -> 0.0071194048 | I21: =SUMIF(EXTRATO!$F$14:$F$194,"ENOP",EXTRATO!$J$14:$J$194)-SUMIF(EXTRATO!$F$14:$F$194,"ENOP_S",EXTRATO!$J$14:$J$194) -> 2549.12 | J21: =I21/$I$16 -> 0.00012083805 | K21: =$K$16*BR21 -> 24956.787 | L21: =IF(K21="","",K21/$K$16) -> 0.001119682 | M21: =IF(L21="","",J21-L21) -> -0.00099884391 | O21: =IFERROR(N21/$N$16,"") | P21: =$P$16*BR21 -> 26325.725 | Q21: =IF(P21="","",P21/$P$16) -> 0.001119682 | R21: =N21-P21 -> -26325.725 | T21: =S21/$D$16 -> 0 | U21: =$U$16*BR21 -> 27378.754 | V21: =IF(U21="","",U21/$U$16) -> 0.001119682 | W21: =IF(V21="","",T21-V21) -> -0.001119682 | Y21: =X21/$D$16 -> 0 | Z21: =$Z$16*BR21 -> 28431.783 | AA21: =IF(Z21="","",Z21/$Z$16) -> 0.001119682 | AB21: =IF(AA21="","",Y21-AA21) -> -0.001119682 | AD21: =AC21/$D$16 -> 0 | AE21: =$AE$16*BR21 -> 27378.754 | AF21: =IF(AE21="","",AE21/$AE$16) -> 0.001119682 | AG21: =IF(AF21="","",AD21-AF21) -> -0.001119682 | AI21: =AH21/$D$16 -> 0 | AJ21: =$AJ$16*BR21 -> 29274.206 | AK21: =IF(AJ21="","",AJ21/$AJ$16) -> 0.001119682 | AL21: =IF(AK21="","",AI21-AK21) -> -0.001119682 | AN21: =AM21/$D$16 -> 0 | AO21: =$AO$16*BR21 -> 27484.057 | AP21: =IF(AO21="","",AO21/$AO$16) -> 0.001119682 | AQ21: =IF(AP21="","",AN21-AP21) -> -0.001119682 | AS21: =AR21/$D$16 -> 0 | AT21: =$AT$16*BR21 -> 27273.451 | AU21: =IF(AT21="","",AT21/$AT$16) -> 0.001119682 | AV21: =IF(AU21="","",AS21-AU21) -> -0.001119682 | AX21: =AW21/$D$16 -> 0 | AY21: =$AY$16*BR21 -> 28958.298 | AZ21: =IF(AY21="","",AY21/$AY$16) -> 0.001119682 | BA21: =IF(AZ21="","",AX21-AZ21) -> -0.001119682 | BC21: =BB21/$D$16 -> 0 | BD21: =$BD$16*BR21 -> 28221.177 | BE21: =IF(BD21="","",BD21/$BD$16) -> 0.001119682 | BF21: =IF(BE21="","",BC21-BE21) -> -0.001119682 | BH21: =BG21/$D$16 -> 0 | BI21: =$BI$16*BR21 -> 31696.173 | BJ21: =IF(BI21="","",BI21/$BI$16) -> 0.001119682 | BK21: =IF(BJ21="","",BH21-BJ21) -> -0.001119682 | BL21: =SUM(D21,I21,N21,S21,X21,AC21,AH21,AM21,AR21,AW21,BB21,BG21) -> 195231.58 | BM21: =BL21/$BL$16 -> 0.0043890288 | BN21: =F21+K21+P21+U21+Z21+AE21+AJ21+AO21+AT21+AY21+BD21+BI21 -> 331040.66 | BO21: =IF(BN21="","",BN21/$BN$16) -> 0.001119682 | BP21: =IF(BO21="","",BM21-BO21) -> 0.0032693468 | BQ21: 307366.84 | BR21: =BQ21/$BQ$16 -> 0.001119682
A22: Acordo_E | B22: Acordo_S | C22: ( + ) Acordos Comerciais | D22: =SUMIF(EXTRATO!$F$14:$F$194,"Acordo_E",EXTRATO!$I$14:$I$194)-SUMIF(EXTRATO!$F$14:$F$194,"Acordo_S",EXTRATO!$I$14:$I$194) -> 287208.95 | E22: =D22/$D$16 -> 0.012281032 | F22: =$F$16*BR22 -> 228654.98 | G22: =IF(F22="","",F22/$F$16) -> 0.010820148 | H22: =IF(G22="","",E22-G22) -> 0.0014608838 | I22: =SUMIF(EXTRATO!$F$14:$F$194,"Acordo_E",EXTRATO!$J$14:$J$194)-SUMIF(EXTRATO!$F$14:$F$194,"Acordo_S",EXTRATO!$J$14:$J$194) -> 195834.05 | J22: =I22/$I$16 -> 0.0092832842 | K22: =$K$16*BR22 -> 241172.18 | L22: =IF(K22="","",K22/$K$16) -> 0.010820148 | M22: =IF(L22="","",J22-L22) -> -0.001536864 | O22: =IFERROR(N22/$N$16,"") | P22: =$P$16*BR22 -> 254401.03 | Q22: =IF(P22="","",P22/$P$16) -> 0.010820148 | R22: =N22-P22 -> -254401.03 | T22: =S22/$D$16 -> 0 | U22: =$U$16*BR22 -> 264577.07 | V22: =IF(U22="","",U22/$U$16) -> 0.010820148 | W22: =IF(V22="","",T22-V22) -> -0.010820148 | Y22: =X22/$D$16 -> 0 | Z22: =$Z$16*BR22 -> 274753.12 | AA22: =IF(Z22="","",Z22/$Z$16) -> 0.010820148 | AB22: =IF(AA22="","",Y22-AA22) -> -0.010820148 | AD22: =AC22/$D$16 -> 0 | AE22: =$AE$16*BR22 -> 264577.07 | AF22: =IF(AE22="","",AE22/$AE$16) -> 0.010820148 | AG22: =IF(AF22="","",AD22-AF22) -> -0.010820148 | AI22: =AH22/$D$16 -> 0 | AJ22: =$AJ$16*BR22 -> 282893.95 | AK22: =IF(AJ22="","",AJ22/$AJ$16) -> 0.010820148 | AL22: =IF(AK22="","",AI22-AK22) -> -0.010820148 | AN22: =AM22/$D$16 -> 0 | AO22: =$AO$16*BR22 -> 265594.68 | AP22: =IF(AO22="","",AO22/$AO$16) -> 0.010820148 | AQ22: =IF(AP22="","",AN22-AP22) -> -0.010820148 | AS22: =AR22/$D$16 -> 0 | AT22: =$AT$16*BR22 -> 263559.47 | AU22: =IF(AT22="","",AT22/$AT$16) -> 0.010820148 | AV22: =IF(AU22="","",AS22-AU22) -> -0.010820148 | AX22: =AW22/$D$16 -> 0 | AY22: =$AY$16*BR22 -> 279841.14 | AZ22: =IF(AY22="","",AY22/$AY$16) -> 0.010820148 | BA22: =IF(AZ22="","",AX22-AZ22) -> -0.010820148 | BC22: =BB22/$D$16 -> 0 | BD22: =$BD$16*BR22 -> 272717.91 | BE22: =IF(BD22="","",BD22/$BD$16) -> 0.010820148 | BF22: =IF(BE22="","",BC22-BE22) -> -0.010820148 | BH22: =BG22/$D$16 -> 0 | BI22: =$BI$16*BR22 -> 306298.84 | BJ22: =IF(BI22="","",BI22/$BI$16) -> 0.010820148 | BK22: =IF(BJ22="","",BH22-BJ22) -> -0.010820148 | BL22: =SUM(D22,I22,N22,S22,X22,AC22,AH22,AM22,AR22,AW22,BB22,BG22) -> 483043 | BM22: =BL22/$BL$16 -> 0.010859358 | BN22: =F22+K22+P22+U22+Z22+AE22+AJ22+AO22+AT22+AY22+BD22+BI22 -> 3199041.4 | BO22: =IF(BN22="","",BN22/$BN$16) -> 0.010820148 | BP22: =IF(BO22="","",BM22-BO22) -> 3.9209794e-05 | BQ22: 2970267.3 | BR22: =BQ22/$BQ$16 -> 0.010820148
A23: Devf_E | C23: ( + ) Devoluções | D23: =SUMIF(EXTRATO!$F$14:$F$194,"devf_e",EXTRATO!$I$14:$I$194) -> 159091.48 | E23: =D23/$D$16 -> 0.0068027391 | F23: =$F$16*BR23 -> 123907.54 | G23: =IF(F23="","",F23/$F$16) -> 0.0058634104 | H23: =IF(G23="","",E23-G23) -> 0.00093932875 | I23: =SUMIF(EXTRATO!$F$14:$F$194,"devf_e",EXTRATO!$J$14:$J$194) -> 207041.3 | J23: =I23/$I$16 -> 0.0098145508 | K23: =$K$16*BR23 -> 130690.58 | L23: =IF(K23="","",K23/$K$16) -> 0.0058634104 | M23: =IF(L23="","",J23-L23) -> 0.0039511404 | O23: =IFERROR(N23/$N$16,"") | P23: =$P$16*BR23 -> 137859.26 | Q23: =IF(P23="","",P23/$P$16) -> 0.0058634104 | R23: =N23-P23 -> -137859.26 | T23: =S23/$D$16 -> 0 | U23: =$U$16*BR23 -> 143373.63 | V23: =IF(U23="","",U23/$U$16) -> 0.0058634104 | W23: =IF(V23="","",T23-V23) -> -0.0058634104 | Y23: =X23/$D$16 -> 0 | Z23: =$Z$16*BR23 -> 148888 | AA23: =IF(Z23="","",Z23/$Z$16) -> 0.0058634104 | AB23: =IF(AA23="","",Y23-AA23) -> -0.0058634104 | AD23: =AC23/$D$16 -> 0 | AE23: =$AE$16*BR23 -> 143373.63 | AF23: =IF(AE23="","",AE23/$AE$16) -> 0.0058634104 | AG23: =IF(AF23="","",AD23-AF23) -> -0.0058634104 | AI23: =AH23/$D$16 -> 0 | AJ23: =$AJ$16*BR23 -> 153299.5 | AK23: =IF(AJ23="","",AJ23/$AJ$16) -> 0.0058634104 | AL23: =IF(AK23="","",AI23-AK23) -> -0.0058634104 | AN23: =AM23/$D$16 -> 0 | AO23: =$AO$16*BR23 -> 143925.07 | AP23: =IF(AO23="","",AO23/$AO$16) -> 0.0058634104 | AQ23: =IF(AP23="","",AN23-AP23) -> -0.0058634104 | AS23: =AR23/$D$16 -> 0 | AT23: =$AT$16*BR23 -> 142822.2 | AU23: =IF(AT23="","",AT23/$AT$16) -> 0.0058634104 | AV23: =IF(AU23="","",AS23-AU23) -> -0.0058634104 | AX23: =AW23/$D$16 -> 0 | AY23: =$AY$16*BR23 -> 151645.19 | AZ23: =IF(AY23="","",AY23/$AY$16) -> 0.0058634104 | BA23: =IF(AZ23="","",AX23-AZ23) -> -0.0058634104 | BC23: =BB23/$D$16 -> 0 | BD23: =$BD$16*BR23 -> 147785.13 | BE23: =IF(BD23="","",BD23/$BD$16) -> 0.0058634104 | BF23: =IF(BE23="","",BC23-BE23) -> -0.0058634104 | BH23: =BG23/$D$16 -> 0 | BI23: =$BI$16*BR23 -> 165982.55 | BJ23: =IF(BI23="","",BI23/$BI$16) -> 0.0058634104 | BK23: =IF(BJ23="","",BH23-BJ23) -> -0.0058634104 | BL23: =SUM(D23,I23,N23,S23,X23,AC23,AH23,AM23,AR23,AW23,BB23,BG23) -> 366132.78 | BM23: =BL23/$BL$16 -> 0.0082310829 | BN23: =F23+K23+P23+U23+Z23+AE23+AJ23+AO23+AT23+AY23+BD23+BI23 -> 1733552.3 | BO23: =IF(BN23="","",BN23/$BN$16) -> 0.0058634104 | BP23: =IF(BO23="","",BM23-BO23) -> 0.0023676725 | BQ23: 1609580.2 | BR23: =BQ23/$BQ$16 -> 0.0058634104
C24: ( = ) Sub Total de Fornecedores | D24: =SUM(D22:D23) -> 446300.43 | E24: =SUM(E22:E23) -> 0.019083771 | F24: =SUM(F22:F23) -> 352562.52 | G24: =IF(F24="","",SUM(G22:G23)) -> 0.016683559 | H24: =IF(G24="","",E24-G24) -> 0.0024002125 | I24: =SUM(I22:I23) -> 402875.35 | J24: =SUM(J22:J23) -> 0.019097835 | K24: =SUM(K22:K23) -> 371862.76 | L24: =IF(K24="","",SUM(L22:L23)) -> 0.016683559 | M24: =IF(L24="","",J24-L24) -> 0.0024142764 | N24: =SUM(N22:N23) -> 0 | O24: =IFERROR(SUM(O22:O23),"") -> 0 | P24: =SUM(P22:P23) -> 392260.3 | Q24: =IF(P24="","",SUM(Q22:Q23)) -> 0.016683559 | R24: =N24-P24 -> -392260.3 | S24: =SUM(S22:S23) -> 0 | T24: =SUM(T22:T23) -> 0 | U24: =SUM(U22:U23) -> 407950.71 | V24: =IF(U24="","",SUM(V22:V23)) -> 0.016683559 | W24: =IF(V24="","",T24-V24) -> -0.016683559 | X24: =SUM(X22:X23) -> 0 | Y24: =SUM(Y22:Y23) -> 0 | Z24: =SUM(Z22:Z23) -> 423641.12 | AA24: =IF(Z24="","",SUM(AA22:AA23)) -> 0.016683559 | AB24: =IF(AA24="","",Y24-AA24) -> -0.016683559 | AC24: =SUM(AC22:AC23) -> 0 | AD24: =SUM(AD22:AD23) -> 0 | AE24: =SUM(AE22:AE23) -> 407950.71 | AF24: =IF(AE24="","",SUM(AF22:AF23)) -> 0.016683559 | AG24: =IF(AF24="","",AD24-AF24) -> -0.016683559 | AH24: =SUM(AH22:AH23) -> 0 | AI24: =SUM(AI22:AI23) -> 0 | AJ24: =SUM(AJ22:AJ23) -> 436193.45 | AK24: =IF(AJ24="","",SUM(AK22:AK23)) -> 0.016683559 | AL24: =IF(AK24="","",AI24-AK24) -> -0.016683559 | AM24: =SUM(AM22:AM23) -> 0 | AN24: =SUM(AN22:AN23) -> 0 | AO24: =SUM(AO22:AO23) -> 409519.75 | AP24: =IF(AO24="","",SUM(AP22:AP23)) -> 0.016683559 | AQ24: =IF(AP24="","",AN24-AP24) -> -0.016683559 | AR24: =SUM(AR22:AR23) -> 0 | AS24: =SUM(AS22:AS23) -> 0 | AT24: =SUM(AT22:AT23) -> 406381.67 | AU24: =IF(AT24="","",SUM(AU22:AU23)) -> 0.016683559 | AV24: =IF(AU24="","",AS24-AU24) -> -0.016683559 | AW24: =SUM(AW22:AW23) -> 0 | AX24: =SUM(AX22:AX23) -> 0 | AY24: =SUM(AY22:AY23) -> 431486.33 | AZ24: =IF(AY24="","",SUM(AZ22:AZ23)) -> 0.016683559 | BA24: =IF(AZ24="","",AX24-AZ24) -> -0.016683559 | BB24: =SUM(BB22:BB23) -> 0 | BC24: =SUM(BC22:BC23) -> 0 | BD24: =SUM(BD22:BD23) -> 420503.04 | BE24: =IF(BD24="","",SUM(BE22:BE23)) -> 0.016683559 | BF24: =IF(BE24="","",BC24-BE24) -> -0.016683559 | BG24: =SUM(BG22:BG23) -> 0 | BH24: =SUM(BH22:BH23) -> 0 | BI24: =SUM(BI22:BI23) -> 472281.4 | BJ24: =IF(BI24="","",SUM(BJ22:BJ23)) -> 0.016683559 | BK24: =IF(BJ24="","",BH24-BJ24) -> -0.016683559 | BL24: =SUM(BL22:BL23) -> 849175.78 | BM24: =SUM(BM22:BM23) -> 0.019090441 | BN24: =F24+K24+P24+U24+Z24+AE24+AJ24+AO24+AT24+AY24+BD24+BI24 -> 4932593.7 | BO24: =IF(BN24="","",SUM(BO22:BO23)) -> 0.016683559 | BP24: =IF(BO24="","",BM24-BO24) -> 0.0024068823 | BQ24: =SUM(BQ22:BQ23) -> 4579847.5 | BR24: =SUM(BR22:BR23) -> 0.016683559
A25: CHQ_E | B25: CHQ_S | C25: ( +/- ) Mvto Chq. Devolvidos | D25: =SUMIF(EXTRATO!$F$14:$F$194,"CHQ_E",EXTRATO!$I$14:$I$194)-SUMIF(EXTRATO!$F$14:$F$194,"CHQ_S",EXTRATO!$I$14:$I$194) -> -824.99 | E25: =D25/$D$16 -> -3.5276507e-05 | G25: 0 | H25: =IF(G25="","",E25-G25) -> -3.5276507e-05 | I25: =SUMIF(EXTRATO!$F$14:$F$194,"CHQ_E",EXTRATO!$J$14:$J$194)-SUMIF(EXTRATO!$F$14:$F$194,"CHQ_S",EXTRATO!$J$14:$J$194) -> -39.7 | J25: =I25/$I$16 -> -1.8819321e-06 | K25: =0 -> 0 | L25: =IF(K25="","",K25/$K$16) -> 0 | M25: =IF(L25="","",J25-L25) -> -1.8819321e-06 | O25: =IFERROR(N25/$N$16,"") | P25: =0 -> 0 | Q25: =IF(P25="","",P25/$P$16) -> 0 | R25: =N25-P25 -> 0 | T25: =S25/$D$16 -> 0 | U25: =0 -> 0 | V25: =IF(U25="","",U25/$U$16) -> 0 | W25: =IF(V25="","",T25-V25) -> 0 | Y25: =X25/$D$16 -> 0 | Z25: =0 -> 0 | AA25: =IF(Z25="","",Z25/$Z$16) -> 0 | AB25: =IF(AA25="","",Y25-AA25) -> 0 | AD25: =AC25/$D$16 -> 0 | AE25: =0 -> 0 | AF25: =IF(AE25="","",AE25/$AE$16) -> 0 | AG25: =IF(AF25="","",AD25-AF25) -> 0 | AI25: =AH25/$D$16 -> 0 | AJ25: =0 -> 0 | AK25: =IF(AJ25="","",AJ25/$AJ$16) -> 0 | AL25: =IF(AK25="","",AI25-AK25) -> 0 | AN25: =AM25/$D$16 -> 0 | AO25: =0 -> 0 | AP25: =IF(AO25="","",AO25/$AO$16) -> 0 | AQ25: =IF(AP25="","",AN25-AP25) -> 0 | AS25: =AR25/$D$16 -> 0 | AT25: =0 -> 0 | AU25: =IF(AT25="","",AT25/$AT$16) -> 0 | AV25: =IF(AU25="","",AS25-AU25) -> 0 | AX25: =AW25/$D$16 -> 0 | AY25: =0 -> 0 | AZ25: =IF(AY25="","",AY25/$AY$16) -> 0 | BA25: =IF(AZ25="","",AX25-AZ25) -> 0 | BC25: =BB25/$D$16 -> 0 | BD25: =0 -> 0 | BE25: =IF(BD25="","",BD25/$BD$16) -> 0 | BF25: =IF(BE25="","",BC25-BE25) -> 0 | BH25: =BG25/$D$16 -> 0 | BI25: =0 -> 0 | BJ25: =IF(BI25="","",BI25/$BI$16) -> 0 | BK25: =IF(BJ25="","",BH25-BJ25) -> 0 | BL25: =SUM(D25,I25,N25,S25,X25,AC25,AH25,AM25,AR25,AW25,BB25,BG25) -> -864.69 | BM25: =BL25/$BL$16 -> -1.9439218e-05 | BN25: =F25+K25+P25+U25+Z25+AE25+AJ25+AO25+AT25+AY25+BD25+BI25 -> 0 | BO25: =IF(BN25="","",BN25/$BN$16) -> 0 | BP25: =IF(BO25="","",BM25-BO25) -> -1.9439218e-05 | BQ25: -3832.03 | BR25: =BQ25/$BQ$16 -> -1.3959394e-05
C26: Lucro Bruto | D26: =D20+D24+D25+D21 -> 3987512 | E26: =E20+E21+E24+E25 -> 0.1705057 | F26: =F18-F19+F21+F24+F25 -> 4285705.6 | G26: =IF(F26="","",G20+G21+G24+G25) -> 0.20280324 | H26: =IF(G26="","",E26-G26) -> -0.032297544 | I26: =I20+I24+I25+I21 -> 3605897.7 | J26: =J20+J21+J24+J25 -> 0.17093337 | K26: =K18-K19+K21+K24+K25 -> 4520316.9 | L26: =IF(K26="","",L20+L21+L24+L25) -> 0.20280324 | M26: =IF(L26="","",J26-L26) -> -0.031869873 | N26: =N20+N24+N25+N21 -> 0 | O26: =IFERROR(O20+O21+O24+O25,"") | P26: =P18-P19+P21+P24+P25 -> 4768266.8 | Q26: =IF(P26="","",Q20+Q21+Q24+Q25) -> 0.20280324 | R26: =IFERROR(IF(Q26="","",O26-Q26),"") | S26: =S20+S24+S25+S21 -> 0 | T26: =T20+T21+T24+T25 -> 0 | U26: =U18-U19+U21+U24+U25 -> 4958997.5 | V26: =IF(U26="","",V20+V21+V24+V25) -> 0.20280324 | W26: =IF(V26="","",T26-V26) -> -0.20280324 | X26: =X20+X24+X25+X21 -> 0 | Y26: =Y20+Y21+Y24+Y25 -> 0 | Z26: =Z18-Z19+Z21+Z24+Z25 -> 5149728.2 | AA26: =IF(Z26="","",AA20+AA21+AA24+AA25) -> 0.20280324 | AB26: =IF(AA26="","",Y26-AA26) -> -0.20280324 | AC26: =AC20+AC24+AC25+AC21 -> 0 | AD26: =AD20+AD21+AD24+AD25 -> 0 | AE26: =AE18-AE19+AE21+AE24+AE25 -> 4958997.5 | AF26: =IF(AE26="","",AF20+AF21+AF24+AF25) -> 0.20280324 | AG26: =IF(AF26="","",AD26-AF26) -> -0.20280324 | AH26: =AH20+AH24+AH25+AH21 -> 0 | AI26: =AI20+AI21+AI24+AI25 -> 0 | AJ26: =AJ18-AJ19+AJ21+AJ24+AJ25 -> 5302312.7 | AK26: =IF(AJ26="","",AK20+AK21+AK24+AK25) -> 0.20280324 | AL26: =IF(AK26="","",AI26-AK26) -> -0.20280324 | AM26: =AM20+AM24+AM25+AM21 -> 0 | AN26: =AN20+AN21+AN24+AN25 -> 0 | AO26: =AO18-AO19+AO21+AO24+AO25 -> 4978070.6 | AP26: =IF(AO26="","",AP20+AP21+AP24+AP25) -> 0.20280324 | AQ26: =IF(AP26="","",AN26-AP26) -> -0.20280324 | AR26: =AR20+AR24+AR25+AR21 -> 0 | AS26: =AS20+AS21+AS24+AS25 -> 0 | AT26: =AT18-AT19+AT21+AT24+AT25 -> 4939924.4 | AU26: =IF(AT26="","",AU20+AU21+AU24+AU25) -> 0.20280324 | AV26: =IF(AU26="","",AS26-AU26) -> -0.20280324 | AW26: =AW20+AW24+AW25+AW21 -> 0 | AX26: =AX20+AX21+AX24+AX25 -> 0 | AY26: =AY18-AY19+AY21+AY24+AY25 -> 5245093.5 | AZ26: =IF(AY26="","",AZ20+AZ21+AZ24+AZ25) -> 0.20280324 | BA26: =IF(AZ26="","",AX26-AZ26) -> -0.20280324 | BB26: =BB20+BB24+BB25+BB21 -> 0 | BC26: =BC20+BC21+BC24+BC25 -> 0 | BD26: =BD18-BD19+BD21+BD24+BD25 -> 5111582 | BE26: =IF(BD26="","",BE20+BE21+BE24+BE25) -> 0.20280324 | BF26: =IF(BE26="","",BC26-BE26) -> -0.20280324 | BG26: =BG20+BG24+BG25+BG21 -> 0 | BH26: =BH20+BH21+BH24+BH25 -> 0 | BI26: =BI18-BI19+BI21+BI24+BI25 -> 5740993.2 | BJ26: =IF(BI26="","",BJ20+BJ21+BJ24+BJ25) -> 0.20280324 | BK26: =IF(BJ26="","",BH26-BJ26) -> -0.20280324 | BL26: =BL20+BL24+BL25+BL21 -> 7593409.7 | BM26: =BM20+BM21+BM24+BM25 -> 0.17104405 | BN26: =F26+K26+P26+U26+Z26+AE26+AJ26+AO26+AT26+AY26+BD26+BI26 -> 59959989 | BO26: =IF(BN26="","",BO20+BO21+BO24+BO25) -> 0.20280324 | BP26: =IF(BO26="","",BM26-BO26) -> -0.031759192 | BQ26: =BQ20+BQ24+BQ25+BQ21 -> 48128441 | BR26: =BR20+BR21+BR24+BR25 -> 0.17532323
C28: Custos operacionais
A29: Pessoal | B29: Pessoal_E | C29: ( - ) Pessoal/Folha | D29: =SUMIF(EXTRATO!$F$14:$F$194,"PESSOAL",EXTRATO!$I$14:$I$194)-SUMIF(EXTRATO!$F$14:$F$194,"PESSOAL_E",EXTRATO!$I$14:$I$194)+SUMIF(DESPESA!$E$4:$E$140,"PESSOAL",DESPESA!$I$4:$I$140) -> 672226.15 | E29: =D29/$D$16 -> 0.028744337 | F29: 1120013.6 | G29: =IF(OR(F29="",F$16=0),"",F29/$F$16) -> 0.053 | H29: =IF(G29="","",E29-G29) -> -0.024255663 | I29: =SUMIF(EXTRATO!$F$14:$F$194,"PESSOAL",EXTRATO!$J$14:$J$194)-SUMIF(EXTRATO!$F$14:$F$194,"PESSOAL_E",EXTRATO!$J$14:$J$194)+SUMIF(DESPESA!$E$4:$E$140,"PESSOAL",DESPESA!$J$4:$J$140) -> 670371.83 | J29: =I29/$I$16 -> 0.031778193 | K29: 1181326.3 | L29: =IF(OR(K29="",K$16=0),"",K29/$K$16) -> 0.053 | M29: =IF(L29="","",J29-L29) -> -0.021221807 | O29: =IFERROR(N29/$N$16,"") | P29: 1246124.8 | Q29: =IF(OR(P29="",P$16=0),"",P29/$P$16) -> 0.053 | R29: =N29-P29 -> -1246124.8 | T29: =S29/$D$16 -> 0 | U29: 1295969.8 | V29: =IF(OR(U29="",U$16=0),"",U29/$U$16) -> 0.053 | W29: =IF(V29="","",T29-V29) -> -0.053 | Y29: =X29/$D$16 -> 0 | Z29: 1345814.7 | AA29: =IF(OR(Z29="",Z$16=0),"",Z29/$Z$16) -> 0.053 | AB29: =IF(AA29="","",Y29-AA29) -> -0.053 | AD29: =AC29/$D$16 -> 0 | AE29: 1295969.8 | AF29: =IF(OR(AE29="",AE$16=0),"",AE29/$AE$16) -> 0.053 | AG29: =IF(AF29="","",AD29-AF29) -> -0.053 | AI29: =AH29/$D$16 -> 0 | AJ29: 1385690.7 | AK29: =IF(OR(AJ29="",AJ$16=0),"",AJ29/$AJ$16) -> 0.053 | AL29: =IF(AK29="","",AI29-AK29) -> -0.053 | AN29: =AM29/$D$16 -> 0 | AO29: 1300954.3 | AP29: =IF(OR(AO29="",AO$16=0),"",AO29/$AO$16) -> 0.053 | AQ29: =IF(AP29="","",AN29-AP29) -> -0.053 | AS29: =AR29/$D$16 -> 0 | AT29: 1290985.3 | AU29: =IF(OR(AT29="",AT$16=0),"",AT29/$AT$16) -> 0.053 | AV29: =IF(AU29="","",AS29-AU29) -> -0.053 | AX29: =AW29/$D$16 -> 0 | AY29: 1370737.2 | AZ29: =IF(OR(AY29="",AY$16=0),"",AY29/$AY$16) -> 0.053 | BA29: =IF(AZ29="","",AX29-AZ29) -> -0.053 | BC29: =BB29/$D$16 -> 0 | BD29: 1335845.8 | BE29: =IF(OR(BD29="",BD$16=0),"",BD29/$BD$16) -> 0.053 | BF29: =IF(BE29="","",BC29-BE29) -> -0.053 | BH29: =BG29/$D$16 -> 0 | BI29: 1500334.2 | BJ29: =IF(OR(BI29="",BI$16=0),"",BI29/$BI$16) -> 0.053 | BK29: =IF(BJ29="","",BH29-BJ29) -> -0.053 | BL29: =SUM(D29,I29,N29,S29,X29,AC29,AH29,AM29,AR29,AW29,BB29,BG29) -> 1342598 | BM29: =BL29/$BL$16 -> 0.030183135 | BN29: =F29+K29+P29+U29+Z29+AE29+AJ29+AO29+AT29+AY29+BD29+BI29 -> 15669766 | BO29: =IF(BN29="","",BN29/$BN$16) -> 0.053 | BP29: =IF(BO29="","",BM29-BO29) -> -0.022816865 | BQ29: 15006488 | BR29: =BQ29/$BQ$16 -> 0.054665929
